Workbook

Sheet Gantt
A1: GANTT — Planification des recrutements (généré dynamiquement depuis la feuille Suivi)
D2: =IF(DAY(D$3)=1,TEXT(D$3,"mmmm"),"") | E2: =IF(DAY(E$3)=1,TEXT(E$3,"mmmm"),"") | F2: =IF(DAY(F$3)=1,TEXT(F$3,"mmmm"),"") | G2: =IF(DAY(G$3)=1,TEXT(G$3,"mmmm"),"") | H2: =IF(DAY(H$3)=1,TEXT(H$3,"mmmm"),"") | I2: =IF(DAY(I$3)=1,TEXT(I$3,"mmmm"),"") | J2: =IF(DAY(J$3)=1,TEXT(J$3,"mmmm"),"") | K2: =IF(DAY(K$3)=1,TEXT(K$3,"mmmm"),"") | ... DS2: =IF(DAY(DS$3)=1,TEXT(DS$3,"mmmm"),"")
A3: ID | B3: Étape | C3: Statut | D3: =Suivi!$A$6 | E3: =D3+1 | F3: =E3+1 | G3: =F3+1 | H3: =G3+1 | I3: =H3+1 | J3: =I3+1 | K3: =J3+1 | L3: =K3+1 | ... DS3: =DR3+1
A4: =Suivi!B4 | B4: =IF(Suivi!D4="",Suivi!C4,Suivi!D4) | C4: =IF(Suivi!G4="","",Suivi!G4)
A5: =Suivi!B5 | B5: =IF(Suivi!D5="",Suivi!C5,Suivi!D5) | C5: =IF(Suivi!G5="","",Suivi!G5)
A6: =Suivi!B6 | B6: =IF(Suivi!D6="",Suivi!C6,Suivi!D6) | C6: =IF(Suivi!G6="","",Suivi!G6)
A7: =Suivi!B7 | B7: =IF(Suivi!D7="",Suivi!C7,Suivi!D7) | C7: =IF(Suivi!G7="","",Suivi!G7)
A8: =Suivi!B8 | B8: =IF(Suivi!D8="",Suivi!C8,Suivi!D8) | C8: =IF(Suivi!G8="","",Suivi!G8)
A9: =Suivi!B9 | B9: =IF(Suivi!D9="",Suivi!C9,Suivi!D9) | C9: =IF(Suivi!G9="","",Suivi!G9)
A10: =Suivi!B10 | B10: =IF(Suivi!D10="",Suivi!C10,Suivi!D10) | C10: =IF(Suivi!G10="","",Suivi!G10)
A11: =Suivi!B11 | B11: =IF(Suivi!D11="",Suivi!C11,Suivi!D11) | C11: =IF(Suivi!G11="","",Suivi!G11)
A12: =Suivi!B12 | B12: =IF(Suivi!D12="",Suivi!C12,Suivi!D12) | C12: =IF(Suivi!G12="","",Suivi!G12)
A13: =Suivi!B13 | B13: =IF(Suivi!D13="",Suivi!C13,Suivi!D13) | C13: =IF(Suivi!G13="","",Suivi!G13)
A14: =Suivi!B14 | B14: =IF(Suivi!D14="",Suivi!C14,Suivi!D14) | C14: =IF(Suivi!G14="","",Suivi!G14)
A15: =Suivi!B15 | B15: =IF(Suivi!D15="",Suivi!C15,Suivi!D15) | C15: =IF(Suivi!G15="","",Suivi!G15)
... A56: =Suivi!B56 | B56: =IF(Suivi!D56="",Suivi!C56,Suivi!D56) | C56: =IF(Suivi!G56="","",Suivi!G56)
B58: Légende : | E58: Macro-étape
E59: Tâche
E60: Week-end
B62: Le graphique se met à jour automatiquement lorsque les dates changent dans les feuilles Paramètres / Suivi.

Sheet Suivi
A3: Dossier | B3: =Paramètres!G4 | C3: =Paramètres!H4 | D3: =Paramètres!I4 | E3: Début le | F3: Fin prévue le | G3: Statut | H3: Durée (j ouvrés)
A4: 1 | B4: =Paramètres!G5 | C4: =IF(Paramètres!H5="","",Paramètres!H5) | D4: =IF(Paramètres!I5="","",Paramètres!I5) | E4: =MIN(E5:E8) | F4: =MAX(F5:F8) | G4: En attente | H4: =NETWORKDAYS(E4,F4)
A5: DATE DEBUT PROJET | B5: =Paramètres!G6 | C5: =IF(Paramètres!H6="","",Paramètres!H6) | D5: =IF(Paramètres!I6="","",Paramètres!I6) | E5: =IF(Paramètres!J6&Paramètres!L6&Paramètres!N6="",WORKDAY($A$6-1,1),MAX(IF(Paramètres!J6="",0,IF(Paramètres!K6="",NA(),IF(RIGHT(TRIM(Paramètres!K6),3)="Fin",WORKDAY(IF(LEFT(TRIM(Paramètres!K6),1)="F",INDEX($F$4:$F$56,MATCH(Paramètres!J6,Paramètres!$G$5:$G$57,0)),INDEX($E$4:$E$56,MATCH(Paramètres!J6,Paramètres!$G$5:$G$57,0))),1-$H5),IF(LEFT(TRIM(Paramètres!K6),1)="F",WORKDAY(IF(LEFT(TRIM(Paramètres!K6),1)="F",INDEX($F$4:$F$56,MATCH(Paramètres!J6,Paramètres!$G$5:$G$57,0)),INDEX($E$4:$E$56,MATCH(Paramètres!J6,Paramètres!$G$5:$G$57,0))),1),IF(LEFT(TRIM(Paramètres!K6),1)="F",INDEX($F$4:$F$56,MATCH(Paramètres!J6,Paramètres!$G$5:$G$57,0)),INDEX($E$4:$E$56,MATCH(Paramètres!J6,Paramètres!$G$5:$G$57,0))))))),IF(Paramètres!L6="",0,IF(Paramètres!M6="",NA(),IF(RIGHT(TRIM(Paramètres!M6),3)="Fin",WORKDAY(IF(LEFT(TRIM(Paramètres!M6),1)="F",INDEX($F$4:$F$56,MATCH(Paramètres!L6,Paramètres!$G$5:$G$57,0)),INDEX($E$4:$E$56,MATCH(Paramètres!L6,Paramètres!$G$5:$G$57,0))),1-$H5),IF(LEFT(TRIM(Paramètres!M6),1)="F",WORKDAY(IF(LEFT(TRIM(Paramètres!M6),1)="F",INDEX($F$4:$F$56,MATCH(Paramètres!L6,Paramètres!$G$5:$G$57,0)),INDEX($E$4:$E$56,MATCH(Paramètres!L6,Paramètres!$G$5:$G$57,0))),1),IF(LEFT(TRIM(Paramètres!M6),1)="F",INDEX($F$4:$F$56,MATCH(Paramètres!L6,Paramètres!$G$5:$G$57,0)),INDEX($E$4:$E$56,MATCH(Paramètres!L6,Paramètres!$G$5:$G$57,0))))))),IF(Paramètres!N6="",0,IF(Paramètres!O6="",NA(),IF(RIGHT(TRIM(Paramètres!O6),3)="Fin",WORKDAY(IF(LEFT(TRIM(Paramètres!O6),1)="F",INDEX($F$4:$F$56,MATCH(Paramètres!N6,Paramètres!$G$5:$G$57,0)),INDEX($E$4:$E$56,MATCH(Paramètres!N6,Paramètres!$G$5:$G$57,0))),1-$H5),IF(LEFT(TRIM(Paramètres!O6),1)="F",WORKDAY(IF(LEFT(TRIM(Paramètres!O6),1)="F",INDEX($F$4:$F$56,MATCH(Paramètres!N6,Paramètres!$G$5:$G$57,0)),INDEX($E$4:$E$56,MATCH(Paramètres!N6,Paramètres!$G$5:$G$57,0))),1),IF(LEFT(TRIM(Paramètres!O6),1)="F",INDEX($F$4:$F$56,MATCH(Paramètres!N6,Paramètres!$G$5:$G$57,0)),INDEX($E$4:$E$56,MATCH(Paramètres!N6,Paramètres!$G$5:$G$57,0))))))))) | F5: =IF($H5=0,WORKDAY(E5,-1),WORKDAY(E5,$H5-1)) | H5: =Paramètres!B6
A6: 46308 | B6: =Paramètres!G7 | C6: =IF(Paramètres!H7="","",Paramètres!H7) | D6: =IF(Paramètres!I7="","",Paramètres!I7) | E6: =IF(Paramètres!J7&Paramètres!L7&Paramètres!N7="",WORKDAY($A$6-1,1),MAX(IF(Paramètres!J7="",0,IF(Paramètres!K7="",NA(),IF(RIGHT(TRIM(Paramètres!K7),3)="Fin",WORKDAY(IF(LEFT(TRIM(Paramètres!K7),1)="F",INDEX($F$4:$F$56,MATCH(Paramètres!J7,Paramètres!$G$5:$G$57,0)),INDEX($E$4:$E$56,MATCH(Paramètres!J7,Paramètres!$G$5:$G$57,0))),1-$H6),IF(LEFT(TRIM(Paramètres!K7),1)="F",WORKDAY(IF(LEFT(TRIM(Paramètres!K7),1)="F",INDEX($F$4:$F$56,MATCH(Paramètres!J7,Paramètres!$G$5:$G$57,0)),INDEX($E$4:$E$56,MATCH(Paramètres!J7,Paramètres!$G$5:$G$57,0))),1),IF(LEFT(TRIM(Paramètres!K7),1)="F",INDEX($F$4:$F$56,MATCH(Paramètres!J7,Paramètres!$G$5:$G$57,0)),INDEX($E$4:$E$56,MATCH(Paramètres!J7,Paramètres!$G$5:$G$57,0))))))),IF(Paramètres!L7="",0,IF(Paramètres!M7="",NA(),IF(RIGHT(TRIM(Paramètres!M7),3)="Fin",WORKDAY(IF(LEFT(TRIM(Paramètres!M7),1)="F",INDEX($F$4:$F$56,MATCH(Paramètres!L7,Paramètres!$G$5:$G$57,0)),INDEX($E$4:$E$56,MATCH(Paramètres!L7,Paramètres!$G$5:$G$57,0))),1-$H6),IF(LEFT(TRIM(Paramètres!M7),1)="F",WORKDAY(IF(LEFT(TRIM(Paramètres!M7),1)="F",INDEX($F$4:$F$56,MATCH(Paramètres!L7,Paramètres!$G$5:$G$57,0)),INDEX($E$4:$E$56,MATCH(Paramètres!L7,Paramètres!$G$5:$G$57,0))),1),IF(LEFT(TRIM(Paramètres!M7),1)="F",INDEX($F$4:$F$56,MATCH(Paramètres!L7,Paramètres!$G$5:$G$57,0)),INDEX($E$4:$E$56,MATCH(Paramètres!L7,Paramètres!$G$5:$G$57,0))))))),IF(Paramètres!N7="",0,IF(Paramètres!O7="",NA(),IF(RIGHT(TRIM(Paramètres!O7),3)="Fin",WORKDAY(IF(LEFT(TRIM(Paramètres!O7),1)="F",INDEX($F$4:$F$56,MATCH(Paramètres!N7,Paramètres!$G$5:$G$57,0)),INDEX($E$4:$E$56,MATCH(Paramètres!N7,Paramètres!$G$5:$G$57,0))),1-$H6),IF(LEFT(TRIM(Paramètres!O7),1)="F",WORKDAY(IF(LEFT(TRIM(Paramètres!O7),1)="F",INDEX($F$4:$F$56,MATCH(Paramètres!N7,Paramètres!$G$5:$G$57,0)),INDEX($E$4:$E$56,MATCH(Paramètres!N7,Paramètres!$G$5:$G$57,0))),1),IF(LEFT(TRIM(Paramètres!O7),1)="F",INDEX($F$4:$F$56,MATCH(Paramètres!N7,Paramètres!$G$5:$G$57,0)),INDEX($E$4:$E$56,MATCH(Paramètres!N7,Paramètres!$G$5:$G$57,0))))))))) | F6: =IF($H6=0,WORKDAY(E6,-1),WORKDAY(E6,$H6-1)) | H6: =Paramètres!B7
B7: =Paramètres!G8 | C7: =IF(Paramètres!H8="","",Paramètres!H8) | D7: =IF(Paramètres!I8="","",Paramètres!I8) | E7: =IF(Paramètres!J8&Paramètres!L8&Paramètres!N8="",WORKDAY($A$6-1,1),MAX(IF(Paramètres!J8="",0,IF(Paramètres!K8="",NA(),IF(RIGHT(TRIM(Paramètres!K8),3)="Fin",WORKDAY(IF(LEFT(TRIM(Paramètres!K8),1)="F",INDEX($F$4:$F$56,MATCH(Paramètres!J8,Paramètres!$G$5:$G$57,0)),INDEX($E$4:$E$56,MATCH(Paramètres!J8,Paramètres!$G$5:$G$57,0))),1-$H7),IF(LEFT(TRIM(Paramètres!K8),1)="F",WORKDAY(IF(LEFT(TRIM(Paramètres!K8),1)="F",INDEX($F$4:$F$56,MATCH(Paramètres!J8,Paramètres!$G$5:$G$57,0)),INDEX($E$4:$E$56,MATCH(Paramètres!J8,Paramètres!$G$5:$G$57,0))),1),IF(LEFT(TRIM(Paramètres!K8),1)="F",INDEX($F$4:$F$56,MATCH(Paramètres!J8,Paramètres!$G$5:$G$57,0)),INDEX($E$4:$E$56,MATCH(Paramètres!J8,Paramètres!$G$5:$G$57,0))))))),IF(Paramètres!L8="",0,IF(Paramètres!M8="",NA(),IF(RIGHT(TRIM(Paramètres!M8),3)="Fin",WORKDAY(IF(LEFT(TRIM(Paramètres!M8),1)="F",INDEX($F$4:$F$56,MATCH(Paramètres!L8,Paramètres!$G$5:$G$57,0)),INDEX($E$4:$E$56,MATCH(Paramètres!L8,Paramètres!$G$5:$G$57,0))),1-$H7),IF(LEFT(TRIM(Paramètres!M8),1)="F",WORKDAY(IF(LEFT(TRIM(Paramètres!M8),1)="F",INDEX($F$4:$F$56,MATCH(Paramètres!L8,Paramètres!$G$5:$G$57,0)),INDEX($E$4:$E$56,MATCH(Paramètres!L8,Paramètres!$G$5:$G$57,0))),1),IF(LEFT(TRIM(Paramètres!M8),1)="F",INDEX($F$4:$F$56,MATCH(Paramètres!L8,Paramètres!$G$5:$G$57,0)),INDEX($E$4:$E$56,MATCH(Paramètres!L8,Paramètres!$G$5:$G$57,0))))))),IF(Paramètres!N8="",0,IF(Paramètres!O8="",NA(),IF(RIGHT(TRIM(Paramètres!O8),3)="Fin",WORKDAY(IF(LEFT(TRIM(Paramètres!O8),1)="F",INDEX($F$4:$F$56,MATCH(Paramètres!N8,Paramètres!$G$5:$G$57,0)),INDEX($E$4:$E$56,MATCH(Paramètres!N8,Paramètres!$G$5:$G$57,0))),1-$H7),IF(LEFT(TRIM(Paramètres!O8),1)="F",WORKDAY(IF(LEFT(TRIM(Paramètres!O8),1)="F",INDEX($F$4:$F$56,MATCH(Paramètres!N8,Paramètres!$G$5:$G$57,0)),INDEX($E$4:$E$56,MATCH(Paramètres!N8,Paramètres!$G$5:$G$57,0))),1),IF(LEFT(TRIM(Paramètres!O8),1)="F",INDEX($F$4:$F$56,MATCH(Paramètres!N8,Paramètres!$G$5:$G$57,0)),INDEX($E$4:$E$56,MATCH(Paramètres!N8,Paramètres!$G$5:$G$57,0))))))))) | F7: =IF($H7=0,WORKDAY(E7,-1),WORKDAY(E7,$H7-1)) | H7: =Paramètres!B8
B8: =Paramètres!G9 | C8: =IF(Paramètres!H9="","",Paramètres!H9) | D8: =IF(Paramètres!I9="","",Paramètres!I9) | E8: =IF(Paramètres!J9&Paramètres!L9&Paramètres!N9="",WORKDAY($A$6-1,1),MAX(IF(Paramètres!J9="",0,IF(Paramètres!K9="",NA(),IF(RIGHT(TRIM(Paramètres!K9),3)="Fin",WORKDAY(IF(LEFT(TRIM(Paramètres!K9),1)="F",INDEX($F$4:$F$56,MATCH(Paramètres!J9,Paramètres!$G$5:$G$57,0)),INDEX($E$4:$E$56,MATCH(Paramètres!J9,Paramètres!$G$5:$G$57,0))),1-$H8),IF(LEFT(TRIM(Paramètres!K9),1)="F",WORKDAY(IF(LEFT(TRIM(Paramètres!K9),1)="F",INDEX($F$4:$F$56,MATCH(Paramètres!J9,Paramètres!$G$5:$G$57,0)),INDEX($E$4:$E$56,MATCH(Paramètres!J9,Paramètres!$G$5:$G$57,0))),1),IF(LEFT(TRIM(Paramètres!K9),1)="F",INDEX($F$4:$F$56,MATCH(Paramètres!J9,Paramètres!$G$5:$G$57,0)),INDEX($E$4:$E$56,MATCH(Paramètres!J9,Paramètres!$G$5:$G$57,0))))))),IF(Paramètres!L9="",0,IF(Paramètres!M9="",NA(),IF(RIGHT(TRIM(Paramètres!M9),3)="Fin",WORKDAY(IF(LEFT(TRIM(Paramètres!M9),1)="F",INDEX($F$4:$F$56,MATCH(Paramètres!L9,Paramètres!$G$5:$G$57,0)),INDEX($E$4:$E$56,MATCH(Paramètres!L9,Paramètres!$G$5:$G$57,0))),1-$H8),IF(LEFT(TRIM(Paramètres!M9),1)="F",WORKDAY(IF(LEFT(TRIM(Paramètres!M9),1)="F",INDEX($F$4:$F$56,MATCH(Paramètres!L9,Paramètres!$G$5:$G$57,0)),INDEX($E$4:$E$56,MATCH(Paramètres!L9,Paramètres!$G$5:$G$57,0))),1),IF(LEFT(TRIM(Paramètres!M9),1)="F",INDEX($F$4:$F$56,MATCH(Paramètres!L9,Paramètres!$G$5:$G$57,0)),INDEX($E$4:$E$56,MATCH(Paramètres!L9,Paramètres!$G$5:$G$57,0))))))),IF(Paramètres!N9="",0,IF(Paramètres!O9="",NA(),IF(RIGHT(TRIM(Paramètres!O9),3)="Fin",WORKDAY(IF(LEFT(TRIM(Paramètres!O9),1)="F",INDEX($F$4:$F$56,MATCH(Paramètres!N9,Paramètres!$G$5:$G$57,0)),INDEX($E$4:$E$56,MATCH(Paramètres!N9,Paramètres!$G$5:$G$57,0))),1-$H8),IF(LEFT(TRIM(Paramètres!O9),1)="F",WORKDAY(IF(LEFT(TRIM(Paramètres!O9),1)="F",INDEX($F$4:$F$56,MATCH(Paramètres!N9,Paramètres!$G$5:$G$57,0)),INDEX($E$4:$E$56,MATCH(Paramètres!N9,Paramètres!$G$5:$G$57,0))),1),IF(LEFT(TRIM(Paramètres!O9),1)="F",INDEX($F$4:$F$56,MATCH(Paramètres!N9,Paramètres!$G$5:$G$57,0)),INDEX($E$4:$E$56,MATCH(Paramètres!N9,Paramètres!$G$5:$G$57,0))))))))) | F8: =IF($H8=0,WORKDAY(E8,-1),WORKDAY(E8,$H8-1)) | H8: =Paramètres!B9
B9: =Paramètres!G10 | C9: =IF(Paramètres!H10="","",Paramètres!H10) | D9: =IF(Paramètres!I10="","",Paramètres!I10) | E9: =MIN(E10:E13) | F9: =MAX(F10:F13) | H9: =NETWORKDAYS(E9,F9)
B10: =Paramètres!G11 | C10: =IF(Paramètres!H11="","",Paramètres!H11) | D10: =IF(Paramètres!I11="","",Paramètres!I11) | E10: =IF(Paramètres!J11&Paramètres!L11&Paramètres!N11="",WORKDAY($A$6-1,1),MAX(IF(Paramètres!J11="",0,IF(Paramètres!K11="",NA(),IF(RIGHT(TRIM(Paramètres!K11),3)="Fin",WORKDAY(IF(LEFT(TRIM(Paramètres!K11),1)="F",INDEX($F$4:$F$56,MATCH(Paramètres!J11,Paramètres!$G$5:$G$57,0)),INDEX($E$4:$E$56,MATCH(Paramètres!J11,Paramètres!$G$5:$G$57,0))),1-$H10),IF(LEFT(TRIM(Paramètres!K11),1)="F",WORKDAY(IF(LEFT(TRIM(Paramètres!K11),1)="F",INDEX($F$4:$F$56,MATCH(Paramètres!J11,Paramètres!$G$5:$G$57,0)),INDEX($E$4:$E$56,MATCH(Paramètres!J11,Paramètres!$G$5:$G$57,0))),1),IF(LEFT(TRIM(Paramètres!K11),1)="F",INDEX($F$4:$F$56,MATCH(Paramètres!J11,Paramètres!$G$5:$G$57,0)),INDEX($E$4:$E$56,MATCH(Paramètres!J11,Paramètres!$G$5:$G$57,0))))))),IF(Paramètres!L11="",0,IF(Paramètres!M11="",NA(),IF(RIGHT(TRIM(Paramètres!M11),3)="Fin",WORKDAY(IF(LEFT(TRIM(Paramètres!M11),1)="F",INDEX($F$4:$F$56,MATCH(Paramètres!L11,Paramètres!$G$5:$G$57,0)),INDEX($E$4:$E$56,MATCH(Paramètres!L11,Paramètres!$G$5:$G$57,0))),1-$H10),IF(LEFT(TRIM(Paramètres!M11),1)="F",WORKDAY(IF(LEFT(TRIM(Paramètres!M11),1)="F",INDEX($F$4:$F$56,MATCH(Paramètres!L11,Paramètres!$G$5:$G$57,0)),INDEX($E$4:$E$56,MATCH(Paramètres!L11,Paramètres!$G$5:$G$57,0))),1),IF(LEFT(TRIM(Paramètres!M11),1)="F",INDEX($F$4:$F$56,MATCH(Paramètres!L11,Paramètres!$G$5:$G$57,0)),INDEX($E$4:$E$56,MATCH(Paramètres!L11,Paramètres!$G$5:$G$57,0))))))),IF(Paramètres!N11="",0,IF(Paramètres!O11="",NA(),IF(RIGHT(TRIM(Paramètres!O11),3)="Fin",WORKDAY(IF(LEFT(TRIM(Paramètres!O11),1)="F",INDEX($F$4:$F$56,MATCH(Paramètres!N11,Paramètres!$G$5:$G$57,0)),INDEX($E$4:$E$56,MATCH(Paramètres!N11,Paramètres!$G$5:$G$57,0))),1-$H10),IF(LEFT(TRIM(Paramètres!O11),1)="F",WORKDAY(IF(LEFT(TRIM(Paramètres!O11),1)="F",INDEX($F$4:$F$56,MATCH(Paramètres!N11,Paramètres!$G$5:$G$57,0)),INDEX($E$4:$E$56,MATCH(Paramètres!N11,Paramètres!$G$5:$G$57,0))),1),IF(LEFT(TRIM(Paramètres!O11),1)="F",INDEX($F$4:$F$56,MATCH(Paramètres!N11,Paramètres!$G$5:$G$57,0)),INDEX($E$4:$E$56,MATCH(Paramètres!N11,Paramètres!$G$5:$G$57,0))))))))) | F10: =IF($H10=0,WORKDAY(E10,-1),WORKDAY(E10,$H10-1)) | H10: =Paramètres!B11
B11: =Paramètres!G12 | C11: =IF(Paramètres!H12="","",Paramètres!H12) | D11: =IF(Paramètres!I12="","",Paramètres!I12) | E11: =IF(Paramètres!J12&Paramètres!L12&Paramètres!N12="",WORKDAY($A$6-1,1),MAX(IF(Paramètres!J12="",0,IF(Paramètres!K12="",NA(),IF(RIGHT(TRIM(Paramètres!K12),3)="Fin",WORKDAY(IF(LEFT(TRIM(Paramètres!K12),1)="F",INDEX($F$4:$F$56,MATCH(Paramètres!J12,Paramètres!$G$5:$G$57,0)),INDEX($E$4:$E$56,MATCH(Paramètres!J12,Paramètres!$G$5:$G$57,0))),1-$H11),IF(LEFT(TRIM(Paramètres!K12),1)="F",WORKDAY(IF(LEFT(TRIM(Paramètres!K12),1)="F",INDEX($F$4:$F$56,MATCH(Paramètres!J12,Paramètres!$G$5:$G$57,0)),INDEX($E$4:$E$56,MATCH(Paramètres!J12,Paramètres!$G$5:$G$57,0))),1),IF(LEFT(TRIM(Paramètres!K12),1)="F",INDEX($F$4:$F$56,MATCH(Paramètres!J12,Paramètres!$G$5:$G$57,0)),INDEX($E$4:$E$56,MATCH(Paramètres!J12,Paramètres!$G$5:$G$57,0))))))),IF(Paramètres!L12="",0,IF(Paramètres!M12="",NA(),IF(RIGHT(TRIM(Paramètres!M12),3)="Fin",WORKDAY(IF(LEFT(TRIM(Paramètres!M12),1)="F",INDEX($F$4:$F$56,MATCH(Paramètres!L12,Paramètres!$G$5:$G$57,0)),INDEX($E$4:$E$56,MATCH(Paramètres!L12,Paramètres!$G$5:$G$57,0))),1-$H11),IF(LEFT(TRIM(Paramètres!M12),1)="F",WORKDAY(IF(LEFT(TRIM(Paramètres!M12),1)="F",INDEX($F$4:$F$56,MATCH(Paramètres!L12,Paramètres!$G$5:$G$57,0)),INDEX($E$4:$E$56,MATCH(Paramètres!L12,Paramètres!$G$5:$G$57,0))),1),IF(LEFT(TRIM(Paramètres!M12),1)="F",INDEX($F$4:$F$56,MATCH(Paramètres!L12,Paramètres!$G$5:$G$57,0)),INDEX($E$4:$E$56,MATCH(Paramètres!L12,Paramètres!$G$5:$G$57,0))))))),IF(Paramètres!N12="",0,IF(Paramètres!O12="",NA(),IF(RIGHT(TRIM(Paramètres!O12),3)="Fin",WORKDAY(IF(LEFT(TRIM(Paramètres!O12),1)="F",INDEX($F$4:$F$56,MATCH(Paramètres!N12,Paramètres!$G$5:$G$57,0)),INDEX($E$4:$E$56,MATCH(Paramètres!N12,Paramètres!$G$5:$G$57,0))),1-$H11),IF(LEFT(TRIM(Paramètres!O12),1)="F",WORKDAY(IF(LEFT(TRIM(Paramètres!O12),1)="F",INDEX($F$4:$F$56,MATCH(Paramètres!N12,Paramètres!$G$5:$G$57,0)),INDEX($E$4:$E$56,MATCH(Paramètres!N12,Paramètres!$G$5:$G$57,0))),1),IF(LEFT(TRIM(Paramètres!O12),1)="F",INDEX($F$4:$F$56,MATCH(Paramètres!N12,Paramètres!$G$5:$G$57,0)),INDEX($E$4:$E$56,MATCH(Paramètres!N12,Paramètres!$G$5:$G$57,0))))))))) | F11: =IF($H11=0,WORKDAY(E11,-1),WORKDAY(E11,$H11-1)) | H11: =Paramètres!B12
B12: =Paramètres!G13 | C12: =IF(Paramètres!H13="","",Paramètres!H13) | D12: =IF(Paramètres!I13="","",Paramètres!I13) | E12: =IF(Paramètres!J13&Paramètres!L13&Paramètres!N13="",WORKDAY($A$6-1,1),MAX(IF(Paramètres!J13="",0,IF(Paramètres!K13="",NA(),IF(RIGHT(TRIM(Paramètres!K13),3)="Fin",WORKDAY(IF(LEFT(TRIM(Paramètres!K13),1)="F",INDEX($F$4:$F$56,MATCH(Paramètres!J13,Paramètres!$G$5:$G$57,0)),INDEX($E$4:$E$56,MATCH(Paramètres!J13,Paramètres!$G$5:$G$57,0))),1-$H12),IF(LEFT(TRIM(Paramètres!K13),1)="F",WORKDAY(IF(LEFT(TRIM(Paramètres!K13),1)="F",INDEX($F$4:$F$56,MATCH(Paramètres!J13,Paramètres!$G$5:$G$57,0)),INDEX($E$4:$E$56,MATCH(Paramètres!J13,Paramètres!$G$5:$G$57,0))),1),IF(LEFT(TRIM(Paramètres!K13),1)="F",INDEX($F$4:$F$56,MATCH(Paramètres!J13,Paramètres!$G$5:$G$57,0)),INDEX($E$4:$E$56,MATCH(Paramètres!J13,Paramètres!$G$5:$G$57,0))))))),IF(Paramètres!L13="",0,IF(Paramètres!M13="",NA(),IF(RIGHT(TRIM(Paramètres!M13),3)="Fin",WORKDAY(IF(LEFT(TRIM(Paramètres!M13),1)="F",INDEX($F$4:$F$56,MATCH(Paramètres!L13,Paramètres!$G$5:$G$57,0)),INDEX($E$4:$E$56,MATCH(Paramètres!L13,Paramètres!$G$5:$G$57,0))),1-$H12),IF(LEFT(TRIM(Paramètres!M13),1)="F",WORKDAY(IF(LEFT(TRIM(Paramètres!M13),1)="F",INDEX($F$4:$F$56,MATCH(Paramètres!L13,Paramètres!$G$5:$G$57,0)),INDEX($E$4:$E$56,MATCH(Paramètres!L13,Paramètres!$G$5:$G$57,0))),1),IF(LEFT(TRIM(Paramètres!M13),1)="F",INDEX($F$4:$F$56,MATCH(Paramètres!L13,Paramètres!$G$5:$G$57,0)),INDEX($E$4:$E$56,MATCH(Paramètres!L13,Paramètres!$G$5:$G$57,0))))))),IF(Paramètres!N13="",0,IF(Paramètres!O13="",NA(),IF(RIGHT(TRIM(Paramètres!O13),3)="Fin",WORKDAY(IF(LEFT(TRIM(Paramètres!O13),1)="F",INDEX($F$4:$F$56,MATCH(Paramètres!N13,Paramètres!$G$5:$G$57,0)),INDEX($E$4:$E$56,MATCH(Paramètres!N13,Paramètres!$G$5:$G$57,0))),1-$H12),IF(LEFT(TRIM(Paramètres!O13),1)="F",WORKDAY(IF(LEFT(TRIM(Paramètres!O13),1)="F",INDEX($F$4:$F$56,MATCH(Paramètres!N13,Paramètres!$G$5:$G$57,0)),INDEX($E$4:$E$56,MATCH(Paramètres!N13,Paramètres!$G$5:$G$57,0))),1),IF(LEFT(TRIM(Paramètres!O13),1)="F",INDEX($F$4:$F$56,MATCH(Paramètres!N13,Paramètres!$G$5:$G$57,0)),INDEX($E$4:$E$56,MATCH(Paramètres!N13,Paramètres!$G$5:$G$57,0))))))))) | F12: =IF($H12=0,WORKDAY(E12,-1),WORKDAY(E12,$H12-1)) | H12: =Paramètres!B13
B13: =Paramètres!G14 | C13: =IF(Paramètres!H14="","",Paramètres!H14) | D13: =IF(Paramètres!I14="","",Paramètres!I14) | E13: =IF(Paramètres!J14&Paramètres!L14&Paramètres!N14="",WORKDAY($A$6-1,1),MAX(IF(Paramètres!J14="",0,IF(Paramètres!K14="",NA(),IF(RIGHT(TRIM(Paramètres!K14),3)="Fin",WORKDAY(IF(LEFT(TRIM(Paramètres!K14),1)="F",INDEX($F$4:$F$56,MATCH(Paramètres!J14,Paramètres!$G$5:$G$57,0)),INDEX($E$4:$E$56,MATCH(Paramètres!J14,Paramètres!$G$5:$G$57,0))),1-$H13),IF(LEFT(TRIM(Paramètres!K14),1)="F",WORKDAY(IF(LEFT(TRIM(Paramètres!K14),1)="F",INDEX($F$4:$F$56,MATCH(Paramètres!J14,Paramètres!$G$5:$G$57,0)),INDEX($E$4:$E$56,MATCH(Paramètres!J14,Paramètres!$G$5:$G$57,0))),1),IF(LEFT(TRIM(Paramètres!K14),1)="F",INDEX($F$4:$F$56,MATCH(Paramètres!J14,Paramètres!$G$5:$G$57,0)),INDEX($E$4:$E$56,MATCH(Paramètres!J14,Paramètres!$G$5:$G$57,0))))))),IF(Paramètres!L14="",0,IF(Paramètres!M14="",NA(),IF(RIGHT(TRIM(Paramètres!M14),3)="Fin",WORKDAY(IF(LEFT(TRIM(Paramètres!M14),1)="F",INDEX($F$4:$F$56,MATCH(Paramètres!L14,Paramètres!$G$5:$G$57,0)),INDEX($E$4:$E$56,MATCH(Paramètres!L14,Paramètres!$G$5:$G$57,0))),1-$H13),IF(LEFT(TRIM(Paramètres!M14),1)="F",WORKDAY(IF(LEFT(TRIM(Paramètres!M14),1)="F",INDEX($F$4:$F$56,MATCH(Paramètres!L14,Paramètres!$G$5:$G$57,0)),INDEX($E$4:$E$56,MATCH(Paramètres!L14,Paramètres!$G$5:$G$57,0))),1),IF(LEFT(TRIM(Paramètres!M14),1)="F",INDEX($F$4:$F$56,MATCH(Paramètres!L14,Paramètres!$G$5:$G$57,0)),INDEX($E$4:$E$56,MATCH(Paramètres!L14,Paramètres!$G$5:$G$57,0))))))),IF(Paramètres!N14="",0,IF(Paramètres!O14="",NA(),IF(RIGHT(TRIM(Paramètres!O14),3)="Fin",WORKDAY(IF(LEFT(TRIM(Paramètres!O14),1)="F",INDEX($F$4:$F$56,MATCH(Paramètres!N14,Paramètres!$G$5:$G$57,0)),INDEX($E$4:$E$56,MATCH(Paramètres!N14,Paramètres!$G$5:$G$57,0))),1-$H13),IF(LEFT(TRIM(Paramètres!O14),1)="F",WORKDAY(IF(LEFT(TRIM(Paramètres!O14),1)="F",INDEX($F$4:$F$56,MATCH(Paramètres!N14,Paramètres!$G$5:$G$57,0)),INDEX($E$4:$E$56,MATCH(Paramètres!N14,Paramètres!$G$5:$G$57,0))),1),IF(LEFT(TRIM(Paramètres!O14),1)="F",INDEX($F$4:$F$56,MATCH(Paramètres!N14,Paramètres!$G$5:$G$57,0)),INDEX($E$4:$E$56,MATCH(Paramètres!N14,Paramètres!$G$5:$G$57,0))))))))) | F13: =IF($H13=0,WORKDAY(E13,-1),WORKDAY(E13,$H13-1)) | H13: =Paramètres!B14
B14: =Paramètres!G15 | C14: =IF(Paramètres!H15="","",Paramètres!H15) | D14: =IF(Paramètres!I15="","",Paramètres!I15) | E14: =MIN(E15:E30) | F14: =MAX(F15:F30) | H14: =NETWORKDAYS(E14,F14)
B15: =Paramètres!G16 | C15: =IF(Paramètres!H16="","",Paramètres!H16) | D15: =IF(Paramètres!I16="","",Paramètres!I16) | E15: =IF(Paramètres!J16&Paramètres!L16&Paramètres!N16="",WORKDAY($A$6-1,1),MAX(IF(Paramètres!J16="",0,IF(Paramètres!K16="",NA(),IF(RIGHT(TRIM(Paramètres!K16),3)="Fin",WORKDAY(IF(LEFT(TRIM(Paramètres!K16),1)="F",INDEX($F$4:$F$56,MATCH(Paramètres!J16,Paramètres!$G$5:$G$57,0)),INDEX($E$4:$E$56,MATCH(Paramètres!J16,Paramètres!$G$5:$G$57,0))),1-$H15),IF(LEFT(TRIM(Paramètres!K16),1)="F",WORKDAY(IF(LEFT(TRIM(Paramètres!K16),1)="F",INDEX($F$4:$F$56,MATCH(Paramètres!J16,Paramètres!$G$5:$G$57,0)),INDEX($E$4:$E$56,MATCH(Paramètres!J16,Paramètres!$G$5:$G$57,0))),1),IF(LEFT(TRIM(Paramètres!K16),1)="F",INDEX($F$4:$F$56,MATCH(Paramètres!J16,Paramètres!$G$5:$G$57,0)),INDEX($E$4:$E$56,MATCH(Paramètres!J16,Paramètres!$G$5:$G$57,0))))))),IF(Paramètres!L16="",0,IF(Paramètres!M16="",NA(),IF(RIGHT(TRIM(Paramètres!M16),3)="Fin",WORKDAY(IF(LEFT(TRIM(Paramètres!M16),1)="F",INDEX($F$4:$F$56,MATCH(Paramètres!L16,Paramètres!$G$5:$G$57,0)),INDEX($E$4:$E$56,MATCH(Paramètres!L16,Paramètres!$G$5:$G$57,0))),1-$H15),IF(LEFT(TRIM(Paramètres!M16),1)="F",WORKDAY(IF(LEFT(TRIM(Paramètres!M16),1)="F",INDEX($F$4:$F$56,MATCH(Paramètres!L16,Paramètres!$G$5:$G$57,0)),INDEX($E$4:$E$56,MATCH(Paramètres!L16,Paramètres!$G$5:$G$57,0))),1),IF(LEFT(TRIM(Paramètres!M16),1)="F",INDEX($F$4:$F$56,MATCH(Paramètres!L16,Paramètres!$G$5:$G$57,0)),INDEX($E$4:$E$56,MATCH(Paramètres!L16,Paramètres!$G$5:$G$57,0))))))),IF(Paramètres!N16="",0,IF(Paramètres!O16="",NA(),IF(RIGHT(TRIM(Paramètres!O16),3)="Fin",WORKDAY(IF(LEFT(TRIM(Paramètres!O16),1)="F",INDEX($F$4:$F$56,MATCH(Paramètres!N16,Paramètres!$G$5:$G$57,0)),INDEX($E$4:$E$56,MATCH(Paramètres!N16,Paramètres!$G$5:$G$57,0))),1-$H15),IF(LEFT(TRIM(Paramètres!O16),1)="F",WORKDAY(IF(LEFT(TRIM(Paramètres!O16),1)="F",INDEX($F$4:$F$56,MATCH(Paramètres!N16,Paramètres!$G$5:$G$57,0)),INDEX($E$4:$E$56,MATCH(Paramètres!N16,Paramètres!$G$5:$G$57,0))),1),IF(LEFT(TRIM(Paramètres!O16),1)="F",INDEX($F$4:$F$56,MATCH(Paramètres!N16,Paramètres!$G$5:$G$57,0)),INDEX($E$4:$E$56,MATCH(Paramètres!N16,Paramètres!$G$5:$G$57,0))))))))) | F15: =IF($H15=0,WORKDAY(E15,-1),WORKDAY(E15,$H15-1)) | H15: =Paramètres!B16
B16: =Paramètres!G17 | C16: =IF(Paramètres!H17="","",Paramètres!H17) | D16: =IF(Paramètres!I17="","",Paramètres!I17) | E16: =IF(Paramètres!J17&Paramètres!L17&Paramètres!N17="",WORKDAY($A$6-1,1),MAX(IF(Paramètres!J17="",0,IF(Paramètres!K17="",NA(),IF(RIGHT(TRIM(Paramètres!K17),3)="Fin",WORKDAY(IF(LEFT(TRIM(Paramètres!K17),1)="F",INDEX($F$4:$F$56,MATCH(Paramètres!J17,Paramètres!$G$5:$G$57,0)),INDEX($E$4:$E$56,MATCH(Paramètres!J17,Paramètres!$G$5:$G$57,0))),1-$H16),IF(LEFT(TRIM(Paramètres!K17),1)="F",WORKDAY(IF(LEFT(TRIM(Paramètres!K17),1)="F",INDEX($F$4:$F$56,MATCH(Paramètres!J17,Paramètres!$G$5:$G$57,0)),INDEX($E$4:$E$56,MATCH(Paramètres!J17,Paramètres!$G$5:$G$57,0))),1),IF(LEFT(TRIM(Paramètres!K17),1)="F",INDEX($F$4:$F$56,MATCH(Paramètres!J17,Paramètres!$G$5:$G$57,0)),INDEX($E$4:$E$56,MATCH(Paramètres!J17,Paramètres!$G$5:$G$57,0))))))),IF(Paramètres!L17="",0,IF(Paramètres!M17="",NA(),IF(RIGHT(TRIM(Paramètres!M17),3)="Fin",WORKDAY(IF(LEFT(TRIM(Paramètres!M17),1)="F",INDEX($F$4:$F$56,MATCH(Paramètres!L17,Paramètres!$G$5:$G$57,0)),INDEX($E$4:$E$56,MATCH(Paramètres!L17,Paramètres!$G$5:$G$57,0))),1-$H16),IF(LEFT(TRIM(Paramètres!M17),1)="F",WORKDAY(IF(LEFT(TRIM(Paramètres!M17),1)="F",INDEX($F$4:$F$56,MATCH(Paramètres!L17,Paramètres!$G$5:$G$57,0)),INDEX($E$4:$E$56,MATCH(Paramètres!L17,Paramètres!$G$5:$G$57,0))),1),IF(LEFT(TRIM(Paramètres!M17),1)="F",INDEX($F$4:$F$56,MATCH(Paramètres!L17,Paramètres!$G$5:$G$57,0)),INDEX($E$4:$E$56,MATCH(Paramètres!L17,Paramètres!$G$5:$G$57,0))))))),IF(Paramètres!N17="",0,IF(Paramètres!O17="",NA(),IF(RIGHT(TRIM(Paramètres!O17),3)="Fin",WORKDAY(IF(LEFT(TRIM(Paramètres!O17),1)="F",INDEX($F$4:$F$56,MATCH(Paramètres!N17,Paramètres!$G$5:$G$57,0)),INDEX($E$4:$E$56,MATCH(Paramètres!N17,Paramètres!$G$5:$G$57,0))),1-$H16),IF(LEFT(TRIM(Paramètres!O17),1)="F",WORKDAY(IF(LEFT(TRIM(Paramètres!O17),1)="F",INDEX($F$4:$F$56,MATCH(Paramètres!N17,Paramètres!$G$5:$G$57,0)),INDEX($E$4:$E$56,MATCH(Paramètres!N17,Paramètres!$G$5:$G$57,0))),1),IF(LEFT(TRIM(Paramètres!O17),1)="F",INDEX($F$4:$F$56,MATCH(Paramètres!N17,Paramètres!$G$5:$G$57,0)),INDEX($E$4:$E$56,MATCH(Paramètres!N17,Paramètres!$G$5:$G$57,0))))))))) | F16: =IF($H16=0,WORKDAY(E16,-1),WORKDAY(E16,$H16-1)) | H16: =Paramètres!B17
B17: =Paramètres!G18 | C17: =IF(Paramètres!H18="","",Paramètres!H18) | D17: =IF(Paramètres!I18="","",Paramètres!I18) | E17: =IF(Paramètres!J18&Paramètres!L18&Paramètres!N18="",WORKDAY($A$6-1,1),MAX(IF(Paramètres!J18="",0,IF(Paramètres!K18="",NA(),IF(RIGHT(TRIM(Paramètres!K18),3)="Fin",WORKDAY(IF(LEFT(TRIM(Paramètres!K18),1)="F",INDEX($F$4:$F$56,MATCH(Paramètres!J18,Paramètres!$G$5:$G$57,0)),INDEX($E$4:$E$56,MATCH(Paramètres!J18,Paramètres!$G$5:$G$57,0))),1-$H17),IF(LEFT(TRIM(Paramètres!K18),1)="F",WORKDAY(IF(LEFT(TRIM(Paramètres!K18),1)="F",INDEX($F$4:$F$56,MATCH(Paramètres!J18,Paramètres!$G$5:$G$57,0)),INDEX($E$4:$E$56,MATCH(Paramètres!J18,Paramètres!$G$5:$G$57,0))),1),IF(LEFT(TRIM(Paramètres!K18),1)="F",INDEX($F$4:$F$56,MATCH(Paramètres!J18,Paramètres!$G$5:$G$57,0)),INDEX($E$4:$E$56,MATCH(Paramètres!J18,Paramètres!$G$5:$G$57,0))))))),IF(Paramètres!L18="",0,IF(Paramètres!M18="",NA(),IF(RIGHT(TRIM(Paramètres!M18),3)="Fin",WORKDAY(IF(LEFT(TRIM(Paramètres!M18),1)="F",INDEX($F$4:$F$56,MATCH(Paramètres!L18,Paramètres!$G$5:$G$57,0)),INDEX($E$4:$E$56,MATCH(Paramètres!L18,Paramètres!$G$5:$G$57,0))),1-$H17),IF(LEFT(TRIM(Paramètres!M18),1)="F",WORKDAY(IF(LEFT(TRIM(Paramètres!M18),1)="F",INDEX($F$4:$F$56,MATCH(Paramètres!L18,Paramètres!$G$5:$G$57,0)),INDEX($E$4:$E$56,MATCH(Paramètres!L18,Paramètres!$G$5:$G$57,0))),1),IF(LEFT(TRIM(Paramètres!M18),1)="F",INDEX($F$4:$F$56,MATCH(Paramètres!L18,Paramètres!$G$5:$G$57,0)),INDEX($E$4:$E$56,MATCH(Paramètres!L18,Paramètres!$G$5:$G$57,0))))))),IF(Paramètres!N18="",0,IF(Paramètres!O18="",NA(),IF(RIGHT(TRIM(Paramètres!O18),3)="Fin",WORKDAY(IF(LEFT(TRIM(Paramètres!O18),1)="F",INDEX($F$4:$F$56,MATCH(Paramètres!N18,Paramètres!$G$5:$G$57,0)),INDEX($E$4:$E$56,MATCH(Paramètres!N18,Paramètres!$G$5:$G$57,0))),1-$H17),IF(LEFT(TRIM(Paramètres!O18),1)="F",WORKDAY(IF(LEFT(TRIM(Paramètres!O18),1)="F",INDEX($F$4:$F$56,MATCH(Paramètres!N18,Paramètres!$G$5:$G$57,0)),INDEX($E$4:$E$56,MATCH(Paramètres!N18,Paramètres!$G$5:$G$57,0))),1),IF(LEFT(TRIM(Paramètres!O18),1)="F",INDEX($F$4:$F$56,MATCH(Paramètres!N18,Paramètres!$G$5:$G$57,0)),INDEX($E$4:$E$56,MATCH(Paramètres!N18,Paramètres!$G$5:$G$57,0))))))))) | F17: =IF($H17=0,WORKDAY(E17,-1),WORKDAY(E17,$H17-1)) | H17: =Paramètres!B18
B18: =Paramètres!G19 | C18: =IF(Paramètres!H19="","",Paramètres!H19) | D18: =IF(Paramètres!I19="","",Paramètres!I19) | E18: =IF(Paramètres!J19&Paramètres!L19&Paramètres!N19="",WORKDAY($A$6-1,1),MAX(IF(Paramètres!J19="",0,IF(Paramètres!K19="",NA(),IF(RIGHT(TRIM(Paramètres!K19),3)="Fin",WORKDAY(IF(LEFT(TRIM(Paramètres!K19),1)="F",INDEX($F$4:$F$56,MATCH(Paramètres!J19,Paramètres!$G$5:$G$57,0)),INDEX($E$4:$E$56,MATCH(Paramètres!J19,Paramètres!$G$5:$G$57,0))),1-$H18),IF(LEFT(TRIM(Paramètres!K19),1)="F",WORKDAY(IF(LEFT(TRIM(Paramètres!K19),1)="F",INDEX($F$4:$F$56,MATCH(Paramètres!J19,Paramètres!$G$5:$G$57,0)),INDEX($E$4:$E$56,MATCH(Paramètres!J19,Paramètres!$G$5:$G$57,0))),1),IF(LEFT(TRIM(Paramètres!K19),1)="F",INDEX($F$4:$F$56,MATCH(Paramètres!J19,Paramètres!$G$5:$G$57,0)),INDEX($E$4:$E$56,MATCH(Paramètres!J19,Paramètres!$G$5:$G$57,0))))))),IF(Paramètres!L19="",0,IF(Paramètres!M19="",NA(),IF(RIGHT(TRIM(Paramètres!M19),3)="Fin",WORKDAY(IF(LEFT(TRIM(Paramètres!M19),1)="F",INDEX($F$4:$F$56,MATCH(Paramètres!L19,Paramètres!$G$5:$G$57,0)),INDEX($E$4:$E$56,MATCH(Paramètres!L19,Paramètres!$G$5:$G$57,0))),1-$H18),IF(LEFT(TRIM(Paramètres!M19),1)="F",WORKDAY(IF(LEFT(TRIM(Paramètres!M19),1)="F",INDEX($F$4:$F$56,MATCH(Paramètres!L19,Paramètres!$G$5:$G$57,0)),INDEX($E$4:$E$56,MATCH(Paramètres!L19,Paramètres!$G$5:$G$57,0))),1),IF(LEFT(TRIM(Paramètres!M19),1)="F",INDEX($F$4:$F$56,MATCH(Paramètres!L19,Paramètres!$G$5:$G$57,0)),INDEX($E$4:$E$56,MATCH(Paramètres!L19,Paramètres!$G$5:$G$57,0))))))),IF(Paramètres!N19="",0,IF(Paramètres!O19="",NA(),IF(RIGHT(TRIM(Paramètres!O19),3)="Fin",WORKDAY(IF(LEFT(TRIM(Paramètres!O19),1)="F",INDEX($F$4:$F$56,MATCH(Paramètres!N19,Paramètres!$G$5:$G$57,0)),INDEX($E$4:$E$56,MATCH(Paramètres!N19,Paramètres!$G$5:$G$57,0))),1-$H18),IF(LEFT(TRIM(Paramètres!O19),1)="F",WORKDAY(IF(LEFT(TRIM(Paramètres!O19),1)="F",INDEX($F$4:$F$56,MATCH(Paramètres!N19,Paramètres!$G$5:$G$57,0)),INDEX($E$4:$E$56,MATCH(Paramètres!N19,Paramètres!$G$5:$G$57,0))),1),IF(LEFT(TRIM(Paramètres!O19),1)="F",INDEX($F$4:$F$56,MATCH(Paramètres!N19,Paramètres!$G$5:$G$57,0)),INDEX($E$4:$E$56,MATCH(Paramètres!N19,Paramètres!$G$5:$G$57,0))))))))) | F18: =IF($H18=0,WORKDAY(E18,-1),WORKDAY(E18,$H18-1)) | H18: =Paramètres!B19
B19: =Paramètres!G20 | C19: =IF(Paramètres!H20="","",Paramètres!H20) | D19: =IF(Paramètres!I20="","",Paramètres!I20) | E19: =IF(Paramètres!J20&Paramètres!L20&Paramètres!N20="",WORKDAY($A$6-1,1),MAX(IF(Paramètres!J20="",0,IF(Paramètres!K20="",NA(),IF(RIGHT(TRIM(Paramètres!K20),3)="Fin",WORKDAY(IF(LEFT(TRIM(Paramètres!K20),1)="F",INDEX($F$4:$F$56,MATCH(Paramètres!J20,Paramètres!$G$5:$G$57,0)),INDEX($E$4:$E$56,MATCH(Paramètres!J20,Paramètres!$G$5:$G$57,0))),1-$H19),IF(LEFT(TRIM(Paramètres!K20),1)="F",WORKDAY(IF(LEFT(TRIM(Paramètres!K20),1)="F",INDEX($F$4:$F$56,MATCH(Paramètres!J20,Paramètres!$G$5:$G$57,0)),INDEX($E$4:$E$56,MATCH(Paramètres!J20,Paramètres!$G$5:$G$57,0))),1),IF(LEFT(TRIM(Paramètres!K20),1)="F",INDEX($F$4:$F$56,MATCH(Paramètres!J20,Paramètres!$G$5:$G$57,0)),INDEX($E$4:$E$56,MATCH(Paramètres!J20,Paramètres!$G$5:$G$57,0))))))),IF(Paramètres!L20="",0,IF(Paramètres!M20="",NA(),IF(RIGHT(TRIM(Paramètres!M20),3)="Fin",WORKDAY(IF(LEFT(TRIM(Paramètres!M20),1)="F",INDEX($F$4:$F$56,MATCH(Paramètres!L20,Paramètres!$G$5:$G$57,0)),INDEX($E$4:$E$56,MATCH(Paramètres!L20,Paramètres!$G$5:$G$57,0))),1-$H19),IF(LEFT(TRIM(Paramètres!M20),1)="F",WORKDAY(IF(LEFT(TRIM(Paramètres!M20),1)="F",INDEX($F$4:$F$56,MATCH(Paramètres!L20,Paramètres!$G$5:$G$57,0)),INDEX($E$4:$E$56,MATCH(Paramètres!L20,Paramètres!$G$5:$G$57,0))),1),IF(LEFT(TRIM(Paramètres!M20),1)="F",INDEX($F$4:$F$56,MATCH(Paramètres!L20,Paramètres!$G$5:$G$57,0)),INDEX($E$4:$E$56,MATCH(Paramètres!L20,Paramètres!$G$5:$G$57,0))))))),IF(Paramètres!N20="",0,IF(Paramètres!O20="",NA(),IF(RIGHT(TRIM(Paramètres!O20),3)="Fin",WORKDAY(IF(LEFT(TRIM(Paramètres!O20),1)="F",INDEX($F$4:$F$56,MATCH(Paramètres!N20,Paramètres!$G$5:$G$57,0)),INDEX($E$4:$E$56,MATCH(Paramètres!N20,Paramètres!$G$5:$G$57,0))),1-$H19),IF(LEFT(TRIM(Paramètres!O20),1)="F",WORKDAY(IF(LEFT(TRIM(Paramètres!O20),1)="F",INDEX($F$4:$F$56,MATCH(Paramètres!N20,Paramètres!$G$5:$G$57,0)),INDEX($E$4:$E$56,MATCH(Paramètres!N20,Paramètres!$G$5:$G$57,0))),1),IF(LEFT(TRIM(Paramètres!O20),1)="F",INDEX($F$4:$F$56,MATCH(Paramètres!N20,Paramètres!$G$5:$G$57,0)),INDEX($E$4:$E$56,MATCH(Paramètres!N20,Paramètres!$G$5:$G$57,0))))))))) | F19: =IF($H19=0,WORKDAY(E19,-1),WORKDAY(E19,$H19-1)) | H19: =Paramètres!B20
B20: =Paramètres!G21 | C20: =IF(Paramètres!H21="","",Paramètres!H21) | D20: =IF(Paramètres!I21="","",Paramètres!I21) | E20: =IF(Paramètres!J21&Paramètres!L21&Paramètres!N21="",WORKDAY($A$6-1,1),MAX(IF(Paramètres!J21="",0,IF(Paramètres!K21="",NA(),IF(RIGHT(TRIM(Paramètres!K21),3)="Fin",WORKDAY(IF(LEFT(TRIM(Paramètres!K21),1)="F",INDEX($F$4:$F$56,MATCH(Paramètres!J21,Paramètres!$G$5:$G$57,0)),INDEX($E$4:$E$56,MATCH(Paramètres!J21,Paramètres!$G$5:$G$57,0))),1-$H20),IF(LEFT(TRIM(Paramètres!K21),1)="F",WORKDAY(IF(LEFT(TRIM(Paramètres!K21),1)="F",INDEX($F$4:$F$56,MATCH(Paramètres!J21,Paramètres!$G$5:$G$57,0)),INDEX($E$4:$E$56,MATCH(Paramètres!J21,Paramètres!$G$5:$G$57,0))),1),IF(LEFT(TRIM(Paramètres!K21),1)="F",INDEX($F$4:$F$56,MATCH(Paramètres!J21,Paramètres!$G$5:$G$57,0)),INDEX($E$4:$E$56,MATCH(Paramètres!J21,Paramètres!$G$5:$G$57,0))))))),IF(Paramètres!L21="",0,IF(Paramètres!M21="",NA(),IF(RIGHT(TRIM(Paramètres!M21),3)="Fin",WORKDAY(IF(LEFT(TRIM(Paramètres!M21),1)="F",INDEX($F$4:$F$56,MATCH(Paramètres!L21,Paramètres!$G$5:$G$57,0)),INDEX($E$4:$E$56,MATCH(Paramètres!L21,Paramètres!$G$5:$G$57,0))),1-$H20),IF(LEFT(TRIM(Paramètres!M21),1)="F",WORKDAY(IF(LEFT(TRIM(Paramètres!M21),1)="F",INDEX($F$4:$F$56,MATCH(Paramètres!L21,Paramètres!$G$5:$G$57,0)),INDEX($E$4:$E$56,MATCH(Paramètres!L21,Paramètres!$G$5:$G$57,0))),1),IF(LEFT(TRIM(Paramètres!M21),1)="F",INDEX($F$4:$F$56,MATCH(Paramètres!L21,Paramètres!$G$5:$G$57,0)),INDEX($E$4:$E$56,MATCH(Paramètres!L21,Paramètres!$G$5:$G$57,0))))))),IF(Paramètres!N21="",0,IF(Paramètres!O21="",NA(),IF(RIGHT(TRIM(Paramètres!O21),3)="Fin",WORKDAY(IF(LEFT(TRIM(Paramètres!O21),1)="F",INDEX($F$4:$F$56,MATCH(Paramètres!N21,Paramètres!$G$5:$G$57,0)),INDEX($E$4:$E$56,MATCH(Paramètres!N21,Paramètres!$G$5:$G$57,0))),1-$H20),IF(LEFT(TRIM(Paramètres!O21),1)="F",WORKDAY(IF(LEFT(TRIM(Paramètres!O21),1)="F",INDEX($F$4:$F$56,MATCH(Paramètres!N21,Paramètres!$G$5:$G$57,0)),INDEX($E$4:$E$56,MATCH(Paramètres!N21,Paramètres!$G$5:$G$57,0))),1),IF(LEFT(TRIM(Paramètres!O21),1)="F",INDEX($F$4:$F$56,MATCH(Paramètres!N21,Paramètres!$G$5:$G$57,0)),INDEX($E$4:$E$56,MATCH(Paramètres!N21,Paramètres!$G$5:$G$57,0))))))))) | F20: =IF($H20=0,WORKDAY(E20,-1),WORKDAY(E20,$H20-1)) | H20: =Paramètres!B21
B21: =Paramètres!G22 | C21: =IF(Paramètres!H22="","",Paramètres!H22) | D21: =IF(Paramètres!I22="","",Paramètres!I22) | E21: =IF(Paramètres!J22&Paramètres!L22&Paramètres!N22="",WORKDAY($A$6-1,1),MAX(IF(Paramètres!J22="",0,IF(Paramètres!K22="",NA(),IF(RIGHT(TRIM(Paramètres!K22),3)="Fin",WORKDAY(IF(LEFT(TRIM(Paramètres!K22),1)="F",INDEX($F$4:$F$56,MATCH(Paramètres!J22,Paramètres!$G$5:$G$57,0)),INDEX($E$4:$E$56,MATCH(Paramètres!J22,Paramètres!$G$5:$G$57,0))),1-$H21),IF(LEFT(TRIM(Paramètres!K22),1)="F",WORKDAY(IF(LEFT(TRIM(Paramètres!K22),1)="F",INDEX($F$4:$F$56,MATCH(Paramètres!J22,Paramètres!$G$5:$G$57,0)),INDEX($E$4:$E$56,MATCH(Paramètres!J22,Paramètres!$G$5:$G$57,0))),1),IF(LEFT(TRIM(Paramètres!K22),1)="F",INDEX($F$4:$F$56,MATCH(Paramètres!J22,Paramètres!$G$5:$G$57,0)),INDEX($E$4:$E$56,MATCH(Paramètres!J22,Paramètres!$G$5:$G$57,0))))))),IF(Paramètres!L22="",0,IF(Paramètres!M22="",NA(),IF(RIGHT(TRIM(Paramètres!M22),3)="Fin",WORKDAY(IF(LEFT(TRIM(Paramètres!M22),1)="F",INDEX($F$4:$F$56,MATCH(Paramètres!L22,Paramètres!$G$5:$G$57,0)),INDEX($E$4:$E$56,MATCH(Paramètres!L22,Paramètres!$G$5:$G$57,0))),1-$H21),IF(LEFT(TRIM(Paramètres!M22),1)="F",WORKDAY(IF(LEFT(TRIM(Paramètres!M22),1)="F",INDEX($F$4:$F$56,MATCH(Paramètres!L22,Paramètres!$G$5:$G$57,0)),INDEX($E$4:$E$56,MATCH(Paramètres!L22,Paramètres!$G$5:$G$57,0))),1),IF(LEFT(TRIM(Paramètres!M22),1)="F",INDEX($F$4:$F$56,MATCH(Paramètres!L22,Paramètres!$G$5:$G$57,0)),INDEX($E$4:$E$56,MATCH(Paramètres!L22,Paramètres!$G$5:$G$57,0))))))),IF(Paramètres!N22="",0,IF(Paramètres!O22="",NA(),IF(RIGHT(TRIM(Paramètres!O22),3)="Fin",WORKDAY(IF(LEFT(TRIM(Paramètres!O22),1)="F",INDEX($F$4:$F$56,MATCH(Paramètres!N22,Paramètres!$G$5:$G$57,0)),INDEX($E$4:$E$56,MATCH(Paramètres!N22,Paramètres!$G$5:$G$57,0))),1-$H21),IF(LEFT(TRIM(Paramètres!O22),1)="F",WORKDAY(IF(LEFT(TRIM(Paramètres!O22),1)="F",INDEX($F$4:$F$56,MATCH(Paramètres!N22,Paramètres!$G$5:$G$57,0)),INDEX($E$4:$E$56,MATCH(Paramètres!N22,Paramètres!$G$5:$G$57,0))),1),IF(LEFT(TRIM(Paramètres!O22),1)="F",INDEX($F$4:$F$56,MATCH(Paramètres!N22,Paramètres!$G$5:$G$57,0)),INDEX($E$4:$E$56,MATCH(Paramètres!N22,Paramètres!$G$5:$G$57,0))))))))) | F21: =IF($H21=0,WORKDAY(E21,-1),WORKDAY(E21,$H21-1)) | H21: =Paramètres!B22
B22: =Paramètres!G23 | C22: =IF(Paramètres!H23="","",Paramètres!H23) | D22: =IF(Paramètres!I23="","",Paramètres!I23) | E22: =IF(Paramètres!J23&Paramètres!L23&Paramètres!N23="",WORKDAY($A$6-1,1),MAX(IF(Paramètres!J23="",0,IF(Paramètres!K23="",NA(),IF(RIGHT(TRIM(Paramètres!K23),3)="Fin",WORKDAY(IF(LEFT(TRIM(Paramètres!K23),1)="F",INDEX($F$4:$F$56,MATCH(Paramètres!J23,Paramètres!$G$5:$G$57,0)),INDEX($E$4:$E$56,MATCH(Paramètres!J23,Paramètres!$G$5:$G$57,0))),1-$H22),IF(LEFT(TRIM(Paramètres!K23),1)="F",WORKDAY(IF(LEFT(TRIM(Paramètres!K23),1)="F",INDEX($F$4:$F$56,MATCH(Paramètres!J23,Paramètres!$G$5:$G$57,0)),INDEX($E$4:$E$56,MATCH(Paramètres!J23,Paramètres!$G$5:$G$57,0))),1),IF(LEFT(TRIM(Paramètres!K23),1)="F",INDEX($F$4:$F$56,MATCH(Paramètres!J23,Paramètres!$G$5:$G$57,0)),INDEX($E$4:$E$56,MATCH(Paramètres!J23,Paramètres!$G$5:$G$57,0))))))),IF(Paramètres!L23="",0,IF(Paramètres!M23="",NA(),IF(RIGHT(TRIM(Paramètres!M23),3)="Fin",WORKDAY(IF(LEFT(TRIM(Paramètres!M23),1)="F",INDEX($F$4:$F$56,MATCH(Paramètres!L23,Paramètres!$G$5:$G$57,0)),INDEX($E$4:$E$56,MATCH(Paramètres!L23,Paramètres!$G$5:$G$57,0))),1-$H22),IF(LEFT(TRIM(Paramètres!M23),1)="F",WORKDAY(IF(LEFT(TRIM(Paramètres!M23),1)="F",INDEX($F$4:$F$56,MATCH(Paramètres!L23,Paramètres!$G$5:$G$57,0)),INDEX($E$4:$E$56,MATCH(Paramètres!L23,Paramètres!$G$5:$G$57,0))),1),IF(LEFT(TRIM(Paramètres!M23),1)="F",INDEX($F$4:$F$56,MATCH(Paramètres!L23,Paramètres!$G$5:$G$57,0)),INDEX($E$4:$E$56,MATCH(Paramètres!L23,Paramètres!$G$5:$G$57,0))))))),IF(Paramètres!N23="",0,IF(Paramètres!O23="",NA(),IF(RIGHT(TRIM(Paramètres!O23),3)="Fin",WORKDAY(IF(LEFT(TRIM(Paramètres!O23),1)="F",INDEX($F$4:$F$56,MATCH(Paramètres!N23,Paramètres!$G$5:$G$57,0)),INDEX($E$4:$E$56,MATCH(Paramètres!N23,Paramètres!$G$5:$G$57,0))),1-$H22),IF(LEFT(TRIM(Paramètres!O23),1)="F",WORKDAY(IF(LEFT(TRIM(Paramètres!O23),1)="F",INDEX($F$4:$F$56,MATCH(Paramètres!N23,Paramètres!$G$5:$G$57,0)),INDEX($E$4:$E$56,MATCH(Paramètres!N23,Paramètres!$G$5:$G$57,0))),1),IF(LEFT(TRIM(Paramètres!O23),1)="F",INDEX($F$4:$F$56,MATCH(Paramètres!N23,Paramètres!$G$5:$G$57,0)),INDEX($E$4:$E$56,MATCH(Paramètres!N23,Paramètres!$G$5:$G$57,0))))))))) | F22: =IF($H22=0,WORKDAY(E22,-1),WORKDAY(E22,$H22-1)) | H22: =Paramètres!B23
B23: =Paramètres!G24 | C23: =IF(Paramètres!H24="","",Paramètres!H24) | D23: =IF(Paramètres!I24="","",Paramètres!I24) | E23: =IF(Paramètres!J24&Paramètres!L24&Paramètres!N24="",WORKDAY($A$6-1,1),MAX(IF(Paramètres!J24="",0,IF(Paramètres!K24="",NA(),IF(RIGHT(TRIM(Paramètres!K24),3)="Fin",WORKDAY(IF(LEFT(TRIM(Paramètres!K24),1)="F",INDEX($F$4:$F$56,MATCH(Paramètres!J24,Paramètres!$G$5:$G$57,0)),INDEX($E$4:$E$56,MATCH(Paramètres!J24,Paramètres!$G$5:$G$57,0))),1-$H23),IF(LEFT(TRIM(Paramètres!K24),1)="F",WORKDAY(IF(LEFT(TRIM(Paramètres!K24),1)="F",INDEX($F$4:$F$56,MATCH(Paramètres!J24,Paramètres!$G$5:$G$57,0)),INDEX($E$4:$E$56,MATCH(Paramètres!J24,Paramètres!$G$5:$G$57,0))),1),IF(LEFT(TRIM(Paramètres!K24),1)="F",INDEX($F$4:$F$56,MATCH(Paramètres!J24,Paramètres!$G$5:$G$57,0)),INDEX($E$4:$E$56,MATCH(Paramètres!J24,Paramètres!$G$5:$G$57,0))))))),IF(Paramètres!L24="",0,IF(Paramètres!M24="",NA(),IF(RIGHT(TRIM(Paramètres!M24),3)="Fin",WORKDAY(IF(LEFT(TRIM(Paramètres!M24),1)="F",INDEX($F$4:$F$56,MATCH(Paramètres!L24,Paramètres!$G$5:$G$57,0)),INDEX($E$4:$E$56,MATCH(Paramètres!L24,Paramètres!$G$5:$G$57,0))),1-$H23),IF(LEFT(TRIM(Paramètres!M24),1)="F",WORKDAY(IF(LEFT(TRIM(Paramètres!M24),1)="F",INDEX($F$4:$F$56,MATCH(Paramètres!L24,Paramètres!$G$5:$G$57,0)),INDEX($E$4:$E$56,MATCH(Paramètres!L24,Paramètres!$G$5:$G$57,0))),1),IF(LEFT(TRIM(Paramètres!M24),1)="F",INDEX($F$4:$F$56,MATCH(Paramètres!L24,Paramètres!$G$5:$G$57,0)),INDEX($E$4:$E$56,MATCH(Paramètres!L24,Paramètres!$G$5:$G$57,0))))))),IF(Paramètres!N24="",0,IF(Paramètres!O24="",NA(),IF(RIGHT(TRIM(Paramètres!O24),3)="Fin",WORKDAY(IF(LEFT(TRIM(Paramètres!O24),1)="F",INDEX($F$4:$F$56,MATCH(Paramètres!N24,Paramètres!$G$5:$G$57,0)),INDEX($E$4:$E$56,MATCH(Paramètres!N24,Paramètres!$G$5:$G$57,0))),1-$H23),IF(LEFT(TRIM(Paramètres!O24),1)="F",WORKDAY(IF(LEFT(TRIM(Paramètres!O24),1)="F",INDEX($F$4:$F$56,MATCH(Paramètres!N24,Paramètres!$G$5:$G$57,0)),INDEX($E$4:$E$56,MATCH(Paramètres!N24,Paramètres!$G$5:$G$57,0))),1),IF(LEFT(TRIM(Paramètres!O24),1)="F",INDEX($F$4:$F$56,MATCH(Paramètres!N24,Paramètres!$G$5:$G$57,0)),INDEX($E$4:$E$56,MATCH(Paramètres!N24,Paramètres!$G$5:$G$57,0))))))))) | F23: =IF($H23=0,WORKDAY(E23,-1),WORKDAY(E23,$H23-1)) | H23: =Paramètres!B24
B24: =Paramètres!G25 | C24: =IF(Paramètres!H25="","",Paramètres!H25) | D24: =IF(Paramètres!I25="","",Paramètres!I25) | E24: =IF(Paramètres!J25&Paramètres!L25&Paramètres!N25="",WORKDAY($A$6-1,1),MAX(IF(Paramètres!J25="",0,IF(Paramètres!K25="",NA(),IF(RIGHT(TRIM(Paramètres!K25),3)="Fin",WORKDAY(IF(LEFT(TRIM(Paramètres!K25),1)="F",INDEX($F$4:$F$56,MATCH(Paramètres!J25,Paramètres!$G$5:$G$57,0)),INDEX($E$4:$E$56,MATCH(Paramètres!J25,Paramètres!$G$5:$G$57,0))),1-$H24),IF(LEFT(TRIM(Paramètres!K25),1)="F",WORKDAY(IF(LEFT(TRIM(Paramètres!K25),1)="F",INDEX($F$4:$F$56,MATCH(Paramètres!J25,Paramètres!$G$5:$G$57,0)),INDEX($E$4:$E$56,MATCH(Paramètres!J25,Paramètres!$G$5:$G$57,0))),1),IF(LEFT(TRIM(Paramètres!K25),1)="F",INDEX($F$4:$F$56,MATCH(Paramètres!J25,Paramètres!$G$5:$G$57,0)),INDEX($E$4:$E$56,MATCH(Paramètres!J25,Paramètres!$G$5:$G$57,0))))))),IF(Paramètres!L25="",0,IF(Paramètres!M25="",NA(),IF(RIGHT(TRIM(Paramètres!M25),3)="Fin",WORKDAY(IF(LEFT(TRIM(Paramètres!M25),1)="F",INDEX($F$4:$F$56,MATCH(Paramètres!L25,Paramètres!$G$5:$G$57,0)),INDEX($E$4:$E$56,MATCH(Paramètres!L25,Paramètres!$G$5:$G$57,0))),1-$H24),IF(LEFT(TRIM(Paramètres!M25),1)="F",WORKDAY(IF(LEFT(TRIM(Paramètres!M25),1)="F",INDEX($F$4:$F$56,MATCH(Paramètres!L25,Paramètres!$G$5:$G$57,0)),INDEX($E$4:$E$56,MATCH(Paramètres!L25,Paramètres!$G$5:$G$57,0))),1),IF(LEFT(TRIM(Paramètres!M25),1)="F",INDEX($F$4:$F$56,MATCH(Paramètres!L25,Paramètres!$G$5:$G$57,0)),INDEX($E$4:$E$56,MATCH(Paramètres!L25,Paramètres!$G$5:$G$57,0))))))),IF(Paramètres!N25="",0,IF(Paramètres!O25="",NA(),IF(RIGHT(TRIM(Paramètres!O25),3)="Fin",WORKDAY(IF(LEFT(TRIM(Paramètres!O25),1)="F",INDEX($F$4:$F$56,MATCH(Paramètres!N25,Paramètres!$G$5:$G$57,0)),INDEX($E$4:$E$56,MATCH(Paramètres!N25,Paramètres!$G$5:$G$57,0))),1-$H24),IF(LEFT(TRIM(Paramètres!O25),1)="F",WORKDAY(IF(LEFT(TRIM(Paramètres!O25),1)="F",INDEX($F$4:$F$56,MATCH(Paramètres!N25,Paramètres!$G$5:$G$57,0)),INDEX($E$4:$E$56,MATCH(Paramètres!N25,Paramètres!$G$5:$G$57,0))),1),IF(LEFT(TRIM(Paramètres!O25),1)="F",INDEX($F$4:$F$56,MATCH(Paramètres!N25,Paramètres!$G$5:$G$57,0)),INDEX($E$4:$E$56,MATCH(Paramètres!N25,Paramètres!$G$5:$G$57,0))))))))) | F24: =IF($H24=0,WORKDAY(E24,-1),WORKDAY(E24,$H24-1)) | H24: =Paramètres!B25
B25: =Paramètres!G26 | C25: =IF(Paramètres!H26="","",Paramètres!H26) | D25: =IF(Paramètres!I26="","",Paramètres!I26) | E25: =IF(Paramètres!J26&Paramètres!L26&Paramètres!N26="",WORKDAY($A$6-1,1),MAX(IF(Paramètres!J26="",0,IF(Paramètres!K26="",NA(),IF(RIGHT(TRIM(Paramètres!K26),3)="Fin",WORKDAY(IF(LEFT(TRIM(Paramètres!K26),1)="F",INDEX($F$4:$F$56,MATCH(Paramètres!J26,Paramètres!$G$5:$G$57,0)),INDEX($E$4:$E$56,MATCH(Paramètres!J26,Paramètres!$G$5:$G$57,0))),1-$H25),IF(LEFT(TRIM(Paramètres!K26),1)="F",WORKDAY(IF(LEFT(TRIM(Paramètres!K26),1)="F",INDEX($F$4:$F$56,MATCH(Paramètres!J26,Paramètres!$G$5:$G$57,0)),INDEX($E$4:$E$56,MATCH(Paramètres!J26,Paramètres!$G$5:$G$57,0))),1),IF(LEFT(TRIM(Paramètres!K26),1)="F",INDEX($F$4:$F$56,MATCH(Paramètres!J26,Paramètres!$G$5:$G$57,0)),INDEX($E$4:$E$56,MATCH(Paramètres!J26,Paramètres!$G$5:$G$57,0))))))),IF(Paramètres!L26="",0,IF(Paramètres!M26="",NA(),IF(RIGHT(TRIM(Paramètres!M26),3)="Fin",WORKDAY(IF(LEFT(TRIM(Paramètres!M26),1)="F",INDEX($F$4:$F$56,MATCH(Paramètres!L26,Paramètres!$G$5:$G$57,0)),INDEX($E$4:$E$56,MATCH(Paramètres!L26,Paramètres!$G$5:$G$57,0))),1-$H25),IF(LEFT(TRIM(Paramètres!M26),1)="F",WORKDAY(IF(LEFT(TRIM(Paramètres!M26),1)="F",INDEX($F$4:$F$56,MATCH(Paramètres!L26,Paramètres!$G$5:$G$57,0)),INDEX($E$4:$E$56,MATCH(Paramètres!L26,Paramètres!$G$5:$G$57,0))),1),IF(LEFT(TRIM(Paramètres!M26),1)="F",INDEX($F$4:$F$56,MATCH(Paramètres!L26,Paramètres!$G$5:$G$57,0)),INDEX($E$4:$E$56,MATCH(Paramètres!L26,Paramètres!$G$5:$G$57,0))))))),IF(Paramètres!N26="",0,IF(Paramètres!O26="",NA(),IF(RIGHT(TRIM(Paramètres!O26),3)="Fin",WORKDAY(IF(LEFT(TRIM(Paramètres!O26),1)="F",INDEX($F$4:$F$56,MATCH(Paramètres!N26,Paramètres!$G$5:$G$57,0)),INDEX($E$4:$E$56,MATCH(Paramètres!N26,Paramètres!$G$5:$G$57,0))),1-$H25),IF(LEFT(TRIM(Paramètres!O26),1)="F",WORKDAY(IF(LEFT(TRIM(Paramètres!O26),1)="F",INDEX($F$4:$F$56,MATCH(Paramètres!N26,Paramètres!$G$5:$G$57,0)),INDEX($E$4:$E$56,MATCH(Paramètres!N26,Paramètres!$G$5:$G$57,0))),1),IF(LEFT(TRIM(Paramètres!O26),1)="F",INDEX($F$4:$F$56,MATCH(Paramètres!N26,Paramètres!$G$5:$G$57,0)),INDEX($E$4:$E$56,MATCH(Paramètres!N26,Paramètres!$G$5:$G$57,0))))))))) | F25: =IF($H25=0,WORKDAY(E25,-1),WORKDAY(E25,$H25-1)) | H25: =Paramètres!B26
B26: =Paramètres!G27 | C26: =IF(Paramètres!H27="","",Paramètres!H27) | D26: =IF(Paramètres!I27="","",Paramètres!I27) | E26: =IF(Paramètres!J27&Paramètres!L27&Paramètres!N27="",WORKDAY($A$6-1,1),MAX(IF(Paramètres!J27="",0,IF(Paramètres!K27="",NA(),IF(RIGHT(TRIM(Paramètres!K27),3)="Fin",WORKDAY(IF(LEFT(TRIM(Paramètres!K27),1)="F",INDEX($F$4:$F$56,MATCH(Paramètres!J27,Paramètres!$G$5:$G$57,0)),INDEX($E$4:$E$56,MATCH(Paramètres!J27,Paramètres!$G$5:$G$57,0))),1-$H26),IF(LEFT(TRIM(Paramètres!K27),1)="F",WORKDAY(IF(LEFT(TRIM(Paramètres!K27),1)="F",INDEX($F$4:$F$56,MATCH(Paramètres!J27,Paramètres!$G$5:$G$57,0)),INDEX($E$4:$E$56,MATCH(Paramètres!J27,Paramètres!$G$5:$G$57,0))),1),IF(LEFT(TRIM(Paramètres!K27),1)="F",INDEX($F$4:$F$56,MATCH(Paramètres!J27,Paramètres!$G$5:$G$57,0)),INDEX($E$4:$E$56,MATCH(Paramètres!J27,Paramètres!$G$5:$G$57,0))))))),IF(Paramètres!L27="",0,IF(Paramètres!M27="",NA(),IF(RIGHT(TRIM(Paramètres!M27),3)="Fin",WORKDAY(IF(LEFT(TRIM(Paramètres!M27),1)="F",INDEX($F$4:$F$56,MATCH(Paramètres!L27,Paramètres!$G$5:$G$57,0)),INDEX($E$4:$E$56,MATCH(Paramètres!L27,Paramètres!$G$5:$G$57,0))),1-$H26),IF(LEFT(TRIM(Paramètres!M27),1)="F",WORKDAY(IF(LEFT(TRIM(Paramètres!M27),1)="F",INDEX($F$4:$F$56,MATCH(Paramètres!L27,Paramètres!$G$5:$G$57,0)),INDEX($E$4:$E$56,MATCH(Paramètres!L27,Paramètres!$G$5:$G$57,0))),1),IF(LEFT(TRIM(Paramètres!M27),1)="F",INDEX($F$4:$F$56,MATCH(Paramètres!L27,Paramètres!$G$5:$G$57,0)),INDEX($E$4:$E$56,MATCH(Paramètres!L27,Paramètres!$G$5:$G$57,0))))))),IF(Paramètres!N27="",0,IF(Paramètres!O27="",NA(),IF(RIGHT(TRIM(Paramètres!O27),3)="Fin",WORKDAY(IF(LEFT(TRIM(Paramètres!O27),1)="F",INDEX($F$4:$F$56,MATCH(Paramètres!N27,Paramètres!$G$5:$G$57,0)),INDEX($E$4:$E$56,MATCH(Paramètres!N27,Paramètres!$G$5:$G$57,0))),1-$H26),IF(LEFT(TRIM(Paramètres!O27),1)="F",WORKDAY(IF(LEFT(TRIM(Paramètres!O27),1)="F",INDEX($F$4:$F$56,MATCH(Paramètres!N27,Paramètres!$G$5:$G$57,0)),INDEX($E$4:$E$56,MATCH(Paramètres!N27,Paramètres!$G$5:$G$57,0))),1),IF(LEFT(TRIM(Paramètres!O27),1)="F",INDEX($F$4:$F$56,MATCH(Paramètres!N27,Paramètres!$G$5:$G$57,0)),INDEX($E$4:$E$56,MATCH(Paramètres!N27,Paramètres!$G$5:$G$57,0))))))))) | F26: =IF($H26=0,WORKDAY(E26,-1),WORKDAY(E26,$H26-1)) | H26: =Paramètres!B27
... B30: =Paramètres!G31 | C30: =IF(Paramètres!H31="","",Paramètres!H31) | D30: =IF(Paramètres!I31="","",Paramètres!I31) | E30: =IF(Paramètres!J31&Paramètres!L31&Paramètres!N31="",WORKDAY($A$6-1,1),MAX(IF(Paramètres!J31="",0,IF(Paramètres!K31="",NA(),IF(RIGHT(TRIM(Paramètres!K31),3)="Fin",WORKDAY(IF(LEFT(TRIM(Paramètres!K31),1)="F",INDEX($F$4:$F$56,MATCH(Paramètres!J31,Paramètres!$G$5:$G$57,0)),INDEX($E$4:$E$56,MATCH(Paramètres!J31,Paramètres!$G$5:$G$57,0))),1-$H30),IF(LEFT(TRIM(Paramètres!K31),1)="F",WORKDAY(IF(LEFT(TRIM(Paramètres!K31),1)="F",INDEX($F$4:$F$56,MATCH(Paramètres!J31,Paramètres!$G$5:$G$57,0)),INDEX($E$4:$E$56,MATCH(Paramètres!J31,Paramètres!$G$5:$G$57,0))),1),IF(LEFT(TRIM(Paramètres!K31),1)="F",INDEX($F$4:$F$56,MATCH(Paramètres!J31,Paramètres!$G$5:$G$57,0)),INDEX($E$4:$E$56,MATCH(Paramètres!J31,Paramètres!$G$5:$G$57,0))))))),IF(Paramètres!L31="",0,IF(Paramètres!M31="",NA(),IF(RIGHT(TRIM(Paramètres!M31),3)="Fin",WORKDAY(IF(LEFT(TRIM(Paramètres!M31),1)="F",INDEX($F$4:$F$56,MATCH(Paramètres!L31,Paramètres!$G$5:$G$57,0)),INDEX($E$4:$E$56,MATCH(Paramètres!L31,Paramètres!$G$5:$G$57,0))),1-$H30),IF(LEFT(TRIM(Paramètres!M31),1)="F",WORKDAY(IF(LEFT(TRIM(Paramètres!M31),1)="F",INDEX($F$4:$F$56,MATCH(Paramètres!L31,Paramètres!$G$5:$G$57,0)),INDEX($E$4:$E$56,MATCH(Paramètres!L31,Paramètres!$G$5:$G$57,0))),1),IF(LEFT(TRIM(Paramètres!M31),1)="F",INDEX($F$4:$F$56,MATCH(Paramètres!L31,Paramètres!$G$5:$G$57,0)),INDEX($E$4:$E$56,MATCH(Paramètres!L31,Paramètres!$G$5:$G$57,0))))))),IF(Paramètres!N31="",0,IF(Paramètres!O31="",NA(),IF(RIGHT(TRIM(Paramètres!O31),3)="Fin",WORKDAY(IF(LEFT(TRIM(Paramètres!O31),1)="F",INDEX($F$4:$F$56,MATCH(Paramètres!N31,Paramètres!$G$5:$G$57,0)),INDEX($E$4:$E$56,MATCH(Paramètres!N31,Paramètres!$G$5:$G$57,0))),1-$H30),IF(LEFT(TRIM(Paramètres!O31),1)="F",WORKDAY(IF(LEFT(TRIM(Paramètres!O31),1)="F",INDEX($F$4:$F$56,MATCH(Paramètres!N31,Paramètres!$G$5:$G$57,0)),INDEX($E$4:$E$56,MATCH(Paramètres!N31,Paramètres!$G$5:$G$57,0))),1),IF(LEFT(TRIM(Paramètres!O31),1)="F",INDEX($F$4:$F$56,MATCH(Paramètres!N31,Paramètres!$G$5:$G$57,0)),INDEX($E$4:$E$56,MATCH(Paramètres!N31,Paramètres!$G$5:$G$57,0))))))))) | F30: =IF($H30=0,WORKDAY(E30,-1),WORKDAY(E30,$H30-1)) | H30: =Paramètres!B31
B31: =Paramètres!G32 | C31: =IF(Paramètres!H32="","",Paramètres!H32) | D31: =IF(Paramètres!I32="","",Paramètres!I32) | E31: =MIN(E32:E35) | F31: =MAX(F32:F35) | H31: =NETWORKDAYS(E31,F31)
B32: =Paramètres!G33 | C32: =IF(Paramètres!H33="","",Paramètres!H33) | D32: =IF(Paramètres!I33="","",Paramètres!I33) | E32: =IF(Paramètres!J33&Paramètres!L33&Paramètres!N33="",WORKDAY($A$6-1,1),MAX(IF(Paramètres!J33="",0,IF(Paramètres!K33="",NA(),IF(RIGHT(TRIM(Paramètres!K33),3)="Fin",WORKDAY(IF(LEFT(TRIM(Paramètres!K33),1)="F",INDEX($F$4:$F$56,MATCH(Paramètres!J33,Paramètres!$G$5:$G$57,0)),INDEX($E$4:$E$56,MATCH(Paramètres!J33,Paramètres!$G$5:$G$57,0))),1-$H32),IF(LEFT(TRIM(Paramètres!K33),1)="F",WORKDAY(IF(LEFT(TRIM(Paramètres!K33),1)="F",INDEX($F$4:$F$56,MATCH(Paramètres!J33,Paramètres!$G$5:$G$57,0)),INDEX($E$4:$E$56,MATCH(Paramètres!J33,Paramètres!$G$5:$G$57,0))),1),IF(LEFT(TRIM(Paramètres!K33),1)="F",INDEX($F$4:$F$56,MATCH(Paramètres!J33,Paramètres!$G$5:$G$57,0)),INDEX($E$4:$E$56,MATCH(Paramètres!J33,Paramètres!$G$5:$G$57,0))))))),IF(Paramètres!L33="",0,IF(Paramètres!M33="",NA(),IF(RIGHT(TRIM(Paramètres!M33),3)="Fin",WORKDAY(IF(LEFT(TRIM(Paramètres!M33),1)="F",INDEX($F$4:$F$56,MATCH(Paramètres!L33,Paramètres!$G$5:$G$57,0)),INDEX($E$4:$E$56,MATCH(Paramètres!L33,Paramètres!$G$5:$G$57,0))),1-$H32),IF(LEFT(TRIM(Paramètres!M33),1)="F",WORKDAY(IF(LEFT(TRIM(Paramètres!M33),1)="F",INDEX($F$4:$F$56,MATCH(Paramètres!L33,Paramètres!$G$5:$G$57,0)),INDEX($E$4:$E$56,MATCH(Paramètres!L33,Paramètres!$G$5:$G$57,0))),1),IF(LEFT(TRIM(Paramètres!M33),1)="F",INDEX($F$4:$F$56,MATCH(Paramètres!L33,Paramètres!$G$5:$G$57,0)),INDEX($E$4:$E$56,MATCH(Paramètres!L33,Paramètres!$G$5:$G$57,0))))))),IF(Paramètres!N33="",0,IF(Paramètres!O33="",NA(),IF(RIGHT(TRIM(Paramètres!O33),3)="Fin",WORKDAY(IF(LEFT(TRIM(Paramètres!O33),1)="F",INDEX($F$4:$F$56,MATCH(Paramètres!N33,Paramètres!$G$5:$G$57,0)),INDEX($E$4:$E$56,MATCH(Paramètres!N33,Paramètres!$G$5:$G$57,0))),1-$H32),IF(LEFT(TRIM(Paramètres!O33),1)="F",WORKDAY(IF(LEFT(TRIM(Paramètres!O33),1)="F",INDEX($F$4:$F$56,MATCH(Paramètres!N33,Paramètres!$G$5:$G$57,0)),INDEX($E$4:$E$56,MATCH(Paramètres!N33,Paramètres!$G$5:$G$57,0))),1),IF(LEFT(TRIM(Paramètres!O33),1)="F",INDEX($F$4:$F$56,MATCH(Paramètres!N33,Paramètres!$G$5:$G$57,0)),INDEX($E$4:$E$56,MATCH(Paramètres!N33,Paramètres!$G$5:$G$57,0))))))))) | F32: =IF($H32=0,WORKDAY(E32,-1),WORKDAY(E32,$H32-1)) | H32: =Paramètres!B33
B33: =Paramètres!G34 | C33: =IF(Paramètres!H34="","",Paramètres!H34) | D33: =IF(Paramètres!I34="","",Paramètres!I34) | E33: =IF(Paramètres!J34&Paramètres!L34&Paramètres!N34="",WORKDAY($A$6-1,1),MAX(IF(Paramètres!J34="",0,IF(Paramètres!K34="",NA(),IF(RIGHT(TRIM(Paramètres!K34),3)="Fin",WORKDAY(IF(LEFT(TRIM(Paramètres!K34),1)="F",INDEX($F$4:$F$56,MATCH(Paramètres!J34,Paramètres!$G$5:$G$57,0)),INDEX($E$4:$E$56,MATCH(Paramètres!J34,Paramètres!$G$5:$G$57,0))),1-$H33),IF(LEFT(TRIM(Paramètres!K34),1)="F",WORKDAY(IF(LEFT(TRIM(Paramètres!K34),1)="F",INDEX($F$4:$F$56,MATCH(Paramètres!J34,Paramètres!$G$5:$G$57,0)),INDEX($E$4:$E$56,MATCH(Paramètres!J34,Paramètres!$G$5:$G$57,0))),1),IF(LEFT(TRIM(Paramètres!K34),1)="F",INDEX($F$4:$F$56,MATCH(Paramètres!J34,Paramètres!$G$5:$G$57,0)),INDEX($E$4:$E$56,MATCH(Paramètres!J34,Paramètres!$G$5:$G$57,0))))))),IF(Paramètres!L34="",0,IF(Paramètres!M34="",NA(),IF(RIGHT(TRIM(Paramètres!M34),3)="Fin",WORKDAY(IF(LEFT(TRIM(Paramètres!M34),1)="F",INDEX($F$4:$F$56,MATCH(Paramètres!L34,Paramètres!$G$5:$G$57,0)),INDEX($E$4:$E$56,MATCH(Paramètres!L34,Paramètres!$G$5:$G$57,0))),1-$H33),IF(LEFT(TRIM(Paramètres!M34),1)="F",WORKDAY(IF(LEFT(TRIM(Paramètres!M34),1)="F",INDEX($F$4:$F$56,MATCH(Paramètres!L34,Paramètres!$G$5:$G$57,0)),INDEX($E$4:$E$56,MATCH(Paramètres!L34,Paramètres!$G$5:$G$57,0))),1),IF(LEFT(TRIM(Paramètres!M34),1)="F",INDEX($F$4:$F$56,MATCH(Paramètres!L34,Paramètres!$G$5:$G$57,0)),INDEX($E$4:$E$56,MATCH(Paramètres!L34,Paramètres!$G$5:$G$57,0))))))),IF(Paramètres!N34="",0,IF(Paramètres!O34="",NA(),IF(RIGHT(TRIM(Paramètres!O34),3)="Fin",WORKDAY(IF(LEFT(TRIM(Paramètres!O34),1)="F",INDEX($F$4:$F$56,MATCH(Paramètres!N34,Paramètres!$G$5:$G$57,0)),INDEX($E$4:$E$56,MATCH(Paramètres!N34,Paramètres!$G$5:$G$57,0))),1-$H33),IF(LEFT(TRIM(Paramètres!O34),1)="F",WORKDAY(IF(LEFT(TRIM(Paramètres!O34),1)="F",INDEX($F$4:$F$56,MATCH(Paramètres!N34,Paramètres!$G$5:$G$57,0)),INDEX($E$4:$E$56,MATCH(Paramètres!N34,Paramètres!$G$5:$G$57,0))),1),IF(LEFT(TRIM(Paramètres!O34),1)="F",INDEX($F$4:$F$56,MATCH(Paramètres!N34,Paramètres!$G$5:$G$57,0)),INDEX($E$4:$E$56,MATCH(Paramètres!N34,Paramètres!$G$5:$G$57,0))))))))) | F33: =IF($H33=0,WORKDAY(E33,-1),WORKDAY(E33,$H33-1)) | H33: =Paramètres!B34
B34: =Paramètres!G35 | C34: =IF(Paramètres!H35="","",Paramètres!H35) | D34: =IF(Paramètres!I35="","",Paramètres!I35) | E34: =IF(Paramètres!J35&Paramètres!L35&Paramètres!N35="",WORKDAY($A$6-1,1),MAX(IF(Paramètres!J35="",0,IF(Paramètres!K35="",NA(),IF(RIGHT(TRIM(Paramètres!K35),3)="Fin",WORKDAY(IF(LEFT(TRIM(Paramètres!K35),1)="F",INDEX($F$4:$F$56,MATCH(Paramètres!J35,Paramètres!$G$5:$G$57,0)),INDEX($E$4:$E$56,MATCH(Paramètres!J35,Paramètres!$G$5:$G$57,0))),1-$H34),IF(LEFT(TRIM(Paramètres!K35),1)="F",WORKDAY(IF(LEFT(TRIM(Paramètres!K35),1)="F",INDEX($F$4:$F$56,MATCH(Paramètres!J35,Paramètres!$G$5:$G$57,0)),INDEX($E$4:$E$56,MATCH(Paramètres!J35,Paramètres!$G$5:$G$57,0))),1),IF(LEFT(TRIM(Paramètres!K35),1)="F",INDEX($F$4:$F$56,MATCH(Paramètres!J35,Paramètres!$G$5:$G$57,0)),INDEX($E$4:$E$56,MATCH(Paramètres!J35,Paramètres!$G$5:$G$57,0))))))),IF(Paramètres!L35="",0,IF(Paramètres!M35="",NA(),IF(RIGHT(TRIM(Paramètres!M35),3)="Fin",WORKDAY(IF(LEFT(TRIM(Paramètres!M35),1)="F",INDEX($F$4:$F$56,MATCH(Paramètres!L35,Paramètres!$G$5:$G$57,0)),INDEX($E$4:$E$56,MATCH(Paramètres!L35,Paramètres!$G$5:$G$57,0))),1-$H34),IF(LEFT(TRIM(Paramètres!M35),1)="F",WORKDAY(IF(LEFT(TRIM(Paramètres!M35),1)="F",INDEX($F$4:$F$56,MATCH(Paramètres!L35,Paramètres!$G$5:$G$57,0)),INDEX($E$4:$E$56,MATCH(Paramètres!L35,Paramètres!$G$5:$G$57,0))),1),IF(LEFT(TRIM(Paramètres!M35),1)="F",INDEX($F$4:$F$56,MATCH(Paramètres!L35,Paramètres!$G$5:$G$57,0)),INDEX($E$4:$E$56,MATCH(Paramètres!L35,Paramètres!$G$5:$G$57,0))))))),IF(Paramètres!N35="",0,IF(Paramètres!O35="",NA(),IF(RIGHT(TRIM(Paramètres!O35),3)="Fin",WORKDAY(IF(LEFT(TRIM(Paramètres!O35),1)="F",INDEX($F$4:$F$56,MATCH(Paramètres!N35,Paramètres!$G$5:$G$57,0)),INDEX($E$4:$E$56,MATCH(Paramètres!N35,Paramètres!$G$5:$G$57,0))),1-$H34),IF(LEFT(TRIM(Paramètres!O35),1)="F",WORKDAY(IF(LEFT(TRIM(Paramètres!O35),1)="F",INDEX($F$4:$F$56,MATCH(Paramètres!N35,Paramètres!$G$5:$G$57,0)),INDEX($E$4:$E$56,MATCH(Paramètres!N35,Paramètres!$G$5:$G$57,0))),1),IF(LEFT(TRIM(Paramètres!O35),1)="F",INDEX($F$4:$F$56,MATCH(Paramètres!N35,Paramètres!$G$5:$G$57,0)),INDEX($E$4:$E$56,MATCH(Paramètres!N35,Paramètres!$G$5:$G$57,0))))))))) | F34: =IF($H34=0,WORKDAY(E34,-1),WORKDAY(E34,$H34-1)) | H34: =Paramètres!B35
B35: =Paramètres!G36 | C35: =IF(Paramètres!H36="","",Paramètres!H36) | D35: =IF(Paramètres!I36="","",Paramètres!I36) | E35: =IF(Paramètres!J36&Paramètres!L36&Paramètres!N36="",WORKDAY($A$6-1,1),MAX(IF(Paramètres!J36="",0,IF(Paramètres!K36="",NA(),IF(RIGHT(TRIM(Paramètres!K36),3)="Fin",WORKDAY(IF(LEFT(TRIM(Paramètres!K36),1)="F",INDEX($F$4:$F$56,MATCH(Paramètres!J36,Paramètres!$G$5:$G$57,0)),INDEX($E$4:$E$56,MATCH(Paramètres!J36,Paramètres!$G$5:$G$57,0))),1-$H35),IF(LEFT(TRIM(Paramètres!K36),1)="F",WORKDAY(IF(LEFT(TRIM(Paramètres!K36),1)="F",INDEX($F$4:$F$56,MATCH(Paramètres!J36,Paramètres!$G$5:$G$57,0)),INDEX($E$4:$E$56,MATCH(Paramètres!J36,Paramètres!$G$5:$G$57,0))),1),IF(LEFT(TRIM(Paramètres!K36),1)="F",INDEX($F$4:$F$56,MATCH(Paramètres!J36,Paramètres!$G$5:$G$57,0)),INDEX($E$4:$E$56,MATCH(Paramètres!J36,Paramètres!$G$5:$G$57,0))))))),IF(Paramètres!L36="",0,IF(Paramètres!M36="",NA(),IF(RIGHT(TRIM(Paramètres!M36),3)="Fin",WORKDAY(IF(LEFT(TRIM(Paramètres!M36),1)="F",INDEX($F$4:$F$56,MATCH(Paramètres!L36,Paramètres!$G$5:$G$57,0)),INDEX($E$4:$E$56,MATCH(Paramètres!L36,Paramètres!$G$5:$G$57,0))),1-$H35),IF(LEFT(TRIM(Paramètres!M36),1)="F",WORKDAY(IF(LEFT(TRIM(Paramètres!M36),1)="F",INDEX($F$4:$F$56,MATCH(Paramètres!L36,Paramètres!$G$5:$G$57,0)),INDEX($E$4:$E$56,MATCH(Paramètres!L36,Paramètres!$G$5:$G$57,0))),1),IF(LEFT(TRIM(Paramètres!M36),1)="F",INDEX($F$4:$F$56,MATCH(Paramètres!L36,Paramètres!$G$5:$G$57,0)),INDEX($E$4:$E$56,MATCH(Paramètres!L36,Paramètres!$G$5:$G$57,0))))))),IF(Paramètres!N36="",0,IF(Paramètres!O36="",NA(),IF(RIGHT(TRIM(Paramètres!O36),3)="Fin",WORKDAY(IF(LEFT(TRIM(Paramètres!O36),1)="F",INDEX($F$4:$F$56,MATCH(Paramètres!N36,Paramètres!$G$5:$G$57,0)),INDEX($E$4:$E$56,MATCH(Paramètres!N36,Paramètres!$G$5:$G$57,0))),1-$H35),IF(LEFT(TRIM(Paramètres!O36),1)="F",WORKDAY(IF(LEFT(TRIM(Paramètres!O36),1)="F",INDEX($F$4:$F$56,MATCH(Paramètres!N36,Paramètres!$G$5:$G$57,0)),INDEX($E$4:$E$56,MATCH(Paramètres!N36,Paramètres!$G$5:$G$57,0))),1),IF(LEFT(TRIM(Paramètres!O36),1)="F",INDEX($F$4:$F$56,MATCH(Paramètres!N36,Paramètres!$G$5:$G$57,0)),INDEX($E$4:$E$56,MATCH(Paramètres!N36,Paramètres!$G$5:$G$57,0))))))))) | F35: =IF($H35=0,WORKDAY(E35,-1),WORKDAY(E35,$H35-1)) | H35: =Paramètres!B36
B36: =Paramètres!G37 | C36: =IF(Paramètres!H37="","",Paramètres!H37) | D36: =IF(Paramètres!I37="","",Paramètres!I37) | E36: =MIN(E37:E54) | F36: =MAX(F37:F54) | H36: =NETWORKDAYS(E36,F36)
