Workbook

Sheet Dossiers
A1: DOSSIERS | C1: NE PAS SUPPRIMER DE LIGNE ENTIERE | E1: NE PAS TOUCHER AUX ZONES GRISEES
A2: Une ligne par dossier : référence, nom, date de début, date CS et date Jury. Son bloc apparaît alors automatiquement dans Suivi et dans le tableau de bord.
A3: N° | B3: Référence | C3: Nom / intitulé | D3: Date de début | E3: Libellé (calcul) | F3: Date CS | G3: Date Jury
A4: 1 | B4: TEST GFF | C4: ABCDEFGH | D4: 46307 | E4: =IF(ISNUMBER(D4),A4&" · "&B4&IF(C4<>""," · "&C4,""),IF(B4&C4<>"","(date de début à renseigner)","")) | F4: 46304 | G4: 46307
A5: 2 | B5: TEST GFF | C5: ABCDEFG | D5: 46307 | E5: =IF(ISNUMBER(D5),A5&" · "&B5&IF(C5<>""," · "&C5,""),IF(B5&C5<>"","(date de début à renseigner)","")) | F5: 46335 | G5: 46343
A6: 3 | B6: TEST GFF | C6: ABCDEF | D6: 46307 | E6: =IF(ISNUMBER(D6),A6&" · "&B6&IF(C6<>""," · "&C6,""),IF(B6&C6<>"","(date de début à renseigner)","")) | F6: 46336 | G6: 46344
A7: 4 | E7: =IF(ISNUMBER(D7),A7&" · "&B7&IF(C7<>""," · "&C7,""),IF(B7&C7<>"","(date de début à renseigner)",""))
A8: 5 | E8: =IF(ISNUMBER(D8),A8&" · "&B8&IF(C8<>""," · "&C8,""),IF(B8&C8<>"","(date de début à renseigner)",""))
A9: 6 | E9: =IF(ISNUMBER(D9),A9&" · "&B9&IF(C9<>""," · "&C9,""),IF(B9&C9<>"","(date de début à renseigner)",""))
A10: 7 | E10: =IF(ISNUMBER(D10),A10&" · "&B10&IF(C10<>""," · "&C10,""),IF(B10&C10<>"","(date de début à renseigner)",""))
A11: 8 | E11: =IF(ISNUMBER(D11),A11&" · "&B11&IF(C11<>""," · "&C11,""),IF(B11&C11<>"","(date de début à renseigner)",""))
A12: 9 | E12: =IF(ISNUMBER(D12),A12&" · "&B12&IF(C12<>""," · "&C12,""),IF(B12&C12<>"","(date de début à renseigner)",""))
A13: 10 | E13: =IF(ISNUMBER(D13),A13&" · "&B13&IF(C13<>""," · "&C13,""),IF(B13&C13<>"","(date de début à renseigner)",""))
A14: 11 | E14: =IF(ISNUMBER(D14),A14&" · "&B14&IF(C14<>""," · "&C14,""),IF(B14&C14<>"","(date de début à renseigner)",""))
A15: 12 | E15: =IF(ISNUMBER(D15),A15&" · "&B15&IF(C15<>""," · "&C15,""),IF(B15&C15<>"","(date de début à renseigner)",""))
A16: 13 | E16: =IF(ISNUMBER(D16),A16&" · "&B16&IF(C16<>""," · "&C16,""),IF(B16&C16<>"","(date de début à renseigner)",""))
A17: 14 | E17: =IF(ISNUMBER(D17),A17&" · "&B17&IF(C17<>""," · "&C17,""),IF(B17&C17<>"","(date de début à renseigner)",""))
A18: 15 | E18: =IF(ISNUMBER(D18),A18&" · "&B18&IF(C18<>""," · "&C18,""),IF(B18&C18<>"","(date de début à renseigner)",""))
... A63: 60 | E63: =IF(ISNUMBER(D63),A63&" · "&B63&IF(C63<>""," · "&C63,""),IF(B63&C63<>"","(date de début à renseigner)",""))

Sheet Gantt
A1: Dossier affiché : | C1: 1 | D1: =IFERROR(INDEX(Dossiers!$E$4:$E$63,$C$1),"—")
A2: N° de dossier (1 à 60) — liste déroulante en C1 | B2: Origine calendrier (auto) : | C2: =IFERROR(MIN(INDEX(Dossiers!$D$4:$D$63,$C$1),INDEX(Dossiers!$F$4:$F$63,$C$1),INDEX(Dossiers!$G$4:$G$63,$C$1))-3,INDEX(Dossiers!$D$4:$D$63,$C$1))
G3: =IF(DAY(G$4)=1,TEXT(G$4,"mmm aa"),"") | H3: =IF(DAY(H$4)=1,TEXT(H$4,"mmm aa"),"") | I3: =IF(DAY(I$4)=1,TEXT(I$4,"mmm aa"),"") | J3: =IF(DAY(J$4)=1,TEXT(J$4,"mmm aa"),"") | K3: =IF(DAY(K$4)=1,TEXT(K$4,"mmm aa"),"") | L3: =IF(DAY(L$4)=1,TEXT(L$4,"mmm aa"),"") | M3: =IF(DAY(M$4)=1,TEXT(M$4,"mmm aa"),"") | N3: =IF(DAY(N$4)=1,TEXT(N$4,"mmm aa"),"") | ... EP3: =IF(DAY(EP$4)=1,TEXT(EP$4,"mmm aa"),"")
A4: ID | C4: Étape | E4: Début | F4: Fin | G4: =$C$2 | H4: =G4+1 | I4: =H4+1 | J4: =I4+1 | K4: =J4+1 | L4: =K4+1 | M4: =L4+1 | N4: =M4+1 | O4: =N4+1 | ... EP4: =EO4+1
A5: =IFERROR(INDEX(Suivi!$B:$B,5+($C$1-1)*54),"") | C5: =IFERROR(IF(INDEX(Suivi!$D:$D,5+($C$1-1)*54)="",INDEX(Suivi!$C:$C,5+($C$1-1)*54),INDEX(Suivi!$D:$D,5+($C$1-1)*54)),"") | E5: =IFERROR(INDEX(Suivi!$E:$E,5+($C$1-1)*54),"") | F5: =IFERROR(INDEX(Suivi!$F:$F,5+($C$1-1)*54),"") | O5: =IFERROR(IF(ISNUMBER($A5),1,VALUE(LEFT(SUBSTITUTE(TEXT($A5,"@"),",","."),FIND(".",SUBSTITUTE(TEXT($A5,"@"),",",".")&".0")-1))),"") | P5: =IFERROR(INDEX(Suivi!$G:$G,5+($C$1-1)*54),"")
A6: =IFERROR(INDEX(Suivi!$B:$B,6+($C$1-1)*54),"") | C6: =IFERROR(IF(INDEX(Suivi!$D:$D,6+($C$1-1)*54)="",INDEX(Suivi!$C:$C,6+($C$1-1)*54),INDEX(Suivi!$D:$D,6+($C$1-1)*54)),"") | E6: =IFERROR(INDEX(Suivi!$E:$E,6+($C$1-1)*54),"") | F6: =IFERROR(INDEX(Suivi!$F:$F,6+($C$1-1)*54),"") | O6: =IFERROR(IF(ISNUMBER($A6),1,VALUE(LEFT(SUBSTITUTE(TEXT($A6,"@"),",","."),FIND(".",SUBSTITUTE(TEXT($A6,"@"),",",".")&".0")-1))),"") | P6: =IFERROR(INDEX(Suivi!$G:$G,6+($C$1-1)*54),"")
A7: =IFERROR(INDEX(Suivi!$B:$B,7+($C$1-1)*54),"") | C7: =IFERROR(IF(INDEX(Suivi!$D:$D,7+($C$1-1)*54)="",INDEX(Suivi!$C:$C,7+($C$1-1)*54),INDEX(Suivi!$D:$D,7+($C$1-1)*54)),"") | E7: =IFERROR(INDEX(Suivi!$E:$E,7+($C$1-1)*54),"") | F7: =IFERROR(INDEX(Suivi!$F:$F,7+($C$1-1)*54),"") | O7: =IFERROR(IF(ISNUMBER($A7),1,VALUE(LEFT(SUBSTITUTE(TEXT($A7,"@"),",","."),FIND(".",SUBSTITUTE(TEXT($A7,"@"),",",".")&".0")-1))),"") | P7: =IFERROR(INDEX(Suivi!$G:$G,7+($C$1-1)*54),"")
A8: =IFERROR(INDEX(Suivi!$B:$B,8+($C$1-1)*54),"") | C8: =IFERROR(IF(INDEX(Suivi!$D:$D,8+($C$1-1)*54)="",INDEX(Suivi!$C:$C,8+($C$1-1)*54),INDEX(Suivi!$D:$D,8+($C$1-1)*54)),"") | E8: =IFERROR(INDEX(Suivi!$E:$E,8+($C$1-1)*54),"") | F8: =IFERROR(INDEX(Suivi!$F:$F,8+($C$1-1)*54),"") | O8: =IFERROR(IF(ISNUMBER($A8),1,VALUE(LEFT(SUBSTITUTE(TEXT($A8,"@"),",","."),FIND(".",SUBSTITUTE(TEXT($A8,"@"),",",".")&".0")-1))),"") | P8: =IFERROR(INDEX(Suivi!$G:$G,8+($C$1-1)*54),"")
A9: =IFERROR(INDEX(Suivi!$B:$B,9+($C$1-1)*54),"") | C9: =IFERROR(IF(INDEX(Suivi!$D:$D,9+($C$1-1)*54)="",INDEX(Suivi!$C:$C,9+($C$1-1)*54),INDEX(Suivi!$D:$D,9+($C$1-1)*54)),"") | E9: =IFERROR(INDEX(Suivi!$E:$E,9+($C$1-1)*54),"") | F9: =IFERROR(INDEX(Suivi!$F:$F,9+($C$1-1)*54),"") | O9: =IFERROR(IF(ISNUMBER($A9),1,VALUE(LEFT(SUBSTITUTE(TEXT($A9,"@"),",","."),FIND(".",SUBSTITUTE(TEXT($A9,"@"),",",".")&".0")-1))),"") | P9: =IFERROR(INDEX(Suivi!$G:$G,9+($C$1-1)*54),"")
A10: =IFERROR(INDEX(Suivi!$B:$B,10+($C$1-1)*54),"") | C10: =IFERROR(IF(INDEX(Suivi!$D:$D,10+($C$1-1)*54)="",INDEX(Suivi!$C:$C,10+($C$1-1)*54),INDEX(Suivi!$D:$D,10+($C$1-1)*54)),"") | E10: =IFERROR(INDEX(Suivi!$E:$E,10+($C$1-1)*54),"") | F10: =IFERROR(INDEX(Suivi!$F:$F,10+($C$1-1)*54),"") | O10: =IFERROR(IF(ISNUMBER($A10),1,VALUE(LEFT(SUBSTITUTE(TEXT($A10,"@"),",","."),FIND(".",SUBSTITUTE(TEXT($A10,"@"),",",".")&".0")-1))),"") | P10: =IFERROR(INDEX(Suivi!$G:$G,10+($C$1-1)*54),"")
A11: =IFERROR(INDEX(Suivi!$B:$B,11+($C$1-1)*54),"") | C11: =IFERROR(IF(INDEX(Suivi!$D:$D,11+($C$1-1)*54)="",INDEX(Suivi!$C:$C,11+($C$1-1)*54),INDEX(Suivi!$D:$D,11+($C$1-1)*54)),"") | E11: =IFERROR(INDEX(Suivi!$E:$E,11+($C$1-1)*54),"") | F11: =IFERROR(INDEX(Suivi!$F:$F,11+($C$1-1)*54),"") | O11: =IFERROR(IF(ISNUMBER($A11),1,VALUE(LEFT(SUBSTITUTE(TEXT($A11,"@"),",","."),FIND(".",SUBSTITUTE(TEXT($A11,"@"),",",".")&".0")-1))),"") | P11: =IFERROR(INDEX(Suivi!$G:$G,11+($C$1-1)*54),"")
A12: =IFERROR(INDEX(Suivi!$B:$B,12+($C$1-1)*54),"") | C12: =IFERROR(IF(INDEX(Suivi!$D:$D,12+($C$1-1)*54)="",INDEX(Suivi!$C:$C,12+($C$1-1)*54),INDEX(Suivi!$D:$D,12+($C$1-1)*54)),"") | E12: =IFERROR(INDEX(Suivi!$E:$E,12+($C$1-1)*54),"") | F12: =IFERROR(INDEX(Suivi!$F:$F,12+($C$1-1)*54),"") | O12: =IFERROR(IF(ISNUMBER($A12),1,VALUE(LEFT(SUBSTITUTE(TEXT($A12,"@"),",","."),FIND(".",SUBSTITUTE(TEXT($A12,"@"),",",".")&".0")-1))),"") | P12: =IFERROR(INDEX(Suivi!$G:$G,12+($C$1-1)*54),"")
A13: =IFERROR(INDEX(Suivi!$B:$B,13+($C$1-1)*54),"") | C13: =IFERROR(IF(INDEX(Suivi!$D:$D,13+($C$1-1)*54)="",INDEX(Suivi!$C:$C,13+($C$1-1)*54),INDEX(Suivi!$D:$D,13+($C$1-1)*54)),"") | E13: =IFERROR(INDEX(Suivi!$E:$E,13+($C$1-1)*54),"") | F13: =IFERROR(INDEX(Suivi!$F:$F,13+($C$1-1)*54),"") | O13: =IFERROR(IF(ISNUMBER($A13),1,VALUE(LEFT(SUBSTITUTE(TEXT($A13,"@"),",","."),FIND(".",SUBSTITUTE(TEXT($A13,"@"),",",".")&".0")-1))),"") | P13: =IFERROR(INDEX(Suivi!$G:$G,13+($C$1-1)*54),"")
A14: =IFERROR(INDEX(Suivi!$B:$B,14+($C$1-1)*54),"") | C14: =IFERROR(IF(INDEX(Suivi!$D:$D,14+($C$1-1)*54)="",INDEX(Suivi!$C:$C,14+($C$1-1)*54),INDEX(Suivi!$D:$D,14+($C$1-1)*54)),"") | E14: =IFERROR(INDEX(Suivi!$E:$E,14+($C$1-1)*54),"") | F14: =IFERROR(INDEX(Suivi!$F:$F,14+($C$1-1)*54),"") | O14: =IFERROR(IF(ISNUMBER($A14),1,VALUE(LEFT(SUBSTITUTE(TEXT($A14,"@"),",","."),FIND(".",SUBSTITUTE(TEXT($A14,"@"),",",".")&".0")-1))),"") | P14: =IFERROR(INDEX(Suivi!$G:$G,14+($C$1-1)*54),"")
A15: =IFERROR(INDEX(Suivi!$B:$B,15+($C$1-1)*54),"") | C15: =IFERROR(IF(INDEX(Suivi!$D:$D,15+($C$1-1)*54)="",INDEX(Suivi!$C:$C,15+($C$1-1)*54),INDEX(Suivi!$D:$D,15+($C$1-1)*54)),"") | E15: =IFERROR(INDEX(Suivi!$E:$E,15+($C$1-1)*54),"") | F15: =IFERROR(INDEX(Suivi!$F:$F,15+($C$1-1)*54),"") | O15: =IFERROR(IF(ISNUMBER($A15),1,VALUE(LEFT(SUBSTITUTE(TEXT($A15,"@"),",","."),FIND(".",SUBSTITUTE(TEXT($A15,"@"),",",".")&".0")-1))),"") | P15: =IFERROR(INDEX(Suivi!$G:$G,15+($C$1-1)*54),"")
A16: =IFERROR(INDEX(Suivi!$B:$B,16+($C$1-1)*54),"") | C16: =IFERROR(IF(INDEX(Suivi!$D:$D,16+($C$1-1)*54)="",INDEX(Suivi!$C:$C,16+($C$1-1)*54),INDEX(Suivi!$D:$D,16+($C$1-1)*54)),"") | E16: =IFERROR(INDEX(Suivi!$E:$E,16+($C$1-1)*54),"") | F16: =IFERROR(INDEX(Suivi!$F:$F,16+($C$1-1)*54),"") | O16: =IFERROR(IF(ISNUMBER($A16),1,VALUE(LEFT(SUBSTITUTE(TEXT($A16,"@"),",","."),FIND(".",SUBSTITUTE(TEXT($A16,"@"),",",".")&".0")-1))),"") | P16: =IFERROR(INDEX(Suivi!$G:$G,16+($C$1-1)*54),"")
A17: =IFERROR(INDEX(Suivi!$B:$B,17+($C$1-1)*54),"") | C17: =IFERROR(IF(INDEX(Suivi!$D:$D,17+($C$1-1)*54)="",INDEX(Suivi!$C:$C,17+($C$1-1)*54),INDEX(Suivi!$D:$D,17+($C$1-1)*54)),"") | E17: =IFERROR(INDEX(Suivi!$E:$E,17+($C$1-1)*54),"") | F17: =IFERROR(INDEX(Suivi!$F:$F,17+($C$1-1)*54),"") | O17: =IFERROR(IF(ISNUMBER($A17),1,VALUE(LEFT(SUBSTITUTE(TEXT($A17,"@"),",","."),FIND(".",SUBSTITUTE(TEXT($A17,"@"),",",".")&".0")-1))),"") | P17: =IFERROR(INDEX(Suivi!$G:$G,17+($C$1-1)*54),"")
A18: =IFERROR(INDEX(Suivi!$B:$B,18+($C$1-1)*54),"") | C18: =IFERROR(IF(INDEX(Suivi!$D:$D,18+($C$1-1)*54)="",INDEX(Suivi!$C:$C,18+($C$1-1)*54),INDEX(Suivi!$D:$D,18+($C$1-1)*54)),"") | E18: =IFERROR(INDEX(Suivi!$E:$E,18+($C$1-1)*54),"") | F18: =IFERROR(INDEX(Suivi!$F:$F,18+($C$1-1)*54),"") | O18: =IFERROR(IF(ISNUMBER($A18),1,VALUE(LEFT(SUBSTITUTE(TEXT($A18,"@"),",","."),FIND(".",SUBSTITUTE(TEXT($A18,"@"),",",".")&".0")-1))),"") | P18: =IFERROR(INDEX(Suivi!$G:$G,18+($C$1-1)*54),"")
A19: =IFERROR(INDEX(Suivi!$B:$B,19+($C$1-1)*54),"") | C19: =IFERROR(IF(INDEX(Suivi!$D:$D,19+($C$1-1)*54)="",INDEX(Suivi!$C:$C,19+($C$1-1)*54),INDEX(Suivi!$D:$D,19+($C$1-1)*54)),"") | E19: =IFERROR(INDEX(Suivi!$E:$E,19+($C$1-1)*54),"") | F19: =IFERROR(INDEX(Suivi!$F:$F,19+($C$1-1)*54),"") | O19: =IFERROR(IF(ISNUMBER($A19),1,VALUE(LEFT(SUBSTITUTE(TEXT($A19,"@"),",","."),FIND(".",SUBSTITUTE(TEXT($A19,"@"),",",".")&".0")-1))),"") | P19: =IFERROR(INDEX(Suivi!$G:$G,19+($C$1-1)*54),"")
A20: =IFERROR(INDEX(Suivi!$B:$B,20+($C$1-1)*54),"") | C20: =IFERROR(IF(INDEX(Suivi!$D:$D,20+($C$1-1)*54)="",INDEX(Suivi!$C:$C,20+($C$1-1)*54),INDEX(Suivi!$D:$D,20+($C$1-1)*54)),"") | E20: =IFERROR(INDEX(Suivi!$E:$E,20+($C$1-1)*54),"") | F20: =IFERROR(INDEX(Suivi!$F:$F,20+($C$1-1)*54),"") | O20: =IFERROR(IF(ISNUMBER($A20),1,VALUE(LEFT(SUBSTITUTE(TEXT($A20,"@"),",","."),FIND(".",SUBSTITUTE(TEXT($A20,"@"),",",".")&".0")-1))),"") | P20: =IFERROR(INDEX(Suivi!$G:$G,20+($C$1-1)*54),"")
A21: =IFERROR(INDEX(Suivi!$B:$B,21+($C$1-1)*54),"") | C21: =IFERROR(IF(INDEX(Suivi!$D:$D,21+($C$1-1)*54)="",INDEX(Suivi!$C:$C,21+($C$1-1)*54),INDEX(Suivi!$D:$D,21+($C$1-1)*54)),"") | E21: =IFERROR(INDEX(Suivi!$E:$E,21+($C$1-1)*54),"") | F21: =IFERROR(INDEX(Suivi!$F:$F,21+($C$1-1)*54),"") | O21: =IFERROR(IF(ISNUMBER($A21),1,VALUE(LEFT(SUBSTITUTE(TEXT($A21,"@"),",","."),FIND(".",SUBSTITUTE(TEXT($A21,"@"),",",".")&".0")-1))),"") | P21: =IFERROR(INDEX(Suivi!$G:$G,21+($C$1-1)*54),"")
A22: =IFERROR(INDEX(Suivi!$B:$B,22+($C$1-1)*54),"") | C22: =IFERROR(IF(INDEX(Suivi!$D:$D,22+($C$1-1)*54)="",INDEX(Suivi!$C:$C,22+($C$1-1)*54),INDEX(Suivi!$D:$D,22+($C$1-1)*54)),"") | E22: =IFERROR(INDEX(Suivi!$E:$E,22+($C$1-1)*54),"") | F22: =IFERROR(INDEX(Suivi!$F:$F,22+($C$1-1)*54),"") | O22: =IFERROR(IF(ISNUMBER($A22),1,VALUE(LEFT(SUBSTITUTE(TEXT($A22,"@"),",","."),FIND(".",SUBSTITUTE(TEXT($A22,"@"),",",".")&".0")-1))),"") | P22: =IFERROR(INDEX(Suivi!$G:$G,22+($C$1-1)*54),"")
A23: =IFERROR(INDEX(Suivi!$B:$B,23+($C$1-1)*54),"") | C23: =IFERROR(IF(INDEX(Suivi!$D:$D,23+($C$1-1)*54)="",INDEX(Suivi!$C:$C,23+($C$1-1)*54),INDEX(Suivi!$D:$D,23+($C$1-1)*54)),"") | E23: =IFERROR(INDEX(Suivi!$E:$E,23+($C$1-1)*54),"") | F23: =IFERROR(INDEX(Suivi!$F:$F,23+($C$1-1)*54),"") | O23: =IFERROR(IF(ISNUMBER($A23),1,VALUE(LEFT(SUBSTITUTE(TEXT($A23,"@"),",","."),FIND(".",SUBSTITUTE(TEXT($A23,"@"),",",".")&".0")-1))),"") | P23: =IFERROR(INDEX(Suivi!$G:$G,23+($C$1-1)*54),"")
A24: =IFERROR(INDEX(Suivi!$B:$B,24+($C$1-1)*54),"") | C24: =IFERROR(IF(INDEX(Suivi!$D:$D,24+($C$1-1)*54)="",INDEX(Suivi!$C:$C,24+($C$1-1)*54),INDEX(Suivi!$D:$D,24+($C$1-1)*54)),"") | E24: =IFERROR(INDEX(Suivi!$E:$E,24+($C$1-1)*54),"") | F24: =IFERROR(INDEX(Suivi!$F:$F,24+($C$1-1)*54),"") | O24: =IFERROR(IF(ISNUMBER($A24),1,VALUE(LEFT(SUBSTITUTE(TEXT($A24,"@"),",","."),FIND(".",SUBSTITUTE(TEXT($A24,"@"),",",".")&".0")-1))),"") | P24: =IFERROR(INDEX(Suivi!$G:$G,24+($C$1-1)*54),"")
A25: =IFERROR(INDEX(Suivi!$B:$B,25+($C$1-1)*54),"") | C25: =IFERROR(IF(INDEX(Suivi!$D:$D,25+($C$1-1)*54)="",INDEX(Suivi!$C:$C,25+($C$1-1)*54),INDEX(Suivi!$D:$D,25+($C$1-1)*54)),"") | E25: =IFERROR(INDEX(Suivi!$E:$E,25+($C$1-1)*54),"") | F25: =IFERROR(INDEX(Suivi!$F:$F,25+($C$1-1)*54),"") | O25: =IFERROR(IF(ISNUMBER($A25),1,VALUE(LEFT(SUBSTITUTE(TEXT($A25,"@"),",","."),FIND(".",SUBSTITUTE(TEXT($A25,"@"),",",".")&".0")-1))),"") | P25: =IFERROR(INDEX(Suivi!$G:$G,25+($C$1-1)*54),"")
A26: =IFERROR(INDEX(Suivi!$B:$B,26+($C$1-1)*54),"") | C26: =IFERROR(IF(INDEX(Suivi!$D:$D,26+($C$1-1)*54)="",INDEX(Suivi!$C:$C,26+($C$1-1)*54),INDEX(Suivi!$D:$D,26+($C$1-1)*54)),"") | E26: =IFERROR(INDEX(Suivi!$E:$E,26+($C$1-1)*54),"") | F26: =IFERROR(INDEX(Suivi!$F:$F,26+($C$1-1)*54),"") | O26: =IFERROR(IF(ISNUMBER($A26),1,VALUE(LEFT(SUBSTITUTE(TEXT($A26,"@"),",","."),FIND(".",SUBSTITUTE(TEXT($A26,"@"),",",".")&".0")-1))),"") | P26: =IFERROR(INDEX(Suivi!$G:$G,26+($C$1-1)*54),"")
A27: =IFERROR(INDEX(Suivi!$B:$B,27+($C$1-1)*54),"") | C27: =IFERROR(IF(INDEX(Suivi!$D:$D,27+($C$1-1)*54)="",INDEX(Suivi!$C:$C,27+($C$1-1)*54),INDEX(Suivi!$D:$D,27+($C$1-1)*54)),"") | E27: =IFERROR(INDEX(Suivi!$E:$E,27+($C$1-1)*54),"") | F27: =IFERROR(INDEX(Suivi!$F:$F,27+($C$1-1)*54),"") | O27: =IFERROR(IF(ISNUMBER($A27),1,VALUE(LEFT(SUBSTITUTE(TEXT($A27,"@"),",","."),FIND(".",SUBSTITUTE(TEXT($A27,"@"),",",".")&".0")-1))),"") | P27: =IFERROR(INDEX(Suivi!$G:$G,27+($C$1-1)*54),"")
A28: =IFERROR(INDEX(Suivi!$B:$B,28+($C$1-1)*54),"") | C28: =IFERROR(IF(INDEX(Suivi!$D:$D,28+($C$1-1)*54)="",INDEX(Suivi!$C:$C,28+($C$1-1)*54),INDEX(Suivi!$D:$D,28+($C$1-1)*54)),"") | E28: =IFERROR(INDEX(Suivi!$E:$E,28+($C$1-1)*54),"") | F28: =IFERROR(INDEX(Suivi!$F:$F,28+($C$1-1)*54),"") | O28: =IFERROR(IF(ISNUMBER($A28),1,VALUE(LEFT(SUBSTITUTE(TEXT($A28,"@"),",","."),FIND(".",SUBSTITUTE(TEXT($A28,"@"),",",".")&".0")-1))),"") | P28: =IFERROR(INDEX(Suivi!$G:$G,28+($C$1-1)*54),"")
A29: =IFERROR(INDEX(Suivi!$B:$B,29+($C$1-1)*54),"") | C29: =IFERROR(IF(INDEX(Suivi!$D:$D,29+($C$1-1)*54)="",INDEX(Suivi!$C:$C,29+($C$1-1)*54),INDEX(Suivi!$D:$D,29+($C$1-1)*54)),"") | E29: =IFERROR(INDEX(Suivi!$E:$E,29+($C$1-1)*54),"") | F29: =IFERROR(INDEX(Suivi!$F:$F,29+($C$1-1)*54),"") | O29: =IFERROR(IF(ISNUMBER($A29),1,VALUE(LEFT(SUBSTITUTE(TEXT($A29,"@"),",","."),FIND(".",SUBSTITUTE(TEXT($A29,"@"),",",".")&".0")-1))),"") | P29: =IFERROR(INDEX(Suivi!$G:$G,29+($C$1-1)*54),"")
A30: =IFERROR(INDEX(Suivi!$B:$B,30+($C$1-1)*54),"") | C30: =IFERROR(IF(INDEX(Suivi!$D:$D,30+($C$1-1)*54)="",INDEX(Suivi!$C:$C,30+($C$1-1)*54),INDEX(Suivi!$D:$D,30+($C$1-1)*54)),"") | E30: =IFERROR(INDEX(Suivi!$E:$E,30+($C$1-1)*54),"") | F30: =IFERROR(INDEX(Suivi!$F:$F,30+($C$1-1)*54),"") | O30: =IFERROR(IF(ISNUMBER($A30),1,VALUE(LEFT(SUBSTITUTE(TEXT($A30,"@"),",","."),FIND(".",SUBSTITUTE(TEXT($A30,"@"),",",".")&".0")-1))),"") | P30: =IFERROR(INDEX(Suivi!$G:$G,30+($C$1-1)*54),"")
A31: =IFERROR(INDEX(Suivi!$B:$B,31+($C$1-1)*54),"") | C31: =IFERROR(IF(INDEX(Suivi!$D:$D,31+($C$1-1)*54)="",INDEX(Suivi!$C:$C,31+($C$1-1)*54),INDEX(Suivi!$D:$D,31+($C$1-1)*54)),"") | E31: =IFERROR(INDEX(Suivi!$E:$E,31+($C$1-1)*54),"") | F31: =IFERROR(INDEX(Suivi!$F:$F,31+($C$1-1)*54),"") | O31: =IFERROR(IF(ISNUMBER($A31),1,VALUE(LEFT(SUBSTITUTE(TEXT($A31,"@"),",","."),FIND(".",SUBSTITUTE(TEXT($A31,"@"),",",".")&".0")-1))),"") | P31: =IFERROR(INDEX(Suivi!$G:$G,31+($C$1-1)*54),"")
A32: =IFERROR(INDEX(Suivi!$B:$B,32+($C$1-1)*54),"") | C32: =IFERROR(IF(INDEX(Suivi!$D:$D,32+($C$1-1)*54)="",INDEX(Suivi!$C:$C,32+($C$1-1)*54),INDEX(Suivi!$D:$D,32+($C$1-1)*54)),"") | E32: =IFERROR(INDEX(Suivi!$E:$E,32+($C$1-1)*54),"") | F32: =IFERROR(INDEX(Suivi!$F:$F,32+($C$1-1)*54),"") | O32: =IFERROR(IF(ISNUMBER($A32),1,VALUE(LEFT(SUBSTITUTE(TEXT($A32,"@"),",","."),FIND(".",SUBSTITUTE(TEXT($A32,"@"),",",".")&".0")-1))),"") | P32: =IFERROR(INDEX(Suivi!$G:$G,32+($C$1-1)*54),"")
A33: =IFERROR(INDEX(Suivi!$B:$B,33+($C$1-1)*54),"") | C33: =IFERROR(IF(INDEX(Suivi!$D:$D,33+($C$1-1)*54)="",INDEX(Suivi!$C:$C,33+($C$1-1)*54),INDEX(Suivi!$D:$D,33+($C$1-1)*54)),"") | E33: =IFERROR(INDEX(Suivi!$E:$E,33+($C$1-1)*54),"") | F33: =IFERROR(INDEX(Suivi!$F:$F,33+($C$1-1)*54),"") | O33: =IFERROR(IF(ISNUMBER($A33),1,VALUE(LEFT(SUBSTITUTE(TEXT($A33,"@"),",","."),FIND(".",SUBSTITUTE(TEXT($A33,"@"),",",".")&".0")-1))),"") | P33: =IFERROR(INDEX(Suivi!$G:$G,33+($C$1-1)*54),"")
A34: =IFERROR(INDEX(Suivi!$B:$B,34+($C$1-1)*54),"") | C34: =IFERROR(IF(INDEX(Suivi!$D:$D,34+($C$1-1)*54)="",INDEX(Suivi!$C:$C,34+($C$1-1)*54),INDEX(Suivi!$D:$D,34+($C$1-1)*54)),"") | E34: =IFERROR(INDEX(Suivi!$E:$E,34+($C$1-1)*54),"") | F34: =IFERROR(INDEX(Suivi!$F:$F,34+($C$1-1)*54),"") | O34: =IFERROR(IF(ISNUMBER($A34),1,VALUE(LEFT(SUBSTITUTE(TEXT($A34,"@"),",","."),FIND(".",SUBSTITUTE(TEXT($A34,"@"),",",".")&".0")-1))),"") | P34: =IFERROR(INDEX(Suivi!$G:$G,34+($C$1-1)*54),"")
A35: =IFERROR(INDEX(Suivi!$B:$B,35+($C$1-1)*54),"") | C35: =IFERROR(IF(INDEX(Suivi!$D:$D,35+($C$1-1)*54)="",INDEX(Suivi!$C:$C,35+($C$1-1)*54),INDEX(Suivi!$D:$D,35+($C$1-1)*54)),"") | E35: =IFERROR(INDEX(Suivi!$E:$E,35+($C$1-1)*54),"") | F35: =IFERROR(INDEX(Suivi!$F:$F,35+($C$1-1)*54),"") | O35: =IFERROR(IF(ISNUMBER($A35),1,VALUE(LEFT(SUBSTITUTE(TEXT($A35,"@"),",","."),FIND(".",SUBSTITUTE(TEXT($A35,"@"),",",".")&".0")-1))),"") | P35: =IFERROR(INDEX(Suivi!$G:$G,35+($C$1-1)*54),"")
A36: =IFERROR(INDEX(Suivi!$B:$B,36+($C$1-1)*54),"") | C36: =IFERROR(IF(INDEX(Suivi!$D:$D,36+($C$1-1)*54)="",INDEX(Suivi!$C:$C,36+($C$1-1)*54),INDEX(Suivi!$D:$D,36+($C$1-1)*54)),"") | E36: =IFERROR(INDEX(Suivi!$E:$E,36+($C$1-1)*54),"") | F36: =IFERROR(INDEX(Suivi!$F:$F,36+($C$1-1)*54),"") | O36: =IFERROR(IF(ISNUMBER($A36),1,VALUE(LEFT(SUBSTITUTE(TEXT($A36,"@"),",","."),FIND(".",SUBSTITUTE(TEXT($A36,"@"),",",".")&".0")-1))),"") | P36: =IFERROR(INDEX(Suivi!$G:$G,36+($C$1-1)*54),"")
A37: =IFERROR(INDEX(Suivi!$B:$B,37+($C$1-1)*54),"") | C37: =IFERROR(IF(INDEX(Suivi!$D:$D,37+($C$1-1)*54)="",INDEX(Suivi!$C:$C,37+($C$1-1)*54),INDEX(Suivi!$D:$D,37+($C$1-1)*54)),"") | E37: =IFERROR(INDEX(Suivi!$E:$E,37+($C$1-1)*54),"") | F37: =IFERROR(INDEX(Suivi!$F:$F,37+($C$1-1)*54),"") | O37: =IFERROR(IF(ISNUMBER($A37),1,VALUE(LEFT(SUBSTITUTE(TEXT($A37,"@"),",","."),FIND(".",SUBSTITUTE(TEXT($A37,"@"),",",".")&".0")-1))),"") | P37: =IFERROR(INDEX(Suivi!$G:$G,37+($C$1-1)*54),"")
A38: =IFERROR(INDEX(Suivi!$B:$B,38+($C$1-1)*54),"") | C38: =IFERROR(IF(INDEX(Suivi!$D:$D,38+($C$1-1)*54)="",INDEX(Suivi!$C:$C,38+($C$1-1)*54),INDEX(Suivi!$D:$D,38+($C$1-1)*54)),"") | E38: =IFERROR(INDEX(Suivi!$E:$E,38+($C$1-1)*54),"") | F38: =IFERROR(INDEX(Suivi!$F:$F,38+($C$1-1)*54),"") | O38: =IFERROR(IF(ISNUMBER($A38),1,VALUE(LEFT(SUBSTITUTE(TEXT($A38,"@"),",","."),FIND(".",SUBSTITUTE(TEXT($A38,"@"),",",".")&".0")-1))),"") | P38: =IFERROR(INDEX(Suivi!$G:$G,38+($C$1-1)*54),"")
A39: =IFERROR(INDEX(Suivi!$B:$B,39+($C$1-1)*54),"") | C39: =IFERROR(IF(INDEX(Suivi!$D:$D,39+($C$1-1)*54)="",INDEX(Suivi!$C:$C,39+($C$1-1)*54),INDEX(Suivi!$D:$D,39+($C$1-1)*54)),"") | E39: =IFERROR(INDEX(Suivi!$E:$E,39+($C$1-1)*54),"") | F39: =IFERROR(INDEX(Suivi!$F:$F,39+($C$1-1)*54),"") | O39: =IFERROR(IF(ISNUMBER($A39),1,VALUE(LEFT(SUBSTITUTE(TEXT($A39,"@"),",","."),FIND(".",SUBSTITUTE(TEXT($A39,"@"),",",".")&".0")-1))),"") | P39: =IFERROR(INDEX(Suivi!$G:$G,39+($C$1-1)*54),"")
A40: =IFERROR(INDEX(Suivi!$B:$B,40+($C$1-1)*54),"") | C40: =IFERROR(IF(INDEX(Suivi!$D:$D,40+($C$1-1)*54)="",INDEX(Suivi!$C:$C,40+($C$1-1)*54),INDEX(Suivi!$D:$D,40+($C$1-1)*54)),"") | E40: =IFERROR(INDEX(Suivi!$E:$E,40+($C$1-1)*54),"") | F40: =IFERROR(INDEX(Suivi!$F:$F,40+($C$1-1)*54),"") | O40: =IFERROR(IF(ISNUMBER($A40),1,VALUE(LEFT(SUBSTITUTE(TEXT($A40,"@"),",","."),FIND(".",SUBSTITUTE(TEXT($A40,"@"),",",".")&".0")-1))),"") | P40: =IFERROR(INDEX(Suivi!$G:$G,40+($C$1-1)*54),"")
...

Sheet Planning
A1: PLANNING GLISSANT — Tâches à faire, dossier par dossier
A2: Modifiez la date en D2 pour faire glisser la fenêtre d'un mois. | C2: Date de référence : | D2: =TODAY() | E2: Fin de période : | F2: =D2+30
A3: Dossier | B3: ID | C3: Étape | D3: Début | E3: Fin | F3: Statut | G3: Fait ? | H3: Période | I3: Retard | J3: Date CS | K3: Date Jury
A4: =IF($B4="","",INDEX(Dossiers!$E$4:$E$63,1)) | B4: =IF(INDEX(Suivi!$B:$B,5)="","",INDEX(Suivi!$B:$B,5)) | C4: =IF($B4="","",IF(INDEX(Suivi!$D:$D,5)="",INDEX(Suivi!$C:$C,5),INDEX(Suivi!$D:$D,5))) | D4: =IF($B4="","",INDEX(Suivi!$E:$E,5)) | E4: =IF($B4="","",INDEX(Suivi!$F:$F,5)) | F4: =IF($B4="","",INDEX(Suivi!$G:$G,5)) | H4: =IF(OR($B4="",NOT(ISNUMBER($D4))),"",IF($E4<$D$2,"Passé",IF($D4>$F$2,"À venir","Dans la période"))) | I4: =IF(OR($B4="",NOT(ISNUMBER($D4))),"",IF(AND($E4<$D$2,$G4<>"X",$F4<>"Réalisé",$F4<>"Clôturé"),"RETARD","")) | J4: =IF($B4="","",IF(INDEX(Dossiers!$F$4:$F$63,1)="","",INDEX(Dossiers!$F$4:$F$63,1))) | K4: =IF($B4="","",IF(INDEX(Dossiers!$G$4:$G$63,1)="","",INDEX(Dossiers!$G$4:$G$63,1)))
A5: =IF($B5="","",INDEX(Dossiers!$E$4:$E$63,1)) | B5: =IF(INDEX(Suivi!$B:$B,6)="","",INDEX(Suivi!$B:$B,6)) | C5: =IF($B5="","",IF(INDEX(Suivi!$D:$D,6)="",INDEX(Suivi!$C:$C,6),INDEX(Suivi!$D:$D,6))) | D5: =IF($B5="","",INDEX(Suivi!$E:$E,6)) | E5: =IF($B5="","",INDEX(Suivi!$F:$F,6)) | F5: =IF($B5="","",INDEX(Suivi!$G:$G,6)) | H5: =IF(OR($B5="",NOT(ISNUMBER($D5))),"",IF($E5<$D$2,"Passé",IF($D5>$F$2,"À venir","Dans la période"))) | I5: =IF(OR($B5="",NOT(ISNUMBER($D5))),"",IF(AND($E5<$D$2,$G5<>"X",$F5<>"Réalisé",$F5<>"Clôturé"),"RETARD","")) | J5: =IF($B5="","",IF(INDEX(Dossiers!$F$4:$F$63,1)="","",INDEX(Dossiers!$F$4:$F$63,1))) | K5: =IF($B5="","",IF(INDEX(Dossiers!$G$4:$G$63,1)="","",INDEX(Dossiers!$G$4:$G$63,1)))
A6: =IF($B6="","",INDEX(Dossiers!$E$4:$E$63,1)) | B6: =IF(INDEX(Suivi!$B:$B,7)="","",INDEX(Suivi!$B:$B,7)) | C6: =IF($B6="","",IF(INDEX(Suivi!$D:$D,7)="",INDEX(Suivi!$C:$C,7),INDEX(Suivi!$D:$D,7))) | D6: =IF($B6="","",INDEX(Suivi!$E:$E,7)) | E6: =IF($B6="","",INDEX(Suivi!$F:$F,7)) | F6: =IF($B6="","",INDEX(Suivi!$G:$G,7)) | H6: =IF(OR($B6="",NOT(ISNUMBER($D6))),"",IF($E6<$D$2,"Passé",IF($D6>$F$2,"À venir","Dans la période"))) | I6: =IF(OR($B6="",NOT(ISNUMBER($D6))),"",IF(AND($E6<$D$2,$G6<>"X",$F6<>"Réalisé",$F6<>"Clôturé"),"RETARD","")) | J6: =IF($B6="","",IF(INDEX(Dossiers!$F$4:$F$63,1)="","",INDEX(Dossiers!$F$4:$F$63,1))) | K6: =IF($B6="","",IF(INDEX(Dossiers!$G$4:$G$63,1)="","",INDEX(Dossiers!$G$4:$G$63,1)))
A7: =IF($B7="","",INDEX(Dossiers!$E$4:$E$63,1)) | B7: =IF(INDEX(Suivi!$B:$B,8)="","",INDEX(Suivi!$B:$B,8)) | C7: =IF($B7="","",IF(INDEX(Suivi!$D:$D,8)="",INDEX(Suivi!$C:$C,8),INDEX(Suivi!$D:$D,8))) | D7: =IF($B7="","",INDEX(Suivi!$E:$E,8)) | E7: =IF($B7="","",INDEX(Suivi!$F:$F,8)) | F7: =IF($B7="","",INDEX(Suivi!$G:$G,8)) | H7: =IF(OR($B7="",NOT(ISNUMBER($D7))),"",IF($E7<$D$2,"Passé",IF($D7>$F$2,"À venir","Dans la période"))) | I7: =IF(OR($B7="",NOT(ISNUMBER($D7))),"",IF(AND($E7<$D$2,$G7<>"X",$F7<>"Réalisé",$F7<>"Clôturé"),"RETARD","")) | J7: =IF($B7="","",IF(INDEX(Dossiers!$F$4:$F$63,1)="","",INDEX(Dossiers!$F$4:$F$63,1))) | K7: =IF($B7="","",IF(INDEX(Dossiers!$G$4:$G$63,1)="","",INDEX(Dossiers!$G$4:$G$63,1)))
A8: =IF($B8="","",INDEX(Dossiers!$E$4:$E$63,1)) | B8: =IF(INDEX(Suivi!$B:$B,9)="","",INDEX(Suivi!$B:$B,9)) | C8: =IF($B8="","",IF(INDEX(Suivi!$D:$D,9)="",INDEX(Suivi!$C:$C,9),INDEX(Suivi!$D:$D,9))) | D8: =IF($B8="","",INDEX(Suivi!$E:$E,9)) | E8: =IF($B8="","",INDEX(Suivi!$F:$F,9)) | F8: =IF($B8="","",INDEX(Suivi!$G:$G,9)) | H8: =IF(OR($B8="",NOT(ISNUMBER($D8))),"",IF($E8<$D$2,"Passé",IF($D8>$F$2,"À venir","Dans la période"))) | I8: =IF(OR($B8="",NOT(ISNUMBER($D8))),"",IF(AND($E8<$D$2,$G8<>"X",$F8<>"Réalisé",$F8<>"Clôturé"),"RETARD","")) | J8: =IF($B8="","",IF(INDEX(Dossiers!$F$4:$F$63,1)="","",INDEX(Dossiers!$F$4:$F$63,1))) | K8: =IF($B8="","",IF(INDEX(Dossiers!$G$4:$G$63,1)="","",INDEX(Dossiers!$G$4:$G$63,1)))
A9: =IF($B9="","",INDEX(Dossiers!$E$4:$E$63,1)) | B9: =IF(INDEX(Suivi!$B:$B,10)="","",INDEX(Suivi!$B:$B,10)) | C9: =IF($B9="","",IF(INDEX(Suivi!$D:$D,10)="",INDEX(Suivi!$C:$C,10),INDEX(Suivi!$D:$D,10))) | D9: =IF($B9="","",INDEX(Suivi!$E:$E,10)) | E9: =IF($B9="","",INDEX(Suivi!$F:$F,10)) | F9: =IF($B9="","",INDEX(Suivi!$G:$G,10)) | H9: =IF(OR($B9="",NOT(ISNUMBER($D9))),"",IF($E9<$D$2,"Passé",IF($D9>$F$2,"À venir","Dans la période"))) | I9: =IF(OR($B9="",NOT(ISNUMBER($D9))),"",IF(AND($E9<$D$2,$G9<>"X",$F9<>"Réalisé",$F9<>"Clôturé"),"RETARD","")) | J9: =IF($B9="","",IF(INDEX(Dossiers!$F$4:$F$63,1)="","",INDEX(Dossiers!$F$4:$F$63,1))) | K9: =IF($B9="","",IF(INDEX(Dossiers!$G$4:$G$63,1)="","",INDEX(Dossiers!$G$4:$G$63,1)))
A10: =IF($B10="","",INDEX(Dossiers!$E$4:$E$63,1)) | B10: =IF(INDEX(Suivi!$B:$B,11)="","",INDEX(Suivi!$B:$B,11)) | C10: =IF($B10="","",IF(INDEX(Suivi!$D:$D,11)="",INDEX(Suivi!$C:$C,11),INDEX(Suivi!$D:$D,11))) | D10: =IF($B10="","",INDEX(Suivi!$E:$E,11)) | E10: =IF($B10="","",INDEX(Suivi!$F:$F,11)) | F10: =IF($B10="","",INDEX(Suivi!$G:$G,11)) | H10: =IF(OR($B10="",NOT(ISNUMBER($D10))),"",IF($E10<$D$2,"Passé",IF($D10>$F$2,"À venir","Dans la période"))) | I10: =IF(OR($B10="",NOT(ISNUMBER($D10))),"",IF(AND($E10<$D$2,$G10<>"X",$F10<>"Réalisé",$F10<>"Clôturé"),"RETARD","")) | J10: =IF($B10="","",IF(INDEX(Dossiers!$F$4:$F$63,1)="","",INDEX(Dossiers!$F$4:$F$63,1))) | K10: =IF($B10="","",IF(INDEX(Dossiers!$G$4:$G$63,1)="","",INDEX(Dossiers!$G$4:$G$63,1)))
A11: =IF($B11="","",INDEX(Dossiers!$E$4:$E$63,1)) | B11: =IF(INDEX(Suivi!$B:$B,12)="","",INDEX(Suivi!$B:$B,12)) | C11: =IF($B11="","",IF(INDEX(Suivi!$D:$D,12)="",INDEX(Suivi!$C:$C,12),INDEX(Suivi!$D:$D,12))) | D11: =IF($B11="","",INDEX(Suivi!$E:$E,12)) | E11: =IF($B11="","",INDEX(Suivi!$F:$F,12)) | F11: =IF($B11="","",INDEX(Suivi!$G:$G,12)) | H11: =IF(OR($B11="",NOT(ISNUMBER($D11))),"",IF($E11<$D$2,"Passé",IF($D11>$F$2,"À venir","Dans la période"))) | I11: =IF(OR($B11="",NOT(ISNUMBER($D11))),"",IF(AND($E11<$D$2,$G11<>"X",$F11<>"Réalisé",$F11<>"Clôturé"),"RETARD","")) | J11: =IF($B11="","",IF(INDEX(Dossiers!$F$4:$F$63,1)="","",INDEX(Dossiers!$F$4:$F$63,1))) | K11: =IF($B11="","",IF(INDEX(Dossiers!$G$4:$G$63,1)="","",INDEX(Dossiers!$G$4:$G$63,1)))
A12: =IF($B12="","",INDEX(Dossiers!$E$4:$E$63,1)) | B12: =IF(INDEX(Suivi!$B:$B,13)="","",INDEX(Suivi!$B:$B,13)) | C12: =IF($B12="","",IF(INDEX(Suivi!$D:$D,13)="",INDEX(Suivi!$C:$C,13),INDEX(Suivi!$D:$D,13))) | D12: =IF($B12="","",INDEX(Suivi!$E:$E,13)) | E12: =IF($B12="","",INDEX(Suivi!$F:$F,13)) | F12: =IF($B12="","",INDEX(Suivi!$G:$G,13)) | H12: =IF(OR($B12="",NOT(ISNUMBER($D12))),"",IF($E12<$D$2,"Passé",IF($D12>$F$2,"À venir","Dans la période"))) | I12: =IF(OR($B12="",NOT(ISNUMBER($D12))),"",IF(AND($E12<$D$2,$G12<>"X",$F12<>"Réalisé",$F12<>"Clôturé"),"RETARD","")) | J12: =IF($B12="","",IF(INDEX(Dossiers!$F$4:$F$63,1)="","",INDEX(Dossiers!$F$4:$F$63,1))) | K12: =IF($B12="","",IF(INDEX(Dossiers!$G$4:$G$63,1)="","",INDEX(Dossiers!$G$4:$G$63,1)))
A13: =IF($B13="","",INDEX(Dossiers!$E$4:$E$63,1)) | B13: =IF(INDEX(Suivi!$B:$B,14)="","",INDEX(Suivi!$B:$B,14)) | C13: =IF($B13="","",IF(INDEX(Suivi!$D:$D,14)="",INDEX(Suivi!$C:$C,14),INDEX(Suivi!$D:$D,14))) | D13: =IF($B13="","",INDEX(Suivi!$E:$E,14)) | E13: =IF($B13="","",INDEX(Suivi!$F:$F,14)) | F13: =IF($B13="","",INDEX(Suivi!$G:$G,14)) | H13: =IF(OR($B13="",NOT(ISNUMBER($D13))),"",IF($E13<$D$2,"Passé",IF($D13>$F$2,"À venir","Dans la période"))) | I13: =IF(OR($B13="",NOT(ISNUMBER($D13))),"",IF(AND($E13<$D$2,$G13<>"X",$F13<>"Réalisé",$F13<>"Clôturé"),"RETARD","")) | J13: =IF($B13="","",IF(INDEX(Dossiers!$F$4:$F$63,1)="","",INDEX(Dossiers!$F$4:$F$63,1))) | K13: =IF($B13="","",IF(INDEX(Dossiers!$G$4:$G$63,1)="","",INDEX(Dossiers!$G$4:$G$63,1)))
A14: =IF($B14="","",INDEX(Dossiers!$E$4:$E$63,1)) | B14: =IF(INDEX(Suivi!$B:$B,15)="","",INDEX(Suivi!$B:$B,15)) | C14: =IF($B14="","",IF(INDEX(Suivi!$D:$D,15)="",INDEX(Suivi!$C:$C,15),INDEX(Suivi!$D:$D,15))) | D14: =IF($B14="","",INDEX(Suivi!$E:$E,15)) | E14: =IF($B14="","",INDEX(Suivi!$F:$F,15)) | F14: =IF($B14="","",INDEX(Suivi!$G:$G,15)) | H14: =IF(OR($B14="",NOT(ISNUMBER($D14))),"",IF($E14<$D$2,"Passé",IF($D14>$F$2,"À venir","Dans la période"))) | I14: =IF(OR($B14="",NOT(ISNUMBER($D14))),"",IF(AND($E14<$D$2,$G14<>"X",$F14<>"Réalisé",$F14<>"Clôturé"),"RETARD","")) | J14: =IF($B14="","",IF(INDEX(Dossiers!$F$4:$F$63,1)="","",INDEX(Dossiers!$F$4:$F$63,1))) | K14: =IF($B14="","",IF(INDEX(Dossiers!$G$4:$G$63,1)="","",INDEX(Dossiers!$G$4:$G$63,1)))
A15: =IF($B15="","",INDEX(Dossiers!$E$4:$E$63,1)) | B15: =IF(INDEX(Suivi!$B:$B,16)="","",INDEX(Suivi!$B:$B,16)) | C15: =IF($B15="","",IF(INDEX(Suivi!$D:$D,16)="",INDEX(Suivi!$C:$C,16),INDEX(Suivi!$D:$D,16))) | D15: =IF($B15="","",INDEX(Suivi!$E:$E,16)) | E15: =IF($B15="","",INDEX(Suivi!$F:$F,16)) | F15: =IF($B15="","",INDEX(Suivi!$G:$G,16)) | H15: =IF(OR($B15="",NOT(ISNUMBER($D15))),"",IF($E15<$D$2,"Passé",IF($D15>$F$2,"À venir","Dans la période"))) | I15: =IF(OR($B15="",NOT(ISNUMBER($D15))),"",IF(AND($E15<$D$2,$G15<>"X",$F15<>"Réalisé",$F15<>"Clôturé"),"RETARD","")) | J15: =IF($B15="","",IF(INDEX(Dossiers!$F$4:$F$63,1)="","",INDEX(Dossiers!$F$4:$F$63,1))) | K15: =IF($B15="","",IF(INDEX(Dossiers!$G$4:$G$63,1)="","",INDEX(Dossiers!$G$4:$G$63,1)))
A16: =IF($B16="","",INDEX(Dossiers!$E$4:$E$63,1)) | B16: =IF(INDEX(Suivi!$B:$B,17)="","",INDEX(Suivi!$B:$B,17)) | C16: =IF($B16="","",IF(INDEX(Suivi!$D:$D,17)="",INDEX(Suivi!$C:$C,17),INDEX(Suivi!$D:$D,17))) | D16: =IF($B16="","",INDEX(Suivi!$E:$E,17)) | E16: =IF($B16="","",INDEX(Suivi!$F:$F,17)) | F16: =IF($B16="","",INDEX(Suivi!$G:$G,17)) | H16: =IF(OR($B16="",NOT(ISNUMBER($D16))),"",IF($E16<$D$2,"Passé",IF($D16>$F$2,"À venir","Dans la période"))) | I16: =IF(OR($B16="",NOT(ISNUMBER($D16))),"",IF(AND($E16<$D$2,$G16<>"X",$F16<>"Réalisé",$F16<>"Clôturé"),"RETARD","")) | J16: =IF($B16="","",IF(INDEX(Dossiers!$F$4:$F$63,1)="","",INDEX(Dossiers!$F$4:$F$63,1))) | K16: =IF($B16="","",IF(INDEX(Dossiers!$G$4:$G$63,1)="","",INDEX(Dossiers!$G$4:$G$63,1)))
A17: =IF($B17="","",INDEX(Dossiers!$E$4:$E$63,1)) | B17: =IF(INDEX(Suivi!$B:$B,18)="","",INDEX(Suivi!$B:$B,18)) | C17: =IF($B17="","",IF(INDEX(Suivi!$D:$D,18)="",INDEX(Suivi!$C:$C,18),INDEX(Suivi!$D:$D,18))) | D17: =IF($B17="","",INDEX(Suivi!$E:$E,18)) | E17: =IF($B17="","",INDEX(Suivi!$F:$F,18)) | F17: =IF($B17="","",INDEX(Suivi!$G:$G,18)) | H17: =IF(OR($B17="",NOT(ISNUMBER($D17))),"",IF($E17<$D$2,"Passé",IF($D17>$F$2,"À venir","Dans la période"))) | I17: =IF(OR($B17="",NOT(ISNUMBER($D17))),"",IF(AND($E17<$D$2,$G17<>"X",$F17<>"Réalisé",$F17<>"Clôturé"),"RETARD","")) | J17: =IF($B17="","",IF(INDEX(Dossiers!$F$4:$F$63,1)="","",INDEX(Dossiers!$F$4:$F$63,1))) | K17: =IF($B17="","",IF(INDEX(Dossiers!$G$4:$G$63,1)="","",INDEX(Dossiers!$G$4:$G$63,1)))
A18: =IF($B18="","",INDEX(Dossiers!$E$4:$E$63,1)) | B18: =IF(INDEX(Suivi!$B:$B,19)="","",INDEX(Suivi!$B:$B,19)) | C18: =IF($B18="","",IF(INDEX(Suivi!$D:$D,19)="",INDEX(Suivi!$C:$C,19),INDEX(Suivi!$D:$D,19))) | D18: =IF($B18="","",INDEX(Suivi!$E:$E,19)) | E18: =IF($B18="","",INDEX(Suivi!$F:$F,19)) | F18: =IF($B18="","",INDEX(Suivi!$G:$G,19)) | H18: =IF(OR($B18="",NOT(ISNUMBER($D18))),"",IF($E18<$D$2,"Passé",IF($D18>$F$2,"À venir","Dans la période"))) | I18: =IF(OR($B18="",NOT(ISNUMBER($D18))),"",IF(AND($E18<$D$2,$G18<>"X",$F18<>"Réalisé",$F18<>"Clôturé"),"RETARD","")) | J18: =IF($B18="","",IF(INDEX(Dossiers!$F$4:$F$63,1)="","",INDEX(Dossiers!$F$4:$F$63,1))) | K18: =IF($B18="","",IF(INDEX(Dossiers!$G$4:$G$63,1)="","",INDEX(Dossiers!$G$4:$G$63,1)))
A19: =IF($B19="","",INDEX(Dossiers!$E$4:$E$63,1)) | B19: =IF(INDEX(Suivi!$B:$B,20)="","",INDEX(Suivi!$B:$B,20)) | C19: =IF($B19="","",IF(INDEX(Suivi!$D:$D,20)="",INDEX(Suivi!$C:$C,20),INDEX(Suivi!$D:$D,20))) | D19: =IF($B19="","",INDEX(Suivi!$E:$E,20)) | E19: =IF($B19="","",INDEX(Suivi!$F:$F,20)) | F19: =IF($B19="","",INDEX(Suivi!$G:$G,20)) | H19: =IF(OR($B19="",NOT(ISNUMBER($D19))),"",IF($E19<$D$2,"Passé",IF($D19>$F$2,"À venir","Dans la période"))) | I19: =IF(OR($B19="",NOT(ISNUMBER($D19))),"",IF(AND($E19<$D$2,$G19<>"X",$F19<>"Réalisé",$F19<>"Clôturé"),"RETARD","")) | J19: =IF($B19="","",IF(INDEX(Dossiers!$F$4:$F$63,1)="","",INDEX(Dossiers!$F$4:$F$63,1))) | K19: =IF($B19="","",IF(INDEX(Dossiers!$G$4:$G$63,1)="","",INDEX(Dossiers!$G$4:$G$63,1)))
A20: =IF($B20="","",INDEX(Dossiers!$E$4:$E$63,1)) | B20: =IF(INDEX(Suivi!$B:$B,21)="","",INDEX(Suivi!$B:$B,21)) | C20: =IF($B20="","",IF(INDEX(Suivi!$D:$D,21)="",INDEX(Suivi!$C:$C,21),INDEX(Suivi!$D:$D,21))) | D20: =IF($B20="","",INDEX(Suivi!$E:$E,21)) | E20: =IF($B20="","",INDEX(Suivi!$F:$F,21)) | F20: =IF($B20="","",INDEX(Suivi!$G:$G,21)) | H20: =IF(OR($B20="",NOT(ISNUMBER($D20))),"",IF($E20<$D$2,"Passé",IF($D20>$F$2,"À venir","Dans la période"))) | I20: =IF(OR($B20="",NOT(ISNUMBER($D20))),"",IF(AND($E20<$D$2,$G20<>"X",$F20<>"Réalisé",$F20<>"Clôturé"),"RETARD","")) | J20: =IF($B20="","",IF(INDEX(Dossiers!$F$4:$F$63,1)="","",INDEX(Dossiers!$F$4:$F$63,1))) | K20: =IF($B20="","",IF(INDEX(Dossiers!$G$4:$G$63,1)="","",INDEX(Dossiers!$G$4:$G$63,1)))
A21: =IF($B21="","",INDEX(Dossiers!$E$4:$E$63,1)) | B21: =IF(INDEX(Suivi!$B:$B,22)="","",INDEX(Suivi!$B:$B,22)) | C21: =IF($B21="","",IF(INDEX(Suivi!$D:$D,22)="",INDEX(Suivi!$C:$C,22),INDEX(Suivi!$D:$D,22))) | D21: =IF($B21="","",INDEX(Suivi!$E:$E,22)) | E21: =IF($B21="","",INDEX(Suivi!$F:$F,22)) | F21: =IF($B21="","",INDEX(Suivi!$G:$G,22)) | H21: =IF(OR($B21="",NOT(ISNUMBER($D21))),"",IF($E21<$D$2,"Passé",IF($D21>$F$2,"À venir","Dans la période"))) | I21: =IF(OR($B21="",NOT(ISNUMBER($D21))),"",IF(AND($E21<$D$2,$G21<>"X",$F21<>"Réalisé",$F21<>"Clôturé"),"RETARD","")) | J21: =IF($B21="","",IF(INDEX(Dossiers!$F$4:$F$63,1)="","",INDEX(Dossiers!$F$4:$F$63,1))) | K21: =IF($B21="","",IF(INDEX(Dossiers!$G$4:$G$63,1)="","",INDEX(Dossiers!$G$4:$G$63,1)))
A22: =IF($B22="","",INDEX(Dossiers!$E$4:$E$63,1)) | B22: =IF(INDEX(Suivi!$B:$B,23)="","",INDEX(Suivi!$B:$B,23)) | C22: =IF($B22="","",IF(INDEX(Suivi!$D:$D,23)="",INDEX(Suivi!$C:$C,23),INDEX(Suivi!$D:$D,23))) | D22: =IF($B22="","",INDEX(Suivi!$E:$E,23)) | E22: =IF($B22="","",INDEX(Suivi!$F:$F,23)) | F22: =IF($B22="","",INDEX(Suivi!$G:$G,23)) | H22: =IF(OR($B22="",NOT(ISNUMBER($D22))),"",IF($E22<$D$2,"Passé",IF($D22>$F$2,"À venir","Dans la période"))) | I22: =IF(OR($B22="",NOT(ISNUMBER($D22))),"",IF(AND($E22<$D$2,$G22<>"X",$F22<>"Réalisé",$F22<>"Clôturé"),"RETARD","")) | J22: =IF($B22="","",IF(INDEX(Dossiers!$F$4:$F$63,1)="","",INDEX(Dossiers!$F$4:$F$63,1))) | K22: =IF($B22="","",IF(INDEX(Dossiers!$G$4:$G$63,1)="","",INDEX(Dossiers!$G$4:$G$63,1)))
A23: =IF($B23="","",INDEX(Dossiers!$E$4:$E$63,1)) | B23: =IF(INDEX(Suivi!$B:$B,24)="","",INDEX(Suivi!$B:$B,24)) | C23: =IF($B23="","",IF(INDEX(Suivi!$D:$D,24)="",INDEX(Suivi!$C:$C,24),INDEX(Suivi!$D:$D,24))) | D23: =IF($B23="","",INDEX(Suivi!$E:$E,24)) | E23: =IF($B23="","",INDEX(Suivi!$F:$F,24)) | F23: =IF($B23="","",INDEX(Suivi!$G:$G,24)) | H23: =IF(OR($B23="",NOT(ISNUMBER($D23))),"",IF($E23<$D$2,"Passé",IF($D23>$F$2,"À venir","Dans la période"))) | I23: =IF(OR($B23="",NOT(ISNUMBER($D23))),"",IF(AND($E23<$D$2,$G23<>"X",$F23<>"Réalisé",$F23<>"Clôturé"),"RETARD","")) | J23: =IF($B23="","",IF(INDEX(Dossiers!$F$4:$F$63,1)="","",INDEX(Dossiers!$F$4:$F$63,1))) | K23: =IF($B23="","",IF(INDEX(Dossiers!$G$4:$G$63,1)="","",INDEX(Dossiers!$G$4:$G$63,1)))
A24: =IF($B24="","",INDEX(Dossiers!$E$4:$E$63,1)) | B24: =IF(INDEX(Suivi!$B:$B,25)="","",INDEX(Suivi!$B:$B,25)) | C24: =IF($B24="","",IF(INDEX(Suivi!$D:$D,25)="",INDEX(Suivi!$C:$C,25),INDEX(Suivi!$D:$D,25))) | D24: =IF($B24="","",INDEX(Suivi!$E:$E,25)) | E24: =IF($B24="","",INDEX(Suivi!$F:$F,25)) | F24: =IF($B24="","",INDEX(Suivi!$G:$G,25)) | H24: =IF(OR($B24="",NOT(ISNUMBER($D24))),"",IF($E24<$D$2,"Passé",IF($D24>$F$2,"À venir","Dans la période"))) | I24: =IF(OR($B24="",NOT(ISNUMBER($D24))),"",IF(AND($E24<$D$2,$G24<>"X",$F24<>"Réalisé",$F24<>"Clôturé"),"RETARD","")) | J24: =IF($B24="","",IF(INDEX(Dossiers!$F$4:$F$63,1)="","",INDEX(Dossiers!$F$4:$F$63,1))) | K24: =IF($B24="","",IF(INDEX(Dossiers!$G$4:$G$63,1)="","",INDEX(Dossiers!$G$4:$G$63,1)))
A25: =IF($B25="","",INDEX(Dossiers!$E$4:$E$63,1)) | B25: =IF(INDEX(Suivi!$B:$B,26)="","",INDEX(Suivi!$B:$B,26)) | C25: =IF($B25="","",IF(INDEX(Suivi!$D:$D,26)="",INDEX(Suivi!$C:$C,26),INDEX(Suivi!$D:$D,26))) | D25: =IF($B25="","",INDEX(Suivi!$E:$E,26)) | E25: =IF($B25="","",INDEX(Suivi!$F:$F,26)) | F25: =IF($B25="","",INDEX(Suivi!$G:$G,26)) | H25: =IF(OR($B25="",NOT(ISNUMBER($D25))),"",IF($E25<$D$2,"Passé",IF($D25>$F$2,"À venir","Dans la période"))) | I25: =IF(OR($B25="",NOT(ISNUMBER($D25))),"",IF(AND($E25<$D$2,$G25<>"X",$F25<>"Réalisé",$F25<>"Clôturé"),"RETARD","")) | J25: =IF($B25="","",IF(INDEX(Dossiers!$F$4:$F$63,1)="","",INDEX(Dossiers!$F$4:$F$63,1))) | K25: =IF($B25="","",IF(INDEX(Dossiers!$G$4:$G$63,1)="","",INDEX(Dossiers!$G$4:$G$63,1)))
A26: =IF($B26="","",INDEX(Dossiers!$E$4:$E$63,1)) | B26: =IF(INDEX(Suivi!$B:$B,27)="","",INDEX(Suivi!$B:$B,27)) | C26: =IF($B26="","",IF(INDEX(Suivi!$D:$D,27)="",INDEX(Suivi!$C:$C,27),INDEX(Suivi!$D:$D,27))) | D26: =IF($B26="","",INDEX(Suivi!$E:$E,27)) | E26: =IF($B26="","",INDEX(Suivi!$F:$F,27)) | F26: =IF($B26="","",INDEX(Suivi!$G:$G,27)) | H26: =IF(OR($B26="",NOT(ISNUMBER($D26))),"",IF($E26<$D$2,"Passé",IF($D26>$F$2,"À venir","Dans la période"))) | I26: =IF(OR($B26="",NOT(ISNUMBER($D26))),"",IF(AND($E26<$D$2,$G26<>"X",$F26<>"Réalisé",$F26<>"Clôturé"),"RETARD","")) | J26: =IF($B26="","",IF(INDEX(Dossiers!$F$4:$F$63,1)="","",INDEX(Dossiers!$F$4:$F$63,1))) | K26: =IF($B26="","",IF(INDEX(Dossiers!$G$4:$G$63,1)="","",INDEX(Dossiers!$G$4:$G$63,1)))
A27: =IF($B27="","",INDEX(Dossiers!$E$4:$E$63,1)) | B27: =IF(INDEX(Suivi!$B:$B,28)="","",INDEX(Suivi!$B:$B,28)) | C27: =IF($B27="","",IF(INDEX(Suivi!$D:$D,28)="",INDEX(Suivi!$C:$C,28),INDEX(Suivi!$D:$D,28))) | D27: =IF($B27="","",INDEX(Suivi!$E:$E,28)) | E27: =IF($B27="","",INDEX(Suivi!$F:$F,28)) | F27: =IF($B27="","",INDEX(Suivi!$G:$G,28)) | H27: =IF(OR($B27="",NOT(ISNUMBER($D27))),"",IF($E27<$D$2,"Passé",IF($D27>$F$2,"À venir","Dans la période"))) | I27: =IF(OR($B27="",NOT(ISNUMBER($D27))),"",IF(AND($E27<$D$2,$G27<>"X",$F27<>"Réalisé",$F27<>"Clôturé"),"RETARD","")) | J27: =IF($B27="","",IF(INDEX(Dossiers!$F$4:$F$63,1)="","",INDEX(Dossiers!$F$4:$F$63,1))) | K27: =IF($B27="","",IF(INDEX(Dossiers!$G$4:$G$63,1)="","",INDEX(Dossiers!$G$4:$G$63,1)))
A28: =IF($B28="","",INDEX(Dossiers!$E$4:$E$63,1)) | B28: =IF(INDEX(Suivi!$B:$B,29)="","",INDEX(Suivi!$B:$B,29)) | C28: =IF($B28="","",IF(INDEX(Suivi!$D:$D,29)="",INDEX(Suivi!$C:$C,29),INDEX(Suivi!$D:$D,29))) | D28: =IF($B28="","",INDEX(Suivi!$E:$E,29)) | E28: =IF($B28="","",INDEX(Suivi!$F:$F,29)) | F28: =IF($B28="","",INDEX(Suivi!$G:$G,29)) | H28: =IF(OR($B28="",NOT(ISNUMBER($D28))),"",IF($E28<$D$2,"Passé",IF($D28>$F$2,"À venir","Dans la période"))) | I28: =IF(OR($B28="",NOT(ISNUMBER($D28))),"",IF(AND($E28<$D$2,$G28<>"X",$F28<>"Réalisé",$F28<>"Clôturé"),"RETARD","")) | J28: =IF($B28="","",IF(INDEX(Dossiers!$F$4:$F$63,1)="","",INDEX(Dossiers!$F$4:$F$63,1))) | K28: =IF($B28="","",IF(INDEX(Dossiers!$G$4:$G$63,1)="","",INDEX(Dossiers!$G$4:$G$63,1)))
A29: =IF($B29="","",INDEX(Dossiers!$E$4:$E$63,1)) | B29: =IF(INDEX(Suivi!$B:$B,30)="","",INDEX(Suivi!$B:$B,30)) | C29: =IF($B29="","",IF(INDEX(Suivi!$D:$D,30)="",INDEX(Suivi!$C:$C,30),INDEX(Suivi!$D:$D,30))) | D29: =IF($B29="","",INDEX(Suivi!$E:$E,30)) | E29: =IF($B29="","",INDEX(Suivi!$F:$F,30)) | F29: =IF($B29="","",INDEX(Suivi!$G:$G,30)) | H29: =IF(OR($B29="",NOT(ISNUMBER($D29))),"",IF($E29<$D$2,"Passé",IF($D29>$F$2,"À venir","Dans la période"))) | I29: =IF(OR($B29="",NOT(ISNUMBER($D29))),"",IF(AND($E29<$D$2,$G29<>"X",$F29<>"Réalisé",$F29<>"Clôturé"),"RETARD","")) | J29: =IF($B29="","",IF(INDEX(Dossiers!$F$4:$F$63,1)="","",INDEX(Dossiers!$F$4:$F$63,1))) | K29: =IF($B29="","",IF(INDEX(Dossiers!$G$4:$G$63,1)="","",INDEX(Dossiers!$G$4:$G$63,1)))
A30: =IF($B30="","",INDEX(Dossiers!$E$4:$E$63,1)) | B30: =IF(INDEX(Suivi!$B:$B,31)="","",INDEX(Suivi!$B:$B,31)) | C30: =IF($B30="","",IF(INDEX(Suivi!$D:$D,31)="",INDEX(Suivi!$C:$C,31),INDEX(Suivi!$D:$D,31))) | D30: =IF($B30="","",INDEX(Suivi!$E:$E,31)) | E30: =IF($B30="","",INDEX(Suivi!$F:$F,31)) | F30: =IF($B30="","",INDEX(Suivi!$G:$G,31)) | H30: =IF(OR($B30="",NOT(ISNUMBER($D30))),"",IF($E30<$D$2,"Passé",IF($D30>$F$2,"À venir","Dans la période"))) | I30: =IF(OR($B30="",NOT(ISNUMBER($D30))),"",IF(AND($E30<$D$2,$G30<>"X",$F30<>"Réalisé",$F30<>"Clôturé"),"RETARD","")) | J30: =IF($B30="","",IF(INDEX(Dossiers!$F$4:$F$63,1)="","",INDEX(Dossiers!$F$4:$F$63,1))) | K30: =IF($B30="","",IF(INDEX(Dossiers!$G$4:$G$63,1)="","",INDEX(Dossiers!$G$4:$G$63,1)))
A31: =IF($B31="","",INDEX(Dossiers!$E$4:$E$63,1)) | B31: =IF(INDEX(Suivi!$B:$B,32)="","",INDEX(Suivi!$B:$B,32)) | C31: =IF($B31="","",IF(INDEX(Suivi!$D:$D,32)="",INDEX(Suivi!$C:$C,32),INDEX(Suivi!$D:$D,32))) | D31: =IF($B31="","",INDEX(Suivi!$E:$E,32)) | E31: =IF($B31="","",INDEX(Suivi!$F:$F,32)) | F31: =IF($B31="","",INDEX(Suivi!$G:$G,32)) | H31: =IF(OR($B31="",NOT(ISNUMBER($D31))),"",IF($E31<$D$2,"Passé",IF($D31>$F$2,"À venir","Dans la période"))) | I31: =IF(OR($B31="",NOT(ISNUMBER($D31))),"",IF(AND($E31<$D$2,$G31<>"X",$F31<>"Réalisé",$F31<>"Clôturé"),"RETARD","")) | J31: =IF($B31="","",IF(INDEX(Dossiers!$F$4:$F$63,1)="","",INDEX(Dossiers!$F$4:$F$63,1))) | K31: =IF($B31="","",IF(INDEX(Dossiers!$G$4:$G$63,1)="","",INDEX(Dossiers!$G$4:$G$63,1)))
A32: =IF($B32="","",INDEX(Dossiers!$E$4:$E$63,1)) | B32: =IF(INDEX(Suivi!$B:$B,33)="","",INDEX(Suivi!$B:$B,33)) | C32: =IF($B32="","",IF(INDEX(Suivi!$D:$D,33)="",INDEX(Suivi!$C:$C,33),INDEX(Suivi!$D:$D,33))) | D32: =IF($B32="","",INDEX(Suivi!$E:$E,33)) | E32: =IF($B32="","",INDEX(Suivi!$F:$F,33)) | F32: =IF($B32="","",INDEX(Suivi!$G:$G,33)) | H32: =IF(OR($B32="",NOT(ISNUMBER($D32))),"",IF($E32<$D$2,"Passé",IF($D32>$F$2,"À venir","Dans la période"))) | I32: =IF(OR($B32="",NOT(ISNUMBER($D32))),"",IF(AND($E32<$D$2,$G32<>"X",$F32<>"Réalisé",$F32<>"Clôturé"),"RETARD","")) | J32: =IF($B32="","",IF(INDEX(Dossiers!$F$4:$F$63,1)="","",INDEX(Dossiers!$F$4:$F$63,1))) | K32: =IF($B32="","",IF(INDEX(Dossiers!$G$4:$G$63,1)="","",INDEX(Dossiers!$G$4:$G$63,1)))
A33: =IF($B33="","",INDEX(Dossiers!$E$4:$E$63,1)) | B33: =IF(INDEX(Suivi!$B:$B,34)="","",INDEX(Suivi!$B:$B,34)) | C33: =IF($B33="","",IF(INDEX(Suivi!$D:$D,34)="",INDEX(Suivi!$C:$C,34),INDEX(Suivi!$D:$D,34))) | D33: =IF($B33="","",INDEX(Suivi!$E:$E,34)) | E33: =IF($B33="","",INDEX(Suivi!$F:$F,34)) | F33: =IF($B33="","",INDEX(Suivi!$G:$G,34)) | H33: =IF(OR($B33="",NOT(ISNUMBER($D33))),"",IF($E33<$D$2,"Passé",IF($D33>$F$2,"À venir","Dans la période"))) | I33: =IF(OR($B33="",NOT(ISNUMBER($D33))),"",IF(AND($E33<$D$2,$G33<>"X",$F33<>"Réalisé",$F33<>"Clôturé"),"RETARD","")) | J33: =IF($B33="","",IF(INDEX(Dossiers!$F$4:$F$63,1)="","",INDEX(Dossiers!$F$4:$F$63,1))) | K33: =IF($B33="","",IF(INDEX(Dossiers!$G$4:$G$63,1)="","",INDEX(Dossiers!$G$4:$G$63,1)))
A34: =IF($B34="","",INDEX(Dossiers!$E$4:$E$63,1)) | B34: =IF(INDEX(Suivi!$B:$B,35)="","",INDEX(Suivi!$B:$B,35)) | C34: =IF($B34="","",IF(INDEX(Suivi!$D:$D,35)="",INDEX(Suivi!$C:$C,35),INDEX(Suivi!$D:$D,35))) | D34: =IF($B34="","",INDEX(Suivi!$E:$E,35)) | E34: =IF($B34="","",INDEX(Suivi!$F:$F,35)) | F34: =IF($B34="","",INDEX(Suivi!$G:$G,35)) | H34: =IF(OR($B34="",NOT(ISNUMBER($D34))),"",IF($E34<$D$2,"Passé",IF($D34>$F$2,"À venir","Dans la période"))) | I34: =IF(OR($B34="",NOT(ISNUMBER($D34))),"",IF(AND($E34<$D$2,$G34<>"X",$F34<>"Réalisé",$F34<>"Clôturé"),"RETARD","")) | J34: =IF($B34="","",IF(INDEX(Dossiers!$F$4:$F$63,1)="","",INDEX(Dossiers!$F$4:$F$63,1))) | K34: =IF($B34="","",IF(INDEX(Dossiers!$G$4:$G$63,1)="","",INDEX(Dossiers!$G$4:$G$63,1)))
A35: =IF($B35="","",INDEX(Dossiers!$E$4:$E$63,1)) | B35: =IF(INDEX(Suivi!$B:$B,36)="","",INDEX(Suivi!$B:$B,36)) | C35: =IF($B35="","",IF(INDEX(Suivi!$D:$D,36)="",INDEX(Suivi!$C:$C,36),INDEX(Suivi!$D:$D,36))) | D35: =IF($B35="","",INDEX(Suivi!$E:$E,36)) | E35: =IF($B35="","",INDEX(Suivi!$F:$F,36)) | F35: =IF($B35="","",INDEX(Suivi!$G:$G,36)) | H35: =IF(OR($B35="",NOT(ISNUMBER($D35))),"",IF($E35<$D$2,"Passé",IF($D35>$F$2,"À venir","Dans la période"))) | I35: =IF(OR($B35="",NOT(ISNUMBER($D35))),"",IF(AND($E35<$D$2,$G35<>"X",$F35<>"Réalisé",$F35<>"Clôturé"),"RETARD","")) | J35: =IF($B35="","",IF(INDEX(Dossiers!$F$4:$F$63,1)="","",INDEX(Dossiers!$F$4:$F$63,1))) | K35: =IF($B35="","",IF(INDEX(Dossiers!$G$4:$G$63,1)="","",INDEX(Dossiers!$G$4:$G$63,1)))
A36: =IF($B36="","",INDEX(Dossiers!$E$4:$E$63,1)) | B36: =IF(INDEX(Suivi!$B:$B,37)="","",INDEX(Suivi!$B:$B,37)) | C36: =IF($B36="","",IF(INDEX(Suivi!$D:$D,37)="",INDEX(Suivi!$C:$C,37),INDEX(Suivi!$D:$D,37))) | D36: =IF($B36="","",INDEX(Suivi!$E:$E,37)) | E36: =IF($B36="","",INDEX(Suivi!$F:$F,37)) | F36: =IF($B36="","",INDEX(Suivi!$G:$G,37)) | H36: =IF(OR($B36="",NOT(ISNUMBER($D36))),"",IF($E36<$D$2,"Passé",IF($D36>$F$2,"À venir","Dans la période"))) | I36: =IF(OR($B36="",NOT(ISNUMBER($D36))),"",IF(AND($E36<$D$2,$G36<>"X",$F36<>"Réalisé",$F36<>"Clôturé"),"RETARD","")) | J36: =IF($B36="","",IF(INDEX(Dossiers!$F$4:$F$63,1)="","",INDEX(Dossiers!$F$4:$F$63,1))) | K36: =IF($B36="","",IF(INDEX(Dossiers!$G$4:$G$63,1)="","",INDEX(Dossiers!$G$4:$G$63,1)))
A37: =IF($B37="","",INDEX(Dossiers!$E$4:$E$63,1)) | B37: =IF(INDEX(Suivi!$B:$B,38)="","",INDEX(Suivi!$B:$B,38)) | C37: =IF($B37="","",IF(INDEX(Suivi!$D:$D,38)="",INDEX(Suivi!$C:$C,38),INDEX(Suivi!$D:$D,38))) | D37: =IF($B37="","",INDEX(Suivi!$E:$E,38)) | E37: =IF($B37="","",INDEX(Suivi!$F:$F,38)) | F37: =IF($B37="","",INDEX(Suivi!$G:$G,38)) | H37: =IF(OR($B37="",NOT(ISNUMBER($D37))),"",IF($E37<$D$2,"Passé",IF($D37>$F$2,"À venir","Dans la période"))) | I37: =IF(OR($B37="",NOT(ISNUMBER($D37))),"",IF(AND($E37<$D$2,$G37<>"X",$F37<>"Réalisé",$F37<>"Clôturé"),"RETARD","")) | J37: =IF($B37="","",IF(INDEX(Dossiers!$F$4:$F$63,1)="","",INDEX(Dossiers!$F$4:$F$63,1))) | K37: =IF($B37="","",IF(INDEX(Dossiers!$G$4:$G$63,1)="","",INDEX(Dossiers!$G$4:$G$63,1)))
A38: =IF($B38="","",INDEX(Dossiers!$E$4:$E$63,1)) | B38: =IF(INDEX(Suivi!$B:$B,39)="","",INDEX(Suivi!$B:$B,39)) | C38: =IF($B38="","",IF(INDEX(Suivi!$D:$D,39)="",INDEX(Suivi!$C:$C,39),INDEX(Suivi!$D:$D,39))) | D38: =IF($B38="","",INDEX(Suivi!$E:$E,39)) | E38: =IF($B38="","",INDEX(Suivi!$F:$F,39)) | F38: =IF($B38="","",INDEX(Suivi!$G:$G,39)) | H38: =IF(OR($B38="",NOT(ISNUMBER($D38))),"",IF($E38<$D$2,"Passé",IF($D38>$F$2,"À venir","Dans la période"))) | I38: =IF(OR($B38="",NOT(ISNUMBER($D38))),"",IF(AND($E38<$D$2,$G38<>"X",$F38<>"Réalisé",$F38<>"Clôturé"),"RETARD","")) | J38: =IF($B38="","",IF(INDEX(Dossiers!$F$4:$F$63,1)="","",INDEX(Dossiers!$F$4:$F$63,1))) | K38: =IF($B38="","",IF(INDEX(Dossiers!$G$4:$G$63,1)="","",INDEX(Dossiers!$G$4:$G$63,1)))
A39: =IF($B39="","",INDEX(Dossiers!$E$4:$E$63,1)) | B39: =IF(INDEX(Suivi!$B:$B,40)="","",INDEX(Suivi!$B:$B,40)) | C39: =IF($B39="","",IF(INDEX(Suivi!$D:$D,40)="",INDEX(Suivi!$C:$C,40),INDEX(Suivi!$D:$D,40))) | D39: =IF($B39="","",INDEX(Suivi!$E:$E,40)) | E39: =IF($B39="","",INDEX(Suivi!$F:$F,40)) | F39: =IF($B39="","",INDEX(Suivi!$G:$G,40)) | H39: =IF(OR($B39="",NOT(ISNUMBER($D39))),"",IF($E39<$D$2,"Passé",IF($D39>$F$2,"À venir","Dans la période"))) | I39: =IF(OR($B39="",NOT(ISNUMBER($D39))),"",IF(AND($E39<$D$2,$G39<>"X",$F39<>"Réalisé",$F39<>"Clôturé"),"RETARD","")) | J39: =IF($B39="","",IF(INDEX(Dossiers!$F$4:$F$63,1)="","",INDEX(Dossiers!$F$4:$F$63,1))) | K39: =IF($B39="","",IF(INDEX(Dossiers!$G$4:$G$63,1)="","",INDEX(Dossiers!$G$4:$G$63,1)))
A40: =IF($B40="","",INDEX(Dossiers!$E$4:$E$63,1)) | B40: =IF(INDEX(Suivi!$B:$B,41)="","",INDEX(Suivi!$B:$B,41)) | C40: =IF($B40="","",IF(INDEX(Suivi!$D:$D,41)="",INDEX(Suivi!$C:$C,41),INDEX(Suivi!$D:$D,41))) | D40: =IF($B40="","",INDEX(Suivi!$E:$E,41)) | E40: =IF($B40="","",INDEX(Suivi!$F:$F,41)) | F40: =IF($B40="","",INDEX(Suivi!$G:$G,41)) | H40: =IF(OR($B40="",NOT(ISNUMBER($D40))),"",IF($E40<$D$2,"Passé",IF($D40>$F$2,"À venir","Dans la période"))) | I40: =IF(OR($B40="",NOT(ISNUMBER($D40))),"",IF(AND($E40<$D$2,$G40<>"X",$F40<>"Réalisé",$F40<>"Clôturé"),"RETARD","")) | J40: =IF($B40="","",IF(INDEX(Dossiers!$F$4:$F$63,1)="","",INDEX(Dossiers!$F$4:$F$63,1))) | K40: =IF($B40="","",IF(INDEX(Dossiers!$G$4:$G$63,1)="","",INDEX(Dossiers!$G$4:$G$63,1)))
...

Sheet Tableau de bord
A1: TABLEAU DE BORD DES DOSSIERS
A2: ="Dossiers actifs : "&COUNTIF(A5:A64,"?*") | D2: ="Dossiers avec étapes en retard : "&COUNTIF(K5:K64,">0")
A3: Cliquer sur un dossier pour ouvrir son détail. Réalisation = étapes « Réalisé » ou « Clôturé » sur le total des étapes.
A4: Dossier | B4: Début | C4: Fin prévue | D4: =Paramètres!G5&" · "&Paramètres!H5 | E4: =Paramètres!G10&" · "&Paramètres!H10 | F4: =Paramètres!G15&" · "&Paramètres!H15 | G4: =Paramètres!G32&" · "&Paramètres!H32 | H4: =Paramètres!G37&" · "&Paramètres!H37 | I4: =Paramètres!G56&" · "&Paramètres!H56 | J4: Global | K4: Étapes en retard
A5: =IF(ISNUMBER(Dossiers!$D$4),HYPERLINK("#Suivi!A4",Dossiers!$E$4),"") | B5: =IF($A5="","",Dossiers!$D$4) | C5: =IF($A5="","",MAX(Suivi!$F$5:$F$57)) | D5: =IF($A5="","",(COUNTIF(Suivi!$G$6:$G$9,"Réalisé")+COUNTIF(Suivi!$G$6:$G$9,"Clôturé"))/ROWS(Suivi!$G$6:$G$9)) | E5: =IF($A5="","",(COUNTIF(Suivi!$G$11:$G$14,"Réalisé")+COUNTIF(Suivi!$G$11:$G$14,"Clôturé"))/ROWS(Suivi!$G$11:$G$14)) | F5: =IF($A5="","",(COUNTIF(Suivi!$G$16:$G$31,"Réalisé")+COUNTIF(Suivi!$G$16:$G$31,"Clôturé"))/ROWS(Suivi!$G$16:$G$31)) | G5: =IF($A5="","",(COUNTIF(Suivi!$G$33:$G$36,"Réalisé")+COUNTIF(Suivi!$G$33:$G$36,"Clôturé"))/ROWS(Suivi!$G$33:$G$36)) | H5: =IF($A5="","",(COUNTIF(Suivi!$G$38:$G$55,"Réalisé")+COUNTIF(Suivi!$G$38:$G$55,"Clôturé"))/ROWS(Suivi!$G$38:$G$55)) | I5: =IF($A5="","",(COUNTIF(Suivi!$G$57:$G$57,"Réalisé")+COUNTIF(Suivi!$G$57:$G$57,"Clôturé"))/ROWS(Suivi!$G$57:$G$57)) | J5: =IF($A5="","",SUMPRODUCT(ISNUMBER(SEARCH(".",Suivi!$B$5:$B$57))*((Suivi!$G$5:$G$57="Réalisé")+(Suivi!$G$5:$G$57="Clôturé")))/SUMPRODUCT(--ISNUMBER(SEARCH(".",Suivi!$B$5:$B$57)))) | K5: =IF($A5="","",SUMPRODUCT(ISNUMBER(SEARCH(".",Suivi!$B$5:$B$57))*ISNUMBER(Suivi!$F$5:$F$57)*(Suivi!$F$5:$F$57<TODAY())*(Suivi!$G$5:$G$57<>"Réalisé")*(Suivi!$G$5:$G$57<>"Clôturé")))
A6: =IF(ISNUMBER(Dossiers!$D$5),HYPERLINK("#Suivi!A58",Dossiers!$E$5),"") | B6: =IF($A6="","",Dossiers!$D$5) | C6: =IF($A6="","",MAX(Suivi!$F$59:$F$111)) | D6: =IF($A6="","",(COUNTIF(Suivi!$G$60:$G$63,"Réalisé")+COUNTIF(Suivi!$G$60:$G$63,"Clôturé"))/ROWS(Suivi!$G$60:$G$63)) | E6: =IF($A6="","",(COUNTIF(Suivi!$G$65:$G$68,"Réalisé")+COUNTIF(Suivi!$G$65:$G$68,"Clôturé"))/ROWS(Suivi!$G$65:$G$68)) | F6: =IF($A6="","",(COUNTIF(Suivi!$G$70:$G$85,"Réalisé")+COUNTIF(Suivi!$G$70:$G$85,"Clôturé"))/ROWS(Suivi!$G$70:$G$85)) | G6: =IF($A6="","",(COUNTIF(Suivi!$G$87:$G$90,"Réalisé")+COUNTIF(Suivi!$G$87:$G$90,"Clôturé"))/ROWS(Suivi!$G$87:$G$90)) | H6: =IF($A6="","",(COUNTIF(Suivi!$G$92:$G$109,"Réalisé")+COUNTIF(Suivi!$G$92:$G$109,"Clôturé"))/ROWS(Suivi!$G$92:$G$109)) | I6: =IF($A6="","",(COUNTIF(Suivi!$G$111:$G$111,"Réalisé")+COUNTIF(Suivi!$G$111:$G$111,"Clôturé"))/ROWS(Suivi!$G$111:$G$111)) | J6: =IF($A6="","",SUMPRODUCT(ISNUMBER(SEARCH(".",Suivi!$B$59:$B$111))*((Suivi!$G$59:$G$111="Réalisé")+(Suivi!$G$59:$G$111="Clôturé")))/SUMPRODUCT(--ISNUMBER(SEARCH(".",Suivi!$B$59:$B$111)))) | K6: =IF($A6="","",SUMPRODUCT(ISNUMBER(SEARCH(".",Suivi!$B$59:$B$111))*ISNUMBER(Suivi!$F$59:$F$111)*(Suivi!$F$59:$F$111<TODAY())*(Suivi!$G$59:$G$111<>"Réalisé")*(Suivi!$G$59:$G$111<>"Clôturé")))
A7: =IF(ISNUMBER(Dossiers!$D$6),HYPERLINK("#Suivi!A112",Dossiers!$E$6),"") | B7: =IF($A7="","",Dossiers!$D$6) | C7: =IF($A7="","",MAX(Suivi!$F$113:$F$165)) | D7: =IF($A7="","",(COUNTIF(Suivi!$G$114:$G$117,"Réalisé")+COUNTIF(Suivi!$G$114:$G$117,"Clôturé"))/ROWS(Suivi!$G$114:$G$117)) | E7: =IF($A7="","",(COUNTIF(Suivi!$G$119:$G$122,"Réalisé")+COUNTIF(Suivi!$G$119:$G$122,"Clôturé"))/ROWS(Suivi!$G$119:$G$122)) | F7: =IF($A7="","",(COUNTIF(Suivi!$G$124:$G$139,"Réalisé")+COUNTIF(Suivi!$G$124:$G$139,"Clôturé"))/ROWS(Suivi!$G$124:$G$139)) | G7: =IF($A7="","",(COUNTIF(Suivi!$G$141:$G$144,"Réalisé")+COUNTIF(Suivi!$G$141:$G$144,"Clôturé"))/ROWS(Suivi!$G$141:$G$144)) | H7: =IF($A7="","",(COUNTIF(Suivi!$G$146:$G$163,"Réalisé")+COUNTIF(Suivi!$G$146:$G$163,"Clôturé"))/ROWS(Suivi!$G$146:$G$163)) | I7: =IF($A7="","",(COUNTIF(Suivi!$G$165:$G$165,"Réalisé")+COUNTIF(Suivi!$G$165:$G$165,"Clôturé"))/ROWS(Suivi!$G$165:$G$165)) | J7: =IF($A7="","",SUMPRODUCT(ISNUMBER(SEARCH(".",Suivi!$B$113:$B$165))*((Suivi!$G$113:$G$165="Réalisé")+(Suivi!$G$113:$G$165="Clôturé")))/SUMPRODUCT(--ISNUMBER(SEARCH(".",Suivi!$B$113:$B$165)))) | K7: =IF($A7="","",SUMPRODUCT(ISNUMBER(SEARCH(".",Suivi!$B$113:$B$165))*ISNUMBER(Suivi!$F$113:$F$165)*(Suivi!$F$113:$F$165<TODAY())*(Suivi!$G$113:$G$165<>"Réalisé")*(Suivi!$G$113:$G$165<>"Clôturé")))
A8: =IF(ISNUMBER(Dossiers!$D$7),HYPERLINK("#Suivi!A166",Dossiers!$E$7),"") | B8: =IF($A8="","",Dossiers!$D$7) | C8: =IF($A8="","",MAX(Suivi!$F$167:$F$219)) | D8: =IF($A8="","",(COUNTIF(Suivi!$G$168:$G$171,"Réalisé")+COUNTIF(Suivi!$G$168:$G$171,"Clôturé"))/ROWS(Suivi!$G$168:$G$171)) | E8: =IF($A8="","",(COUNTIF(Suivi!$G$173:$G$176,"Réalisé")+COUNTIF(Suivi!$G$173:$G$176,"Clôturé"))/ROWS(Suivi!$G$173:$G$176)) | F8: =IF($A8="","",(COUNTIF(Suivi!$G$178:$G$193,"Réalisé")+COUNTIF(Suivi!$G$178:$G$193,"Clôturé"))/ROWS(Suivi!$G$178:$G$193)) | G8: =IF($A8="","",(COUNTIF(Suivi!$G$195:$G$198,"Réalisé")+COUNTIF(Suivi!$G$195:$G$198,"Clôturé"))/ROWS(Suivi!$G$195:$G$198)) | H8: =IF($A8="","",(COUNTIF(Suivi!$G$200:$G$217,"Réalisé")+COUNTIF(Suivi!$G$200:$G$217,"Clôturé"))/ROWS(Suivi!$G$200:$G$217)) | I8: =IF($A8="","",(COUNTIF(Suivi!$G$219:$G$219,"Réalisé")+COUNTIF(Suivi!$G$219:$G$219,"Clôturé"))/ROWS(Suivi!$G$219:$G$219)) | J8: =IF($A8="","",SUMPRODUCT(ISNUMBER(SEARCH(".",Suivi!$B$167:$B$219))*((Suivi!$G$167:$G$219="Réalisé")+(Suivi!$G$167:$G$219="Clôturé")))/SUMPRODUCT(--ISNUMBER(SEARCH(".",Suivi!$B$167:$B$219)))) | K8: =IF($A8="","",SUMPRODUCT(ISNUMBER(SEARCH(".",Suivi!$B$167:$B$219))*ISNUMBER(Suivi!$F$167:$F$219)*(Suivi!$F$167:$F$219<TODAY())*(Suivi!$G$167:$G$219<>"Réalisé")*(Suivi!$G$167:$G$219<>"Clôturé")))
A9: =IF(ISNUMBER(Dossiers!$D$8),HYPERLINK("#Suivi!A220",Dossiers!$E$8),"") | B9: =IF($A9="","",Dossiers!$D$8) | C9: =IF($A9="","",MAX(Suivi!$F$221:$F$273)) | D9: =IF($A9="","",(COUNTIF(Suivi!$G$222:$G$225,"Réalisé")+COUNTIF(Suivi!$G$222:$G$225,"Clôturé"))/ROWS(Suivi!$G$222:$G$225)) | E9: =IF($A9="","",(COUNTIF(Suivi!$G$227:$G$230,"Réalisé")+COUNTIF(Suivi!$G$227:$G$230,"Clôturé"))/ROWS(Suivi!$G$227:$G$230)) | F9: =IF($A9="","",(COUNTIF(Suivi!$G$232:$G$247,"Réalisé")+COUNTIF(Suivi!$G$232:$G$247,"Clôturé"))/ROWS(Suivi!$G$232:$G$247)) | G9: =IF($A9="","",(COUNTIF(Suivi!$G$249:$G$252,"Réalisé")+COUNTIF(Suivi!$G$249:$G$252,"Clôturé"))/ROWS(Suivi!$G$249:$G$252)) | H9: =IF($A9="","",(COUNTIF(Suivi!$G$254:$G$271,"Réalisé")+COUNTIF(Suivi!$G$254:$G$271,"Clôturé"))/ROWS(Suivi!$G$254:$G$271)) | I9: =IF($A9="","",(COUNTIF(Suivi!$G$273:$G$273,"Réalisé")+COUNTIF(Suivi!$G$273:$G$273,"Clôturé"))/ROWS(Suivi!$G$273:$G$273)) | J9: =IF($A9="","",SUMPRODUCT(ISNUMBER(SEARCH(".",Suivi!$B$221:$B$273))*((Suivi!$G$221:$G$273="Réalisé")+(Suivi!$G$221:$G$273="Clôturé")))/SUMPRODUCT(--ISNUMBER(SEARCH(".",Suivi!$B$221:$B$273)))) | K9: =IF($A9="","",SUMPRODUCT(ISNUMBER(SEARCH(".",Suivi!$B$221:$B$273))*ISNUMBER(Suivi!$F$221:$F$273)*(Suivi!$F$221:$F$273<TODAY())*(Suivi!$G$221:$G$273<>"Réalisé")*(Suivi!$G$221:$G$273<>"Clôturé")))
A10: =IF(ISNUMBER(Dossiers!$D$9),HYPERLINK("#Suivi!A274",Dossiers!$E$9),"") | B10: =IF($A10="","",Dossiers!$D$9) | C10: =IF($A10="","",MAX(Suivi!$F$275:$F$327)) | D10: =IF($A10="","",(COUNTIF(Suivi!$G$276:$G$279,"Réalisé")+COUNTIF(Suivi!$G$276:$G$279,"Clôturé"))/ROWS(Suivi!$G$276:$G$279)) | E10: =IF($A10="","",(COUNTIF(Suivi!$G$281:$G$284,"Réalisé")+COUNTIF(Suivi!$G$281:$G$284,"Clôturé"))/ROWS(Suivi!$G$281:$G$284)) | F10: =IF($A10="","",(COUNTIF(Suivi!$G$286:$G$301,"Réalisé")+COUNTIF(Suivi!$G$286:$G$301,"Clôturé"))/ROWS(Suivi!$G$286:$G$301)) | G10: =IF($A10="","",(COUNTIF(Suivi!$G$303:$G$306,"Réalisé")+COUNTIF(Suivi!$G$303:$G$306,"Clôturé"))/ROWS(Suivi!$G$303:$G$306)) | H10: =IF($A10="","",(COUNTIF(Suivi!$G$308:$G$325,"Réalisé")+COUNTIF(Suivi!$G$308:$G$325,"Clôturé"))/ROWS(Suivi!$G$308:$G$325)) | I10: =IF($A10="","",(COUNTIF(Suivi!$G$327:$G$327,"Réalisé")+COUNTIF(Suivi!$G$327:$G$327,"Clôturé"))/ROWS(Suivi!$G$327:$G$327)) | J10: =IF($A10="","",SUMPRODUCT(ISNUMBER(SEARCH(".",Suivi!$B$275:$B$327))*((Suivi!$G$275:$G$327="Réalisé")+(Suivi!$G$275:$G$327="Clôturé")))/SUMPRODUCT(--ISNUMBER(SEARCH(".",Suivi!$B$275:$B$327)))) | K10: =IF($A10="","",SUMPRODUCT(ISNUMBER(SEARCH(".",Suivi!$B$275:$B$327))*ISNUMBER(Suivi!$F$275:$F$327)*(Suivi!$F$275:$F$327<TODAY())*(Suivi!$G$275:$G$327<>"Réalisé")*(Suivi!$G$275:$G$327<>"Clôturé")))
A11: =IF(ISNUMBER(Dossiers!$D$10),HYPERLINK("#Suivi!A328",Dossiers!$E$10),"") | B11: =IF($A11="","",Dossiers!$D$10) | C11: =IF($A11="","",MAX(Suivi!$F$329:$F$381)) | D11: =IF($A11="","",(COUNTIF(Suivi!$G$330:$G$333,"Réalisé")+COUNTIF(Suivi!$G$330:$G$333,"Clôturé"))/ROWS(Suivi!$G$330:$G$333)) | E11: =IF($A11="","",(COUNTIF(Suivi!$G$335:$G$338,"Réalisé")+COUNTIF(Suivi!$G$335:$G$338,"Clôturé"))/ROWS(Suivi!$G$335:$G$338)) | F11: =IF($A11="","",(COUNTIF(Suivi!$G$340:$G$355,"Réalisé")+COUNTIF(Suivi!$G$340:$G$355,"Clôturé"))/ROWS(Suivi!$G$340:$G$355)) | G11: =IF($A11="","",(COUNTIF(Suivi!$G$357:$G$360,"Réalisé")+COUNTIF(Suivi!$G$357:$G$360,"Clôturé"))/ROWS(Suivi!$G$357:$G$360)) | H11: =IF($A11="","",(COUNTIF(Suivi!$G$362:$G$379,"Réalisé")+COUNTIF(Suivi!$G$362:$G$379,"Clôturé"))/ROWS(Suivi!$G$362:$G$379)) | I11: =IF($A11="","",(COUNTIF(Suivi!$G$381:$G$381,"Réalisé")+COUNTIF(Suivi!$G$381:$G$381,"Clôturé"))/ROWS(Suivi!$G$381:$G$381)) | J11: =IF($A11="","",SUMPRODUCT(ISNUMBER(SEARCH(".",Suivi!$B$329:$B$381))*((Suivi!$G$329:$G$381="Réalisé")+(Suivi!$G$329:$G$381="Clôturé")))/SUMPRODUCT(--ISNUMBER(SEARCH(".",Suivi!$B$329:$B$381)))) | K11: =IF($A11="","",SUMPRODUCT(ISNUMBER(SEARCH(".",Suivi!$B$329:$B$381))*ISNUMBER(Suivi!$F$329:$F$381)*(Suivi!$F$329:$F$381<TODAY())*(Suivi!$G$329:$G$381<>"Réalisé")*(Suivi!$G$329:$G$381<>"Clôturé")))
A12: =IF(ISNUMBER(Dossiers!$D$11),HYPERLINK("#Suivi!A382",Dossiers!$E$11),"") | B12: =IF($A12="","",Dossiers!$D$11) | C12: =IF($A12="","",MAX(Suivi!$F$383:$F$435)) | D12: =IF($A12="","",(COUNTIF(Suivi!$G$384:$G$387,"Réalisé")+COUNTIF(Suivi!$G$384:$G$387,"Clôturé"))/ROWS(Suivi!$G$384:$G$387)) | E12: =IF($A12="","",(COUNTIF(Suivi!$G$389:$G$392,"Réalisé")+COUNTIF(Suivi!$G$389:$G$392,"Clôturé"))/ROWS(Suivi!$G$389:$G$392)) | F12: =IF($A12="","",(COUNTIF(Suivi!$G$394:$G$409,"Réalisé")+COUNTIF(Suivi!$G$394:$G$409,"Clôturé"))/ROWS(Suivi!$G$394:$G$409)) | G12: =IF($A12="","",(COUNTIF(Suivi!$G$411:$G$414,"Réalisé")+COUNTIF(Suivi!$G$411:$G$414,"Clôturé"))/ROWS(Suivi!$G$411:$G$414)) | H12: =IF($A12="","",(COUNTIF(Suivi!$G$416:$G$433,"Réalisé")+COUNTIF(Suivi!$G$416:$G$433,"Clôturé"))/ROWS(Suivi!$G$416:$G$433)) | I12: =IF($A12="","",(COUNTIF(Suivi!$G$435:$G$435,"Réalisé")+COUNTIF(Suivi!$G$435:$G$435,"Clôturé"))/ROWS(Suivi!$G$435:$G$435)) | J12: =IF($A12="","",SUMPRODUCT(ISNUMBER(SEARCH(".",Suivi!$B$383:$B$435))*((Suivi!$G$383:$G$435="Réalisé")+(Suivi!$G$383:$G$435="Clôturé")))/SUMPRODUCT(--ISNUMBER(SEARCH(".",Suivi!$B$383:$B$435)))) | K12: =IF($A12="","",SUMPRODUCT(ISNUMBER(SEARCH(".",Suivi!$B$383:$B$435))*ISNUMBER(Suivi!$F$383:$F$435)*(Suivi!$F$383:$F$435<TODAY())*(Suivi!$G$383:$G$435<>"Réalisé")*(Suivi!$G$383:$G$435<>"Clôturé")))
